Workbook

Sheet Starlink V4
C2: Date | D2: Details | E2: Units | F2: Per.Unit | G2: Amount | I2: GST
C3: 45473 | D3: 59 Units Purchased V4 | E3: 59 | F3: =G3/E3 -> 518.64407 | G3: 30600 | I3: 3210 | J3: 1 unit Returned | K3: 54.4
C5: 45473 | D5: 42 Units Purchased V4 | E5: 42 | F5: =G5/E5 -> 348.19643 | G5: 14624.25 | I5: 1370
C7: 45477 | D7: 92 Units Purchased V4 | E7: 92 | F7: =G7/E7 -> 359 | G7: =359*92 -> 33028 | I7: =G7/11 -> 3002.5455
C9: 45488 | D9: 54 Units Purchased V4 | E9: 54 | F9: =G9/E9 -> 358.96296 | G9: 19384 | I9: =G9/11 -> 1762.1818
C11: 45491 | D11: 56 Units Purchased V4 | E11: 56 | F11: =G11/E11 -> 357 | G11: 19992 | I11: =G11/11 -> 1817.4545
C13: 45491 | D13: 250 Units Purchased V4 | E13: 250 | F13: =G13/E13 -> 357 | G13: =357*250 -> 89250 | I13: =G13/11 -> 8113.6364
C15: 45495 | D15: 113 Units Purchased V4 | E15: 113 | F15: =G15/E15 -> 357 | G15: 40341 | I15: 0 | J15: Returned | K15: 597
C17: 45497 | D17: 76 Units Purchased V4 | E17: 76 | F17: =G17/E17 -> 357 | G17: 27132 | I17: =G17/11 -> 2466.5455
C19: 45501 | D19: 37 Units Purchased V4 | E19: 37 | F19: =G19/E19 -> 359 | G19: 13283 | I19: 0 | J19: Returned
C21: 45502 | D21: 61 Units Purchased V4 | E21: 61 | F21: =G21/E21 -> 358.90164 | G21: 21893 | I21: =G21/11 -> 1990.2727
C23: 45517 | D23: 400 Units Purchased V4 | E23: 400 | F23: =G23/E23 -> 357 | G23: 142800 | I23: =G23/11 -> 12981.818
C25: 45540 | D25: 40 Units Purchased V4 | E25: 40 | F25: =G25/E25 -> 358 | G25: =358*40 -> 14320 | I25: =G25/11 -> 1301.8182
C27: 45549 | D27: 34 Units Purchased V4 | E27: 34 | F27: =G27/E27 -> 279.47059 | G27: 9502 | I27: =G27/11 -> 863.81818
C29: 45550 | D29: 37 Units Purchased V4 | E29: 37 | F29: =G29/E29 -> 298.18919 | G29: 11033 | I29: =G29/11 -> 1003
C31: 45551 | D31: 34 Units Purchased V4 | E31: 34 | F31: =G31/E31 -> 280.35294 | G31: 9532 | I31: =G31/11 -> 866.54545
C33: 45552 | D33: 14 Units Purchased V4 | E33: 14 | F33: =G33/E33 -> 299.28571 | G33: 4190 | I33: =G33/11 -> 380.90909
C35: 45553 | D35: 62 Units Purchased V4 | E35: 62 | F35: =G35/E35 -> 297.98387 | G35: 18475 | I35: =G35/11 -> 1679.5455
C37: 45554 | D37: 5 Units Purchased V4 | E37: 5 | F37: =G37/E37 -> 298.2 | G37: 1491 | I37: =G37/11 -> 135.54545
C39: 45558 | D39: 15 Units Purchased V4 | E39: 15 | F39: =G39/E39 -> 297.53333 | G39: 4463 | I39: =G39/11 -> 405.72727
C41: 45559 | D41: 19 Units Purchased V4 | E41: 19 | F41: =G41/E41 -> 298.21053 | G41: 5666 | I41: =G41/11 -> 515.09091
C43: 45560 | D43: 12 Units Purchased V4 | E43: 12 | F43: =G43/E43 -> 302.58333 | G43: 3631 | I43: =G43/11 -> 330.09091
C45: 45561 | D45: 6 Units Purchased V4 | E45: 6 | F45: =G45/E45 -> 300.5 | G45: 1803 | I45: =G45/11 -> 163.90909
C47: 45562 | D47: 14 Units Purchased V4 | E47: 14 | F47: =G47/E47 -> 297.85714 | G47: 4170 | I47: =G47/11 -> 379.09091
C49: 45562 | D49: 100 Units Purchased V4 | E49: 100 | F49: =G49/E49 -> 298 | G49: 29800 | I49: =G49/11 -> 2709.0909
... C55: 45565 | D55: 15 Units Purchased V4 | E55: 15 | F55: =G55/E55 -> 298.66667 | G55: 4480 | I55: =G55/11 -> 407.27273
D57: TOTAL | E57: =SUM(E3:E56) -> 1664 | I57: =SUM(I3:I56) -> 48315.273
C60: Date | D60: Details | E60: Units | F60: Per.Unit | G60: Amount | I60: GST
C61: 45566 | D61: Starlink V4 2Units $299 GC Card | E61: 2 | F61: 299 | G61: =E61*F61 -> 598 | I61: =G61/11 -> 54.363636
C62: 45567 | D62: 14 Units Purchased V4 | E62: 14 | F62: =G62/E62 -> 298.14286 | G62: 4174 | I62: =G62/11 -> 379.45455
C63: 45568 | D63: 8 Units Purchased V4 | E63: 8 | F63: =G63/E63 -> 298 | G63: 2384 | I63: =G63/11 -> 216.72727
C64: 45570 | D64: 18 Units Purchased V4 | E64: 18 | F64: =G64/E64 -> 298.88889 | G64: 5380 | I64: =G64/11 -> 489.09091
C65: 45573 | D65: 2 Units Purchased V4 | E65: 2 | F65: =G65/E65 -> 299 | G65: 598 | I65: =G65/11 -> 54.363636
C66: 45575 | D66: 24 Units Purchased V4 | E66: 24 | F66: =G66/E66 -> 299.16292 | G66: 7179.91 | I66: =G66/11 -> 652.71909
C67: 45580 | D67: 55 Units Purchased V4 | E67: 55 | F67: =G67/E67 -> 318 | G67: 17490 | I67: =G67/11 -> 1590
D69: TOTAL | E69: =SUM(E61:E68) -> 123 | I69: =SUM(I61:I68) -> 3436.7191

Sheet Starlink Mini
B3: Date | C3: Details | D3: Units | F3: Amount | H3: GST
B4: 45547 | C4: 42 Units Purchased | D4: 42 | E4: =F4/D4 -> 770.83333 | F4: 32375 | H4: =F4/11 -> 2943.1818
B6: 45548 | C6: 10 Units Purchased | D6: 10 | E6: =F6/D6 -> 799 | F6: 7990 | H6: =F6/11 -> 726.36364
B8: 45551 | C8: 4 Units Purchased | D8: 4 | E8: =F8/D8 -> 781.5 | F8: 3126 | H8: =F8/11 -> 284.18182
B10: 45553 | C10: 64 Units Purchased | D10: 64 | E10: =F10/D10 -> 784.53125 | F10: 50210 | H10: =F10/11 -> 4564.5455
B12: 45554 | C12: 7 Units Purchased | D12: 7 | E12: =F12/D12 -> 790 | F12: 5530 | H12: =F12/11 -> 502.72727
B14: 45556 | C14: 30 Units Purchased | D14: 30 | E14: =F14/D14 -> 799 | F14: 23970 | H14: =F14/11 -> 2179.0909
B16: 45558 | C16: 5 Units Purchased | D16: 5 | E16: =F16/D16 -> 756.2 | F16: 3781 | H16: =F16/11 -> 343.72727
B18: 45559 | C18: 22 Units Purchased | D18: 22 | E18: =F18/D18 -> 757.81818 | F18: 16672 | H18: =F18/11 -> 1515.6364
B20: 45560 | C20: 1 Units Purchased | D20: 1 | E20: =F20/D20 -> 796 | F20: 796 | H20: =F20/11 -> 72.363636
C22: Total | D22: =SUM(D4:D21) -> 185 | H22: =SUM(H4:H21) -> 13131.818
B24: Date | C24: Details | D24: Units | F24: Amount | H24: GST
B25: 45566 | C25: 12 Units Purchased | D25: 12 | E25: 750 | F25: =D25*E25 -> 9000 | H25: =F25/11 -> 818.18182
B26: 45568 | C26: 2 Units Purchased | D26: 2 | E26: =F26/D26 -> 780 | F26: 1560 | H26: =F26/11 -> 141.81818
B27: 45569 | C27: 10 Units Purchased | D27: 10 | E27: =F27/D27 -> 768 | F27: 7680 | H27: =F27/11 -> 698.18182
B28: 45572 | C28: 11 Units Purchased | D28: 11 | E28: =F28/D28 -> 746.81818 | F28: 8215 | H28: =F28/11 -> 746.81818
B29: 45575 | C29: 1 Units Purchased | D29: 1 | E29: =F29/D29 -> 759 | F29: 759 | H29: =F29/11 -> 69
B30: 45576 | C30: 7 Units Purchased | D30: 7 | E30: =F30/D30 -> 755 | F30: 5285 | H30: =F30/11 -> 480.45455
B31: 45577 | C31: 50 Units Purchased | D31: 50 | E31: =F31/D31 -> 750 | F31: 37500 | H31: =F31/11 -> 3409.0909
B32: 45579 | C32: 10 Units Purchased | D32: 10 | E32: =F32/D32 -> 768 | F32: 7680 | H32: =F32/11 -> 698.18182
B33: 45580 | C33: 10 Units Purchased | D33: 10 | E33: =F33/D33 -> 799 | F33: 7990 | H33: =F33/11 -> 726.36364
C35: Total | D35: =SUM(D25:D34) -> 113 | H35: =SUM(H25:H34) -> 7788.0909
F41: Cash | I41: Sell
F42: 20345 | H42: 12 v4 | I42: =12*1190 -> 14280
F43: 15297 | H43: 15 mini | I43: =15*1650 -> 24750
F44: =SUM(F42:F43) -> 35642 | I44: =SUM(I42:I43) -> 39030

Sheet IPHONE
B2: Date | C2: Details | D2: Units | E2: Amount | G2: GST
B3: 45549 | C3: IPHONE 16 ProMax Purchased | D3: 33 | E3: 74639 | G3: =E3/11 -> 6785.3636
B4: 45575 | C4: IPHONE 16 ProMax Purchased | D4: 20 | E4: 44380 | G4: =E4/11 -> 4034.5455
C5: Total | D5: =SUM(D3:D4) -> 53 | G5: =SUM(G3:G4) -> 10819.909

Sheet DJI-Other
C3: Date | D3: Details | E3: Units | F3: Amount | H3: GST
C4: 45565 | D4: DJI Mavic 3Pro 2Unit WB Card $2550 | E4: 2 | F4: 5100 | H4: =F4/11 -> 463.63636
D6: Total | E6: =SUM(E4:E5) -> 2 | H6: =SUM(H4:H5) -> 463.63636
C13: Date | D13: Details | E13: Units | G13: Amount | I13: GST
C14: 45573 | D14: 15Units PS 5 | E14: 15 | F14: =G14/E14 -> 668 | G14: 10020 | I14: =G14/11 -> 910.90909
C15: 45573 | D15: 18 Units JBL Charge.5 | E15: 18 | F15: 312 | G15: =E15*F15 -> 5616 | I15: =G15/11 -> 510.54545
C16: 45573 | D16: 16 Units JBL Essential Flip2 | E16: 16 | F16: 76 | G16: =E16*F16 -> 1216 | I16: =G16/11 -> 110.54545
C17: 45575 | D17: 1 unit Starlink Camera | E17: 1 | F17: =G17/E17 -> 99 | G17: 99 | I17: =G17/11 -> 9
C18: 45567 | D18: Printer | E18: 1 | F18: 290 | G18: 290 | I18: =G18/11 -> 26.363636
D20: Total | E20: =SUM(E14:E19) -> 51 | I20: =SUM(I14:I19) -> 1567.3636

Sheet Total GST
C2: July - Sep
C3: Starlink V4 | D3: ='Starlink V4'!I57 -> 48315.273
C4: Starlink Mini | D4: ='Starlink Mini'!H22 -> 13131.818
C5: IPHONE 16ProMax | D5: =IPHONE!G3 -> 6785.3636
C6: DJI | D6: ='DJI-Other'!H6 -> 463.63636
C7: 1unit Returned | D7: -54
C8: Total | D8: =SUM(D3:D7) -> 68642.091
B10: 45602 | C10: Received WB A/C | D10: -68642.09
C20: Starlink V4 | D20: ='Starlink V4'!I57+'Starlink V4'!I69 -> 51751.992
C21: Starlink Mini | D21: ='Starlink Mini'!H22+'Starlink Mini'!H35 -> 20919.909
C22: IPHONE 16ProMax | D22: =IPHONE!G5 -> 10819.909
C23: DJI | D23: ='DJI-Other'!H6 -> 463.63636
C24: JBL | D24: ='DJI-Other'!I15+'DJI-Other'!I16 -> 621.09091
C25: PS 5 | D25: ='DJI-Other'!I14 -> 910.90909
C26: Starlink Camera | D26: ='DJI-Other'!I17 -> 9
C27: Printer | D27: ='DJI-Other'!I18 -> 26.363636
C29: Total | D29: =SUM(D20:D28) -> 85522.81 | E29: 2.5 | F29: =D29*E29 -> 213807.03

Sheet Australia Oct-Dec
C4: Date | D4: Details | E4: Units | F4: Per.Unit | G4: Amount | I4: GST
B5: ok | C5: 45566 | D5: Starlink V4 2Units $299 GC Card | E5: 2 | F5: 299 | G5: =E5*F5 -> 598 | I5: =G5/11 -> 54.363636
B6: ok | C6: 45567 | D6: 14 Units Purchased V4 | E6: 14 | F6: =G6/E6 -> 298.14286 | G6: 4174 | I6: =G6/11 -> 379.45455
B7: ok | C7: 45568 | D7: 8 Units Purchased V4 | E7: 8 | F7: =G7/E7 -> 298 | G7: 2384 | I7: =G7/11 -> 216.72727
B8: ok | C8: 45570 | D8: 18 Units Purchased V4 | E8: 18 | F8: =G8/E8 -> 298.88889 | G8: 5380 | I8: =G8/11 -> 489.09091
B9: ok | C9: 45573 | D9: 2 Units Purchased V4 | E9: 2 | F9: =G9/E9 -> 299 | G9: 598 | I9: =G9/11 -> 54.363636
B10: ok | C10: 45575 | D10: 24 Units Purchased V4 | E10: 24 | F10: =G10/E10 -> 299.16292 | G10: 7179.91 | I10: =G10/11 -> 652.71909
B11: ok | C11: 45580 | D11: 55 Units Purchased V4 | E11: 55 | F11: =G11/E11 -> 318 | G11: 17490 | I11: =G11/11 -> 1590
B13: ok | C13: 45566 | D13: 12 Units Purchased Mini | E13: 12 | F13: 750 | G13: =E13*F13 -> 9000 | I13: =G13/11 -> 818.18182
B14: ok | C14: 45568 | D14: 2 Units Purchased Mini | E14: 2 | F14: =G14/E14 -> 780 | G14: 1560 | I14: =G14/11 -> 141.81818
B15: ok | C15: 45569 | D15: 10 Units Purchased Mini | E15: 10 | F15: =G15/E15 -> 768 | G15: 7680 | I15: =G15/11 -> 698.18182
B16: ok | C16: 45572 | D16: 11 Units Purchased Mini | E16: 11 | F16: =G16/E16 -> 746.81818 | G16: 8215 | I16: =G16/11 -> 746.81818
B17: ok | C17: 45575 | D17: 1 Units Purchased Mini | E17: 1 | F17: =G17/E17 -> 759 | G17: 759 | I17: =G17/11 -> 69
B18: ok | C18: 45576 | D18: 7 Units Purchased Mini | E18: 7 | F18: =G18/E18 -> 755 | G18: 5285 | I18: =G18/11 -> 480.45455
B19: ok | C19: 45577 | D19: 50 Units Purchased Mini | E19: 50 | F19: =G19/E19 -> 750 | G19: 37500 | I19: =G19/11 -> 3409.0909
B20: ok | C20: 45579 | D20: 10 Units Purchased Mini | E20: 10 | F20: =G20/E20 -> 768 | G20: 7680 | I20: =G20/11 -> 698.18182
B21: ok | C21: 45580 | D21: 10 Units Purchased Mini | E21: 10 | F21: 799 | G21: =E21*F21 -> 7990 | I21: =G21/11 -> 726.36364
B23: ok | C23: 45573 | D23: 15Units PS 5 | E23: 15 | F23: =G23/E23 -> 668 | G23: 10020 | I23: =G23/11 -> 910.90909
B24: ok | C24: 45573 | D24: 18 Units JBL Charge.5 | E24: 18 | F24: 312 | G24: =E24*F24 -> 5616 | I24: =G24/11 -> 510.54545
B25: ok | C25: 45573 | D25: 16 Units JBL Essential Flip2 | E25: 16 | F25: 76 | G25: =E25*F25 -> 1216 | I25: =G25/11 -> 110.54545
B26: ok | C26: 45575 | D26: 1 unit Starlink Camera | E26: 1 | F26: =G26/E26 -> 99 | G26: 99 | I26: =G26/11 -> 9
B27: ok | C27: 45567 | D27: Printer | E27: 1 | F27: 290 | G27: 290 | I27: =G27/11 -> 26.363636
B29: ok | C29: 45575 | D29: IPHONE 16 ProMax Purchased | E29: 20 | F29: =G29/E29 -> 2219 | G29: 44380 | I29: =G29/11 -> 4034.5455
B31: ok | C31: 45584 | D31: Purchase 20 Units Mini $745 | E31: 20 | F31: 745 | G31: =E31*F31 -> 14900 | I31: =G31/11 -> 1354.5455
B32: ok | C32: 45588 | D32: Purchase 8 Units Mini $745 | E32: 8 | F32: 745 | G32: =E32*F32 -> 5960 | I32: =G32/11 -> 541.81818
B34: ok | C34: 45591 | D34: Charge.5 45Units $142 | E34: 45 | F34: 142 | G34: =E34*F34 -> 6390 | I34: =G34/11 -> 580.90909
B35: ok | C35: 45591 | D35: Flip Essential 2 14Units $68 | E35: 14 | F35: 68 | G35: =E35*F35 -> 952 | I35: =G35/11 -> 86.545455
B36: ok | C36: 45591 | D36: PS5 10 Units $669 | E36: 10 | F36: 669 | G36: =E36*F36 -> 6690 | I36: =G36/11 -> 608.18182
B37: ok | C37: 45591 | D37: IP 16ProMax 256GB 1.Unit $2147 | E37: 1 | F37: 2147 | G37: =E37*F37 -> 2147 | I37: =G37/11 -> 195.18182
B38: ok | C38: 45591 | D38: Starlink Mini 30 Units $745 | E38: 30 | F38: 745 | G38: =E38*F38 -> 22350 | I38: =G38/11 -> 2031.8182
B39: ok | C39: 45591 | D39: Charge.5 100 Units $145 | E39: 100 | F39: =G39/E39 -> 0 | G39: 0 | I39: =G39/11 -> 0 | J39: Returned
B40: ok | C40: 45591 | D40: Flip Essential 2 100 Units $68 | E40: 100 | F40: =G40/E40 -> 0 | G40: 0 | I40: =G40/11 -> 0 | J40: Returned
B41: ok | C41: 45591 | D41: PS5 2 Units $675 | E41: 2 | F41: 675 | G41: =E41*F41 -> 1350 | I41: =G41/11 -> 122.72727
B42: ok | C42: 45591 | D42: Charge.5 100 Units $133.3 | E42: 100 | F42: 133.3 | G42: =E42*F42 -> 13330 | I42: =G42/11 -> 1211.8182
B43: ok | C43: 45591 | D43: Charge.5 34 Units $133.3 | E43: 34 | F43: 133.3 | G43: =E43*F43 -> 4532.2 | I43: =G43/11 -> 412.01818
B44: ok | C44: 45591 | D44: Starlink Mini 10 Units $768 | E44: 10 | F44: =G44/E44 -> 0 | G44: 0 | I44: =G44/11 -> 0 | J44: Returned
B45: ok | C45: 45591 | D45: Instax Camera 7units $95 | E45: 7 | F45: 95 | G45: =E45*F45 -> 665 | I45: =G45/11 -> 60.454545
C47: 45593 | D47: Starlink Mini 100 Units $750 | E47: 100 | F47: 0 | G47: =E47*F47 -> 0 | I47: =G47/11 -> 0 | J47: Returned
C48: 45593 | D48: DJI MavicPro 10Units $2500 | E48: =10-8 -> 2 | F48: =G48/E48 -> 2500 | G48: 5000 | I48: =G48/11 -> 454.54545 | J48: 8 Units Returned
C49: 45593 | D49: PS5 2 Units $669 | E49: 2 | F49: 669 | G49: =E49*F49 -> 1338 | I49: =G49/11 -> 121.63636
...

Sheet NewZealand Oct-Dec
C4: Date | D4: Details | E4: Units | F4: Per.Unit | G4: Amount | I4: GST
C6: 45621 | D6: Starlink Mini 3Units $649 | E6: 3 | F6: =G6/E6 -> 649 | G6: =3*649 -> 1947 | I6: =G6*13.04/100 -> 253.8888
C7: 45621 | D7: Charge.5 2Units $145 | E7: 2 | F7: =G7/E7 -> 145 | G7: =145*2 -> 290 | I7: =G7*13.04/100 -> 37.816
C8: 45621 | D8: PS5 2Units $692 | E8: 2 | F8: =G8/E8 -> 692 | G8: =692*2 -> 1384 | I8: =G8*13.04/100 -> 180.4736
C9: 45621 | D9: PS5 10Units $692 | E9: 10 | F9: =G9/E9 -> 692 | G9: =10*692 -> 6920 | I9: =G9*13.04/100 -> 902.368
C10: 45621 | D10: PS5 2Units $692 | E10: 2 | F10: =G10/E10 -> 692 | G10: =2*692 -> 1384 | I10: =G10*13.04/100 -> 180.4736
C11: 45621 | D11: Starlink Mini 1Unit $649 | E11: 1 | F11: =G11/E11 -> 649 | G11: =1*649 -> 649 | I11: =G11*13.04/100 -> 84.6296
C12: 45621 | D12: Starlink Mini 10Unit $649 | E12: 10 | F12: =G12/E12 -> 649 | G12: =10*649 -> 6490 | I12: =G12*13.04/100 -> 846.296
C13: 45621 | D13: Starlink V4 5Units $529 | E13: 5 | F13: =G13/E13 -> 529 | G13: =5*529 -> 2645 | I13: =G13*13.04/100 -> 344.908
C14: 45621 | D14: Starlink Mini 5Unit $644 | E14: 5 | F14: =G14/E14 -> 644 | G14: =5*644 -> 3220 | I14: =G14*13.04/100 -> 419.888
C15: 45621 | D15: Starlink V4 6Units $598 | E15: 6 | F15: =G15/E15 -> 598 | G15: =598*6 -> 3588 | I15: =G15*13.04/100 -> 467.8752
C17: 45622 | D17: Starlink V4 10units $598 WB Card | E17: 10 | F17: =G17/E17 -> 598 | G17: =598*10 -> 5980 | I17: =G17*13.04/100 -> 779.792
C18: 45622 | D18: Starlink Mini 1unit $649 WB Card | E18: 1 | F18: =G18/E18 -> 649 | G18: =649*1 -> 649 | I18: =G18*13.04/100 -> 84.6296
C19: 45622 | D19: Starlink Mini 4unit $649 WB Card | E19: 4 | F19: =G19/E19 -> 649 | G19: =649*4 -> 2596 | I19: =G19*13.04/100 -> 338.5184
C20: 45622 | D20: JBL Charge.5 25Units $128 WB Card | E20: 25 | F20: =G20/E20 -> 128 | G20: =128*25 -> 3200 | I20: =G20*13.04/100 -> 417.28
C21: 45622 | D21: Starlink Mini 2unit $649 WB Card | E21: 2 | F21: =G21/E21 -> 649 | G21: =649*2 -> 1298 | I21: =G21*13.04/100 -> 169.2592
C23: 45622 | D23: Starlink Mini 1unit $649 WB Card | E23: 1 | F23: =G23/E23 -> 649 | G23: =1*649 -> 649 | I23: =G23*13.04/100 -> 84.6296
C24: 45622 | D24: Starlink V4 50units $598 WB Card | E24: 50 | F24: =G24/E24 -> 598 | G24: =50*598 -> 29900 | I24: =G24*13.04/100 -> 3898.96
C26: 45623 | D26: Starlink Mini 46Units $644 WB Card | E26: 46 | F26: =G26/E26 -> 644 | G26: =46*644 -> 29624 | I26: =G26*13.04/100 -> 3862.9696
C27: 45623 | D27: Starlink V4 10Units $530 WB Card | E27: 10 | F27: =G27/E27 -> 530 | G27: =10*530 -> 5300 | I27: =G27*13.04/100 -> 691.12
C28: 45623 | D28: Starlink Mini 5Units $649 WB Card | E28: 5 | F28: =G28/E28 -> 649 | G28: =5*649 -> 3245 | I28: =G28*13.04/100 -> 423.148
C29: 45623 | D29: Starlink Mini 4Units $649 WB Card | E29: 4 | F29: =G29/E29 -> 649 | G29: =4*649 -> 2596 | I29: =G29*13.04/100 -> 338.5184
C30: 45623 | D30: Starlink V4 2Units $529 WB Card | E30: 2 | F30: =G30/E30 -> 529 | G30: =2*529 -> 1058 | I30: =G30*13.04/100 -> 137.9632
C31: 45623 | D31: Starlink Mini 3Units $649 WB Card | E31: 3 | F31: =G31/E31 -> 649 | G31: =3*649 -> 1947 | I31: =G31*13.04/100 -> 253.8888
C33: 45624 | D33: Starlink Mini 1Unit $649 WB Card | E33: 1 | F33: =G33/E33 -> 649 | G33: =1*649 -> 649 | I33: =G33*13.04/100 -> 84.6296
C34: 45624 | D34: Starlink Mini 2Unit $649 WB Card | E34: 2 | F34: =G34/E34 -> 649 | G34: =2*649 -> 1298 | I34: =G34*13.04/100 -> 169.2592
C35: 45624 | D35: Starlink Mini 10Unit $649 WB Card | E35: 10 | F35: =G35/E35 -> 649 | G35: =10*649 -> 6490 | I35: =G35*13.04/100 -> 846.296
C36: 45624 | D36: Starlink V4 23Units $530 WB Card | E36: 23 | F36: =G36/E36 -> 530 | G36: =530*23 -> 12190 | I36: =G36*13.04/100 -> 1589.576
C37: 45624 | D37: Starlink Mini 20Unit $649 WB Card | E37: 20 | F37: =G37/E37 -> 649 | G37: =649*20 -> 12980 | I37: =G37*13.04/100 -> 1692.592
C39: 45625 | D39: Starlink V4 22Units $530 WB Card | E39: 22 | F39: =G39/E39 -> 530 | G39: =22*530 -> 11660 | I39: =G39*13.04/100 -> 1520.464
C40: 45625 | D40: Starlink Mini 100Unit $649 WB Card | E40: 100 | F40: =G40/E40 -> 649 | G40: =649*100 -> 64900 | I40: =G40*13.04/100 -> 8462.96
C42: 45635 | D42: Starlink Mini 8Units $649 WB Card | E42: 8 | F42: =G42/E42 -> 649 | G42: =649*8 -> 5192 | I42: =G42*13.04/100 -> 677.0368
C43: 45635 | D43: PS5 1unit $695 WB Card | E43: 1 | F43: =G43/E43 -> 695 | G43: =695*1 -> 695 | I43: =G43*13.04/100 -> 90.628
C44: 45635 | D44: Starlink V4 1Unit $599 WB Card | E44: 1 | F44: =G44/E44 -> 599 | G44: =599*1 -> 599 | I44: =G44*13.04/100 -> 78.1096
C45: 45635 | D45: PS5 50unit $695 WB Card | E45: 50 | F45: =G45/E45 -> 0 | G45: 0 | I45: =G45*13.04/100 -> 0 | J45: Returned
C47: 45636 | D47: Starlink V4 1Unit $599 WB Card | E47: 1 | F47: =G47/E47 -> 599 | G47: =599*1 -> 599 | I47: =G47*13.04/100 -> 78.1096
C48: 45636 | D48: Starlink V4 2Unit $550 WB Card | E48: 2 | F48: =G48/E48 -> 550 | G48: =2*550 -> 1100 | I48: =G48*13.04/100 -> 143.44
C49: 45636 | D49: Starlink Mini 10Units $649 WB Card | E49: 10 | F49: =G49/E49 -> 649 | G49: =649*10 -> 6490 | I49: =G49*13.04/100 -> 846.296
C50: 45636 | D50: Starlink Mini 36Units $620 WB Card | E50: 36 | F50: =G50/E50 -> 620 | G50: =36*620 -> 22320 | I50: =G50*13.04/100 -> 2910.528
C52: 45637 | D52: Starlink Mini 35Units $620 WB Card | E52: 35 | F52: =G52/E52 -> 620 | G52: =35*620 -> 21700 | I52: =G52*13.04/100 -> 2829.68
...

Sheet Sheet1
