Workbook

Sheet Summary (2)
A1: Dubai selling ledger
A2: DATE | B2: DETAIL | C2: Total Amount | D2: Paid | E2: Balance
A3: 45838 | B3: Invoice 1 | C3: ='[1]invoice 1'!F60 -> 141530 | E3: =C3 -> 141530
A4: 45839 | B4: PAID TO Hawla person | D4: 100000 | E4: =E3-D4 -> 41530
A5: 45839 | B5: PAID TO WAJAHAT | D5: 41000 | E5: =E4-D5 -> 530
A7: 45840 | B7: Invoice 2 | C7: ='[1]invoice 2'!F52 -> 117290 | E7: =E5+C7 -> 117820
A8: 45842 | B8: PAID TO WAJAHAT | D8: 10000 | E8: =E7-D8 -> 107820
A9: 45842 | B9: 8 Device Return | D9: =[1]Return!E12 -> 27090 | E9: =E8-D9 -> 80730
A10: 45845 | B10: Hawala 39,00000 @79.20 | D10: 49242.42 | E10: =E9-D10 -> 31487.58 | F10: -758
A12: 45828 | B12: 882190243917 (386$ @3.678) | D12: =3.678*386 -> 1419.708 | E12: =E10-D12 -> 30067.872
A13: 45831 | B13: 882247971323 (525$ @3.678) | D13: =3.678*525 -> 1930.95 | E13: =E12-D13 -> 28136.922
A14: 45832 | B14: 882279322688 (507$ @3.678) | D14: =3.678*507 -> 1864.746 | E14: =E13-D14 -> 26272.176
A15: 45845 | B15: Clearing Charges 3 x 650 AED | D15: =650*3 -> 1950 | E15: =E14-D15 -> 24322.176
A16: 45841 | B16: 882482082780 (39$ @3.678) usa to usa | D16: =3.678*39 -> 143.442 | E16: =E15-D16 -> 24178.734
A17: 45845 | B17: ONLINE PAYMENT PKR 500000 @79.20 | D17: =500000/79.2 -> 6313.1313 | E17: =E16-D17 -> 17865.603
A18: 45845 | B18: CASH PAYMENT PKR 646500 @79.20 | D18: =646500/79.2 -> 8162.8788 | E18: =E17-D18 -> 9702.7239
A19: 45846 | B19: ONLINE PAYMENT PKR 500000 @79.20 | D19: =500000/79.2 -> 6313.1313 | E19: =E18-D19 -> 3389.5926 | F19: -63
A20: 45848 | B20: ONLINE PAYMENT PKR 268450 @79.20 | D20: =268450/79.2 -> 3389.5202 | E20: =E19-D20 -> 0.072383838
A22: 45848 | B22: Invoice 3 | C22: ='[1]invoice 3'!E97 -> 228660 | E22: =E20+C22 -> 228660.07
A23: 45849 | B23: PAID TO WAJAHAT | D23: 100000 | E23: =E22-D23 -> 128660.07
A24: 45850 | B24: PAID TO MUDDASSIR @79.60 (60k) clear | D24: 100000 | E24: =E23-D24 -> 28660.072
B25: 882482082780(500$ @3.678) | D25: =500*3.678 -> 1839 | E25: =E24-D25 -> 26821.072
B26: 882523663746(500$ @3.678) | D26: =500*3.678 -> 1839 | E26: =E25-D26 -> 24982.072
B27: 882514974053(350$ @3.678) | D27: =350*3.678 -> 1287.3 | E27: =E26-D27 -> 23694.772
B28: Clearing Charges 3 x 650 AED | D28: =3*650 -> 1950 | E28: =E27-D28 -> 21744.772
D29: 21745 | E29: =E28-D29 -> -0.22761616
A30: 45854 | B30: Invoice 4 | C30: ='[1]invoice 4'!E79 -> 155410 | E30: =E29+C30 -> 155409.77
A31: 45857 | B31: PAID TO MUDDASSIR@79.70 (475500) clear | D31: 100000 | E31: =E30-D31 -> 55409.772 | F31: -5966
A32: 45860 | B32: PAID TO MUDDASSIR @79.70 | D32: 50000 | E32: =E31-D32 -> 5409.7724 | F32: 1000
A34: 45859 | B34: Invoice 5 | C34: ='[1]invoice 5'!E64 -> 113640 | E34: =E32+C34 -> 119049.77
A35: 45859 | B35: Invoice 6 | C35: ='[1]invoice 6'!E18 -> 30750 | E35: =+E34+C35 -> 149799.77
A36: 45860 | B36: Invoice 7 | C36: ='[1]invoice 07'!E56 -> 130820 | E36: =+E35+C36 -> 280619.77
A37: 45862 | B37: PAID TO MUDDASSIR @79.80 | D37: 152783.21 | E37: =E36-D37 -> 127836.56 | F37: 5508
A38: 45864 | B38: PAID TO MUDDASSIR ACC 79.80 (17 LAC) | D38: =1700000/79.8 -> 21303.258 | E38: =E37-D38 -> 106533.31
A39: 45867 | B39: paid to MUDDASSIR CASH @79.6 (1CR) | D39: =10000000/79.6 -> 125628.14 | E39: =E38-D39 -> -19094.834
A41: 45868 | B41: Invoice 8 | C41: ='[2]invoice 8'!E34 -> 77890 | E41: =E39+C41 -> 58795.166
A42: 45868 | B42: Invoice 9 | C42: ='[2]Invoice 09'!E33 -> 72940 | E42: =E41+C42 -> 131735.17
A43: 45868 | B43: Invoice 10 | C43: ='[2]Invoice 10'!E64 -> 140580 | E43: =E42+C43 -> 272315.17
A44: 45868 | B44: Paid to Muddassir Cash @79.60 (2CR) | D44: =20000000/79.6 -> 251256.28 | E44: =E43-D44 -> 21058.884
A46: 45869 | B46: Inovice 11 | C46: ='[2]invoice 11'!E34 -> 61670 | E46: =E44+C46 -> 82728.884
...

Sheet Invoice 19
A1: Invoice no 19 | C1: Tracking(RichMond) 883788751040 , 883788751050 | E1: Dated:08-9-2025
A2: S.No | B2: Imei | C2: Description | D2: Status | E2: Price | F2: comments
A3: 1 | B3: 355205565078322 | C3: Ipad A16 128gb Blue | D3: Non-Active | E3: 1230
A4: 2 | B4: 351159274033801 | C4: Ipad A16 128gb Blue (Not For Sale) | D4: Non-Active | E4: 0
A5: 3 | B5: 357241839849014 | C5: Ipad Air 11" W+C 128gb Grey | D5: Active | E5: 0
A6: 4 | B6: 352066340242846 | C6: Ipad Pro 13" W+C Black 512gb | D6: Non-Active | E6: 3700
A7: 5 | B7: 352113554059969 | C7: Iphone 16 Plus Black 256gb | D7: Non-Active | E7: 1650
A8: 6 | B8: 359103743398249 | C8: Iphone 16 Plus White 256gb (Not for Sale) | D8: Non-Active | E8: 0
A9: 7 | B9: 350773435149214 | C9: Iphone 16 PM BT 256gb | D9: Non-Active | E9: 0
A10: 8 | B10: 354737615968772 | C10: Iphone 16 PM BT 256gb | D10: Non-Active | E10: 2400
A11: 9 | B11: 350773432025912 | C11: Iphone 16 PM BT 512gb | D11: Non-Active | E11: 2600
A12: 10 | B12: 356864560693441 | C12: Iphone 16 PM DT 256gb | D12: Non-Active | E12: 2600
A13: 11 | B13: 350773436287461 | C13: Iphone 16 PM DT 256gb | E13: 2600
A14: 12 | B14: 358536505368341 | C14: Iphone 16 PM DT 256gb | D14: Non-Active | E14: 2600
A15: 13 | B15: 350773435256399 | C15: Iphone 16 PM DT 256gb | D15: Non-Active | E15: 2600
A16: 14 | B16: 359518871681035 | C16: Iphone 16 PM DT 256gb | D16: Non-Active | E16: 2600
A17: 15 | B17: 359518871696397 | C17: Iphone 16 PM DT 256gb | D17: Non-Active | E17: 2600
A18: 16 | B18: 356541627059804 | C18: Iphone 16 PM DT 256gb (Not For Sale) | D18: Non-Active | E18: 0
A19: 17 | B19: 356541627220604 | C19: Iphone 16 PM DT 256gb (Not For Sale) | D19: Non-Active | E19: 0
A20: 18 | B20: 350773436239881 | C20: Iphone 16 PM DT 256gb | D20: Non-Active | E20: 2600
A21: 19 | B21: 359297748848305 | C21: Iphone 16 Pro BT 128gb | D21: Non-Active | E21: 1950
A22: 20 | B22: 356102155547585 | C22: Iphone 16 Pro BT 128gb | D22: Non-Active | E22: 1950
A23: 21 | B23: 359072843554185 | C23: Iphone 16 Pro BT 128gb | D23: Non-Active | E23: 1950
A24: 22 | B24: 357719288598851 | C24: Iphone 16 Pro BT 256gb | D24: Non-Active | E24: 2050
A25: 23 | B25: 356043388952418 | C25: Iphone 16 Pro BT 512gb | D25: Non-Active | E25: 2150
... A32: 30 | B32: 359896928540622 | C32: Iphone 16 Pro DT 128gb | D32: Non-Active | E32: 2070
A33: 31 | B33: 357463445435067 | C33: Iphone 16 Pro DT 256gb | D33: Active | E33: 0 | F33: icloud
A34: 32 | B34: 350319297885824 | C34: Iphone 16 Pro DT 256gb | D34: Non-Active | E34: 2200
A35: 33 | B35: 351895498835154 | C35: Iphone 16 Pro DT 512gb | D35: Non-Active | E35: 2300
A36: 34 | B36: 351895498911633 | C36: Iphone 16 Pro DT 512gb | D36: Non-Active | E36: 2300
A37: 35 | B37: 350922055792619 | C37: Iphone 16 Pro NT 128gb | D37: Non-Active | E37: 2000
A38: 36 | B38: 353685838933977 | C38: Iphone 16 UMR 128gb (Not for Sale) | D38: Non-Active | E38: 0
A39: 37 | B39: 354741559011540 | C39: Iphone 16e White 128gb (Not for Sale) | D39: Non-Active | E39: 0
A40: 38 | B40: 351791641715882 | C40: Iwatch Series 10 42mm Silver | D40: Non-Active | E40: 1220
A41: 39 | B41: 358712821134465 | C41: Iwatch Ultra 2 Black | D41: Non-Active | E41: 2100
A42: 40 | B42: 358712821369715 | C42: Iwatch Ultra 2 Black | D42: Non-Active | E42: 2100
A43: 41 | B43: 356706680040211 | C43: Iwatch Ultra 2 Black | D43: Active | E43: 0
A44: 42 | B44: 358712821193172 | C44: Iwatch Ultra 2 Black | D44: Non-Active | E44: 2100
A45: 43 | B45: 352905160257451 | C45: Iwatch Ultra 2 Black | D45: Active | E45: 0
... A48: 46 | B48: 352905161172642 | C48: Iwatch Ultra 2 Black | D48: Non-Active | E48: 2100
...

Sheet Sheet1
A2: 1 | B2: 352512146942626 | C2: Samsung S25 Ultra TSB 256gb
A3: 2 | B3: 352512147363442 | C3: Samsung S25 Ultra TSB 256gb
A4: 3 | B4: 352512147259350 | C4: Samsung S25 Ultra TB 512gb
A5: 4 | B5: 359800202559886 | C5: Galaxy Z Flip7 Blue Shadow 256gb
A6: 5 | B6: 352892774247476
A7: 6 | B7: 352892775339173 | C7: Galaxy S25+ Navy 256gb
A8: 7 | B8: 358754771592003 | C8: Samsung S25 Ultra TB 256gb
A9: 8 | B9: 356930603727890 | C9: Samsung S25 Ultra TB 256gb
A10: 9 | B10: 359373961827191 | C10: Samsung S25 Ultra TSB 256gb
A11: 10 | B11: 350472953012256 | C11: Samsung Fold 7 256gb Jet Black
A12: 11 | B12: 352892775884764 | C12: Samsung S25+ Navy 256gb
A13: 12 | B13: 350472953010417 | C13: Samsung Fold 7 256gb Jet Black
A14: 13 | B14: 352512146860109 | C14: Samsung S25 Ultra 256gb TSB
A15: 14 | B15: 352512147386971 | C15: Samsung S25 Ultra TSB 256gb
A16: 15 | B16: 359800202704433 | C16: Samsung Zflip7 Blue Shadow 256gb
A17: 16 | B17: 352512147346579 | C17: Samsung S25 ultra TB 256gb
A18: 17 | B18: 352512147412439 | C18: Samsung S25 Ultra TSB 256gb
... A21: 20 | B21: 359373961877162 | C21: Samsung S25 Ultra 256gb TSB
A22: 21 | C22: Samsung S25 Ultra
A23: 22 | B23: 358910534765399 | C23: Samsung Fold 7 JB 512gb
A24: 23 | B24: 352512147290561 | C24: Samsung S25 Ultra TB 256gb
A25: 24 | B25: 352512147338402 | C25: Samsung S25 Ultra TB 256gb

Sheet Invoice 20
A1: Invoice no 20 | C1: Tracking(BoilingBrook) 883946231157 | E1: Dated: 06-09-2025
A2: S.No | B2: Imei | C2: Description | D2: Status | E2: Price | F2: comments
A3: 1 | B3: 351159276226528 | C3: Ipad A16 128gb Pink (Not For Sale) | D3: Non-Active | E3: 0
A4: 2 | B4: 354895822268723 | C4: Ipad Pro 13" W+C 256gb | D4: Non-Active | E4: 3600
A5: 3 | B5: 351614406777634 | C5: Iphone 16 PM BT 256gb | D5: Non-Active | E5: 2400
A6: 4 | B6: 355008285776597 | C6: Iphone 16 PM BT 256gb | D6: Non-Active | E6: 2400
A7: 5 | B7: 355008285815761 | C7: Iphone 16 PM BT 256gb (Not For Sale) | D7: Non-Active | E7: 0
A8: 6 | B8: 352864975103154 | C8: Iphone 16 PM BT 256gb | D8: Non-Active | E8: 2400
A9: 7 | B9: 353393810731952 | C9: Iphone 16 PM BT 256gb | D9: Non-Active | E9: 2400
A10: 8 | B10: 351614405635130 | C10: Iphone 16 PM BT 256gb | D10: Non-Active | E10: 2400
A11: 9 | B11: 359518871710263 | C11: Iphone 16 PM BT 256gb | D11: Non-Active | E11: 2400
A12: 10 | B12: 355008286990688 | C12: Iphone 16 PM BT 256gb | D12: Non-Active | E12: 2400
A13: 11 | B13: 355008286621986 | C13: Iphone 16 PM BT 256gb | D13: Non-Active | E13: 2400
A14: 12 | B14: 354959418979257 | C14: Iphone 16 PRO BT 256gb | D14: Non-Active | E14: 2050
... A26: 24 | B26: 358712821026505 | C26: Iwatch ultra 2 | D26: Non-Active | E26: 2100
A27: 25 | B27: 355767493958579 | C27: Iwatch ultra 2 | D27: ACTIVE | E27: 0 | F27: return
A28: 26 | B28: 356245748827087 | C28: Iwatch ultra 2 | D28: Non-Active | E28: 2100
A29: 27 | B29: 358910534765399 | C29: Samsung Fold 7 JB 512gb | E29: 0
A30: 28 | C30: Samsung S25 Ultra | E30: 1900
A31: 29 | B31: 352512147290561 | C31: Samsung S25 Ultra TB 256gb | E31: 1900
A32: 30 | B32: 352512147338402 | C32: Samsung S25 Ultra TB 256gb | E32: 1900
E34: =SUM(E3:E33) -> 58200

Sheet Invoice 21
A1: Invoice no 21 | C1: (IL Kamal) 884247722815 , 884247722826 | E1: Dated: 12/9/2025
A2: S.No | B2: Imei | C2: Description | D2: Status | E2: Price | F2: comments
A3: 1 | B3: 195949644184 | C3: Apple Watch SE Gen 2 | E3: 800
A4: 2 | B4: 351159273601947 | C4: Ipad A16 Blue 128gb | D4: non active | E4: 1250
A5: 3 | B5: 351159272533240 | C5: Ipad A16 Blue 128gb | D5: non active | E5: 1250
A6: 4 | B6: 355205565958531 | C6: Ipad A16 Blue 128gb | D6: non active | E6: 1250
A7: 5 | B7: 355205560042368 | C7: Ipad A16 Pink 128gb | E7: 0 | F7: NOT for sale
A8: 6 | B8: 353357700010629 | C8: Ipad Pro 11" W+C Black 256gb | D8: non active | E8: 3350
A9: 7 | B9: 352628450268098 | C9: Ipad Pro 11" W+C Black 256gb | E9: 3350
A10: 8 | B10: 352628750865893 | C10: Ipad Pro 11" W+C Black 256gb | E10: 3350
A11: 9 | B11: 353357701114677 | C11: Ipad Pro 11" W+C Black 256gb | E11: 3350
A12: 10 | B12: 356334540676163 | C12: Ipad Pro 13" W+C Black 256gb | D12: non active | E12: 3600
A13: 11 | B13: 352066341452394 | C13: Ipad Pro 13" W+C Black 256gb | D13: non active | E13: 3600
A14: 12 | B14: 355067547673574 | C14: Iphone 16 PM BT 256gb | D14: non active | E14: 2400
A15: 13 | B15: 355688666943710 | C15: Iphone 16 PM BT 256gb | D15: non active | E15: 2400
A16: 14 | B16: 355688666763647 | C16: Iphone 16 PM BT 256gb | D16: non active | E16: 2400 | G16: 78.55 | H16: =G16*50000 -> 3927500
A17: 15 | B17: 350773434294243 | C17: Iphone 16 PM BT 256gb | E17: 2400 | H17: 1400000
A18: 16 | B18: 354737617419824 | C18: Iphone 16 PM BT 256gb | E18: 2400 | H18: =SUM(H16:H17) -> 5327500
A19: 17 | B19: 359518872961618 | C19: Iphone 16 PM BT 512gb | D19: non active | E19: 2600 | H19: =H18-1000000 -> 4327500
A20: 18 | B20: 359518872834344 | C20: Iphone 16 PM BT 512gb | D20: active | E20: 0 | F20: RETURN
A21: 19 | B21: 359518872864655 | C21: Iphone 16 PM BT 512gb | E21: 2550
A22: 20 | B22: 354737617306302 | C22: Iphone 16 PM DT 256gb | D22: non active | E22: 2600
A23: 21 | B23: 350773437250861 | C23: Iphone 16 PM DT 256gb | E23: 2600
A24: 22 | B24: 356864568651184 | C24: Iphone 16 PM WT 256gb | E24: 2500
A25: 23 | B25: 358282727992861 | C25: Iphone 16 Pro BT 128gb | D25: non active | E25: 1950
A26: 24 | B26: 358157744692753 | C26: Iphone 16 Pro BT 256gb | D26: active | E26: 2000
A27: 25 | B27: 351670274175228 | C27: Iphone 16 Pro BT 256gb | D27: active | E27: 2000
A28: 26 | B28: 356043387959877 | C28: Iphone 16 Pro DT 128gb | D28: non active | E28: 2070
A29: 27 | B29: 357017258455875 | C29: Iphone 16 Pro DT 256gb | D29: non active | E29: 2200
A30: 28 | B30: 357463447423939 | C30: Iphone 16 Pro DT 256gb | D30: active | E30: 2150
A31: 29 | B31: 358282720893934 | C31: Iphone 16 Pro NT 256gb | D31: active | E31: 2050
A32: 30 | B32: 350159563742162 | C32: Iwatch Series 10 42mm Rose Gold | D32: non active | E32: 1250
A33: 31 | B33: 356706680326768 | C33: Iwatch Ultra 2 BT | D33: non active | E33: 2100
A34: 32 | B34: 356706681387959 | C34: Iwatch Ultra 2 BT | D34: non active | E34: 2100
A35: 33 | B35: 355767491947284 | C35: Iwatch Ultra 2 BT | D35: non active | E35: 2100
A36: 34 | B36: 356706681516581 | C36: Iwatch Ultra 2 BT | D36: active | E36: 2050
... A41: 39 | B41: 352905160604082 | C41: Iwatch Ultra 2 BT | D41: non active | E41: 2100
A42: 40 | B42: 355767493819945 | C42: Iwatch Ultra 2 BT | E42: 2100
A43: 41 | B43: 356706681332328 | C43: Iwatch Ultra 2 BT | E43: 0 | F43: RETURN
A44: 42 | B44: 351880301305124 | C44: Samsung Galaxy Watch Ultra | E44: 0 | F44: RETURN
...

Sheet Invoice 22
A1: Invoice no 22 | C1: Label by AR 884240212850 | E1: Dated:19-09-2025
A2: S.No | B2: Imei | C2: Description | D2: Status | E2: Price | F2: Comments
A3: 1 | B3: 358862985518928 | C3: 16 pro max DT 256 | E3: 2670
A4: 2 | B4: 356864566576244 | C4: 16 pro max DT 256 | E4: 2670
A5: 3 | B5: 359518871023576 | C5: 16 pro max BT 256 | D5: active | E5: 2380
A6: 4 | B6: 354737617076376 | C6: 16 pro max BT 256 | E6: 2430
A7: 5 | B7: 351614406866155 | C7: 16 pro max BT 256 | E7: 2430
A8: 6 | B8: 354210977905105 | C8: 16 pro max BT 256 | E8: 2430
A9: 7 | B9: 354210977021285 | C9: 16 pro max BT 256 | E9: 2430
A10: 8 | B10: 352864978238106 | C10: 16 pro max BT 256 | E10: 2430
A11: 9 | B11: 351614406878523 | C11: 16 pro max BT 256 | E11: 2430
A12: 10 | B12: 354210975224540 | C12: 16 pro max BT 256 | D12: active | E12: 2380
A13: 11 | B13: 356864566698261 | C13: 16 pro max BT 256 | D13: active | E13: 2380
A14: 12 | B14: 350778436919805 | C14: 16 pro max BT 256 | E14: 2430
A15: 13 | B15: 352315400518375 | C15: 16 pro max WT 256 | E15: 2530
A16: 14 | B16: 356541629862825 | C16: 16 pro max WT 256 | E16: 2530
A17: 15 | B17: 350773437481920 | C17: 16 pro max NT 256 | E17: 2530
A18: 16 | B18: 350773437482639 | C18: 16 pro max NT 256 | E18: 2530
A19: 17 | B19: 355031537699841 | C19: 16 pro DT 256 | E19: 2250
A20: 18 | B20: 357017255992102 | C20: 16 pro DT 128 | E20: 2130
A21: 19 | B21: 358282727518922 | C21: 16 pro DT 128 | E21: 2130
A22: 20 | B22: 359896926735232 | C22: 16 pro DT 128 | E22: 2130
A23: 21 | B23: 354959416652773 | C23: 16 pro DT 128 | E23: 2130
A24: 22 | B24: 356312635042750 | C24: 16 e black | E24: 830
A25: 23 | B25: 352512147219875 | C25: Samsung S25 Ultra 256 | E25: 1920
... A37: 35 | B37: 356334540672956 | C37: Ipad Pro M4 13" 256 W+C | E37: 3600
E38: =SUM(E3:E37) -> 79230

Sheet Invoice 23
A1: Invoice no 23 | C1: CANDA | E1: Dated:19-09-2025
A2: S.No | B2: Imei | C2: Description | D2: Status | E2: Price | F2: Comments
A3: 1 | B3: 350523896086276 | C3: 16 pro max DT 256 | E3: 2600
A4: 2 | B4: 357988125804976 | C4: 16 pro max DT 256 | E4: 2600
A5: 3 | B5: 359974602075270 | C5: 16 pro max DT 256 | E5: 2600
A6: 4 | B6: 350523894519302 | C6: 16 pro max DT 256 | E6: 2600
A7: 5 | B7: 351250615706591 | C7: Samsung Z flip 256 | E7: 1400
A8: 6 | B8: 350229401181392 | C8: Samsung S24 Ultra 256 | E8: 1600
E9: =SUM(E3:E8) -> 13400

Sheet INVOICE 24
A1: Invoice no 24 | C1: Label by AR (RichMond) 884208471185 | E1: Dated:25-09-2025
A2: S.No | B2: Imei | C2: Description | D2: Status | E2: Price | F2: Comments
A3: 1 | B3: 351159273888767 | C3: Ipad A16 W+C Silver 128gb | D3: Non Active | E3: 1250
A4: 2 | B4: 351657590056489 | C4: Ipad Pro 11" W+C Black 256gb | D4: Non Active | E4: 3350
A5: 3 | B5: 356334540720326 | C5: Ipad Pro 13" W+C 256gb Black | D5: Non Active | E5: 3600
A6: 4 | B6: 356864565972121 | C6: Iphone 16 PM BT 256gb | D6: Non Active | E6: 2430
A7: 5 | B7: 354737617395503 | C7: Iphone 16 PM DT 256gb | D7: Non Active | E7: 2670
A8: 6 | B8: 350773434784334 | C8: Iphone 16 PM DT 256gb | D8: Non Active | E8: 2670
A9: 7 | B9: 350773434767552 | C9: Iphone 16 PM DT 256gb | D9: Non Active | E9: 2670
A10: 8 | B10: 358862980789144 | C10: Iphone 16 PM DT 256gb | D10: Non Active | E10: 2670
A11: 9 | B11: 358862981335905 | C11: Iphone 16 PM DT 256gb | D11: Non Active | E11: 2670
A12: 10 | B12: 353484629073486 | C12: Iphone 16 PM DT 256gb | D12: Non Active | E12: 2670
A13: 11 | B13: 350773436259343 | C13: Iphone 16 PM NT 512gb | D13: Non Active | E13: 2630
A14: 12 | B14: 356043380758755 | C14: Iphone 16 Pro BT 128gb | D14: Non Active | E14: 2020
... A19: 17 | B19: 350319298607821 | C19: Iphone 16 Pro DT 256gb | D19: Active | E19: 2250
A20: 18 | C20: Iphone Kit | E20: 0 | F20: DETAIL REQ
A21: 19 | B21: 353173802583797 | C21: Iwatch Series 10 46mm Black | D21: Non Active | E21: 1250
A22: 20 | B22: 357810544055289 | C22: Iwatch Series 10 46mm silver | D22: Non Active | E22: 1250
A23: 21 | B23: 355767491701426 | C23: Iwatch Ultra 2 BT | D23: Non Active | E23: 2050
A24: 22 | B24: 358712820521803 | C24: Iwatch Ultra 2 BT | D24: Non Active | E24: 2050
A25: 23 | B25: 356706680126085 | C25: Iwatch Ultra 2 BT | D25: Non Active | E25: 2050
A26: 24 | B26: 358910533661706 | C26: Samsung Fold 7 JB 256gb (Not For Sale)
A27: 25 | B27: 352512147343667 | C27: Samsung S25 ultra TB 256gb (Not For Sale)
A28: 26 | B28: 352512147303943 | C28: Samsung S25 ultra TB 256gb (Not For Sale)
A29: 27 | B29: 352512147420366 | C29: Samsung S25 ultra TB 256gb (Not For Sale)
A30: 28 | B30: 352512146638448 | C30: Samsung S25 ultra TB 256gb (Not For Sale)
A31: 29 | B31: 352512147115917 | C31: Samsung S25 ultra TB 256gb (Not For Sale)
A32: 30 | B32: 352512147289977 | C32: Samsung S25 ultra TB 256gb (Not For Sale)
A33: 31 | B33: 352512147299067 | C33: Samsung S25 ultra TB 256gb (Not For Sale)
A34: 32 | B34: 359373961885892 | C34: Samsung S25 ultra TSB 256gb (Not For Sale)
A35: 33 | B35: 352512147365645 | C35: Samsung S25 ultra TSB 256gb (Not For Sale)
E36: =SUM(E3:E35) -> 50500

Sheet INVOICE 25
A1: Invoice no 25 | C1: Label by AR (georgia) 884423139238 | E1: Dated:25-09-2025
A2: S.No | B2: Imei | C2: Description | D2: Status | E2: Price | F2: Comments
A3: 1 | B3: 355468252380910 | C3: Apple Iwatch SE Gen 2 | D3: Non Active | E3: 650
A4: 2 | C4: Ipad | D4: Non Active | F4: DETAIL REQUIRD
A5: 3 | B5: M4X2N92H2W | C5: Ipad A16 Wifi | D5: Non Active | E5: 1250
A6: 4 | B6: 357241838851979 | C6: Ipad Air 11" M3 W+C 128gb | D6: Non Active | E6: 2250
A7: 5 | B7: 359200574583814 | C7: Ipad Air 11" M3 W+C 128gb Purple | D7: Non Active | E7: 2250
A8: 6 | B8: 357241838832680 | C8: Ipad Air 11" M3 W+C 128gb Starlight | D8: Non Active | E8: 2250
A9: 7 | B9: 359200576673514 | C9: Ipad Air 13" W+C 128gb Purple | D9: Non Active | E9: 3350
A10: 8 | B10: 356334540431304 | C10: Ipad Pro 13" W+C 256gb Black | D10: Non Active | E10: 3600
A11: 9 | B11: 356334540659417 | C11: Ipad Pro 13" W+C 256gb Black | D11: Non Active | E11: 3600
A12: 10 | B12: 354895822324401 | C12: Ipad Pro 13" W+C 512gb Black | D12: Non Active | E12: 3700
A13: 11 | B13: 350773437852070 | C13: Iphone 16 PM BT 256gb | D13: Non Active | E13: 2430
A14: 12 | B14: 356864561723742 | C14: Iphone 16 PM BT 256gb | D14: Non Active | E14: 2430
A15: 13 | B15: 355688665252832 | C15: Iphone 16 PM DT 256gb | D15: Non Active | E15: 2670
A16: 14 | B16: 354737617315188 | C16: Iphone 16 PM DT 256gb | D16: Non Active | E16: 2670
A17: 15 | B17: 356541627095287 | C17: Iphone 16 PM DT 256gb | D17: Non Active | E17: 2670
... A21: 19 | B21: 355469927779932 | C21: Iphone 16 PM NT 256gb | D21: Non Active | E21: 2530
A22: 20 | C22: Iphone 16 PM NT 256gb (KIT) | D22: Non Active | E22: 2400
A23: 21 | B23: 354331125613019 | C23: Iphone 16 PM WT 256gb | D23: Non Active | E23: 2530
A24: 22 | B24: 356043385304902 | C24: Iphone 16 Pro BT 256gb | D24: Non Active | E24: 2120
A25: 23 | B25: 359297748641478 | C25: Iphone 16 Pro BT 256gb | D25: Non Active | E25: 2120
A26: 24 | B26: 356043387931728 | C26: Iphone 16 Pro DT 128gb | D26: Non Active | E26: 2130
A27: 25 | B27: 354959416520632 | C27: Iphone 16 Pro DT 128gb | D27: Non Active | E27: 2130
A28: 26 | B28: 359896927371995 | C28: Iphone 16 Pro DT 256gb | D28: Non Active | E28: 2250
A29: 27 | B29: 359896929230595 | C29: Iphone 16 Pro DT 256gb | D29: Non Active | E29: 2250
A30: 28 | B30: 355031538917093 | C30: Iphone 16 Pro NT 128gb | D30: Non Active | E30: 2100
A31: 29 | B31: 358712820153896 | C31: Iwatch Ultra 2 49mm | D31: Non Active | E31: 2050
A32: 30 | B32: 352905160213975 | C32: Iwatch Ultra 2 49mm | D32: Non Active | E32: 2050
A33: 31 | B33: 352605160033423 | C33: Iwatch Ultra 2 49mm | D33: Non Active | E33: 2050
A34: 32 | B34: 352905161312222 | C34: Iwatch Ultra 2 49mm | D34: Non Active | E34: 2050
A35: 33 | B35: 351878870127622 | C35: Samsung S25 Ultra 256gb TB (Not For Sale) | D35: Non Active
A36: 34 | B36: 352512147206955 | C36: Samsung S25 Ultra TB 256gb (Not For Sale)
A37: 35 | B37: 352512147297087 | C37: Samsung S25 Ultra TB 256gb (Not For Sale) | D37: Non Active
A38: 36 | B38: 352512147305575 | C38: Samsung S25 Ultra TB 256gb (Not For Sale) | D38: Non Active
E39: =SUM(E3:E38) -> 74400

Sheet INOIVCE 26
A1: Invoice no 26 | C1: Label by AR | E1: Dated:26-09-2025
A2: S.No | B2: Imei | C2: Description | D2: Status | E2: Price | F2: Comments
A3: 1 | B3: 354737617258677 | C3: 16 PM DT 256 | D3: Non Active | E3: 2670
A4: 2 | B4: 354737617109318 | C4: 16 PM DT 256 | D4: Non Active | E4: 2670
A5: 3 | B5: 354737617221485 | C5: 16 PM DT 256 | D5: Non Active | E5: 2670
A6: 4 | B6: 353393812730036 | C6: 16 PM BT 256 | D6: Active | E6: =2430-50 -> 2380
A7: 5 | B7: 359518871636237 | C7: 16 PM BT 256 | D7: Non Active | E7: 2430
A8: 6 | B8: 355067547753830 | C8: 16 PM BT 256 | D8: Non Active | E8: 2430
A9: 7 | B9: 355067547925610 | C9: 16 PM BT 256 | D9: Non Active | E9: 2430
A10: 8 | B10: 354737611726729 | C10: 16 PM BT 256 | D10: Non Active | E10: 2430
A11: 9 | B11: 354210977379087 | C11: 16 PM BT 256 | D11: Active | E11: =2430-50 -> 2380
A12: 10 | B12: 355067547891119 | C12: 16 PM BT 256 | D12: Non Active | E12: 2430
A13: 11 | B13: 354737617577266 | C13: 16 PM BT 512 | D13: Non Active | E13: 2600
A14: 12 | B14: 354737617679351 | C14: 16 PM BT 512 | D14: Non Active | E14: 2600
A15: 13 | B15: 350773437600909 | C15: 16 PM BT 512 | D15: Non Active | E15: 2600
A16: 14 | B16: 354423234043251 | C16: 16 PM NT 256 | D16: Non Active | E16: 2530
A17: 15 | B17: 354423232609129 | C17: 16 PM NT 256 | D17: Non Active | E17: 2530
A18: 16 | B18: 354423234113476 | C18: 16 PM NT 256 | D18: Non Active | E18: 2530
A19: 17 | B19: 356541627890323 | C19: 16 PM NT 256 | D19: Non Active | E19: 2530
A20: 18 | B20: 355469927870566 | C20: 16 PM NT 256 | D20: Active | E20: 2530
A21: 19 | B21: 354737617853121 | C21: 16 PM DT 512 | D21: Non Active | E21: =2670+110 -> 2780
A22: 20 | B22: 354423233841580 | C22: 16 PM WT 256 | D22: Active | E22: 2530
A23: 21 | B23: 351895498668035 | C23: 16 PRO BT 128 | D23: Non Active | E23: 2020
A24: 22 | B24: 356043388574774 | C24: 16 PRO BT 128 | D24: Active | E24: =2020-50 -> 1970
A25: 23 | B25: 351827500177366 | C25: 16 PRO BT 128 | D25: Non Active | E25: 2020
A26: 24 | B26: 358282724841194 | C26: 16 PRO BT 128 | D26: Active | E26: 1970
A27: 25 | B27: 351895496103696 | C27: 16 PROBT 256 | D27: Active | E27: =2120-50 -> 2070
A28: 26 | B28: 358157747604557 | C28: 16 PROWT 256 | D28: Active | E28: 2150
A29: 27 | B29: 358282720853052 | C29: 16 PRONT 256 | D29: Active | E29: 2150
A30: 28 | B30: 357719288913308 | C30: 16 PRODT 128 | D30: Non Active | E30: 2150
A31: 29 | B31: 356043388276107 | C31: 16 PRODT 128 | D31: Non Active | E31: 2150
A32: 30 | B32: 357463445758633 | C32: 16 PRODT 128 | D32: Active | E32: 2100
A33: 31 | B33: 356043388481665 | C33: 16 PRODT 128 | D33: Non Active | E33: 2150
A34: 32 | B34: 354959416605839 | C34: 16 PRODT 128 | D34: Active | E34: 2100
A35: 33 | B35: 356043387379886 | C35: 16 PRODT 256 | D35: Non Active | E35: 2250
A36: 34 | B36: 359072848821829 | C36: 16 PRONT 128 | D36: Non Active | E36: 2100
A37: 35 | B37: 350169645154914 | C37: 15 WHITE 128 KIT Not For Sale | D37: Active | E37: 0 | F37: NOT FOR SALE
A38: 36 | B38: 358712821642194 | C38: ULTRA 2 49MM BT | D38: Non Active | E38: 2050
A39: 37 | B39: 358345392856594 | C39: SE GEN 2 40MM STARLIGHT | D39: Non Active | E39: 600
A40: 38 | B40: 352628750256051 | C40: IPAD 256 PRO 11(W+C) | D40: Non Active | E40: 3350
...
