Workbook

Sheet Summary (2)
A1: Dubai selling ledger
A2: DATE | B2: DETAIL | C2: Total Amount | D2: Paid | E2: Balance
A3: 45838 | B3: Invoice 1 | C3: ='[1]invoice 1'!F60 -> 141530 | E3: =C3 -> 141530
A4: 45839 | B4: PAID TO Hawla person | D4: 100000 | E4: =E3-D4 -> 41530
A5: 45839 | B5: PAID TO WAJAHAT | D5: 41000 | E5: =E4-D5 -> 530
A7: 45840 | B7: Invoice 2 | C7: ='[1]invoice 2'!F52 -> 117290 | E7: =E5+C7 -> 117820
A8: 45842 | B8: PAID TO WAJAHAT | D8: 10000 | E8: =E7-D8 -> 107820
A9: 45842 | B9: 8 Device Return | D9: =[1]Return!E12 -> 27090 | E9: =E8-D9 -> 80730
A10: 45845 | B10: Hawala 39,00000 @79.20 | D10: 49242.42 | E10: =E9-D10 -> 31487.58
A12: 45828 | B12: 882190243917 (386$ @3.678) | D12: =3.678*386 -> 1419.708 | E12: =E10-D12 -> 30067.872
A13: 45831 | B13: 882247971323 (525$ @3.678) | D13: =3.678*525 -> 1930.95 | E13: =E12-D13 -> 28136.922
A14: 45832 | B14: 882279322688 (507$ @3.678) | D14: =3.678*507 -> 1864.746 | E14: =E13-D14 -> 26272.176
A15: 45845 | B15: Clearing Charges 3 x 650 AED | D15: =650*3 -> 1950 | E15: =E14-D15 -> 24322.176
A16: 45841 | B16: 882482082780 (39$ @3.678) usa to usa | D16: =3.678*39 -> 143.442 | E16: =E15-D16 -> 24178.734
A17: 45845 | B17: ONLINE PAYMENT PKR 500000 @79.20 | D17: =500000/79.2 -> 6313.1313 | E17: =E16-D17 -> 17865.603
A18: 45845 | B18: CASH PAYMENT PKR 646500 @79.20 | D18: =646500/79.2 -> 8162.8788 | E18: =E17-D18 -> 9702.7239
A19: 45846 | B19: ONLINE PAYMENT PKR 500000 @79.20 | D19: =500000/79.2 -> 6313.1313 | E19: =E18-D19 -> 3389.5926
A20: 45848 | B20: ONLINE PAYMENT PKR 268450 @79.20 | D20: =268450/79.2 -> 3389.5202 | E20: =E19-D20 -> 0.072383838
A22: 45848 | B22: Invoice 3 | C22: ='[1]invoice 3'!E97 -> 228660 | E22: =E20+C22 -> 228660.07
A23: 45849 | B23: PAID TO WAJAHAT | D23: 100000 | E23: =E22-D23 -> 128660.07
A24: 45850 | B24: PAID TO MUDDASSIR @79.60 (60k) clear | D24: 100000 | E24: =E23-D24 -> 28660.072
B25: 882482082780(500$ @3.678) | D25: =500*3.678 -> 1839 | E25: =E24-D25 -> 26821.072
B26: 882523663746(500$ @3.678) | D26: =500*3.678 -> 1839 | E26: =E25-D26 -> 24982.072
B27: 882514974053(350$ @3.678) | D27: =350*3.678 -> 1287.3 | E27: =E26-D27 -> 23694.772
B28: Clearing Charges 3 x 650 AED | D28: =3*650 -> 1950 | E28: =E27-D28 -> 21744.772
D29: 21745 | E29: =E28-D29 -> -0.22761616
A30: 45854 | B30: Invoice 4 | C30: ='[1]invoice 4'!E79 -> 155410 | E30: =E29+C30 -> 155409.77
A31: 45857 | B31: PAID TO MUDDASSIR@79.70 (475500) clear | D31: 100000 | E31: =E30-D31 -> 55409.772
A32: 45860 | B32: PAID TO MUDDASSIR @79.70 | D32: 50000 | E32: =E31-D32 -> 5409.7724
A34: 45859 | B34: Invoice 5 | C34: ='[1]invoice 5'!E64 -> 113640 | E34: =E32+C34 -> 119049.77
A35: 45859 | B35: Invoice 6 | C35: ='[1]invoice 6'!E18 -> 30750 | E35: =+E34+C35 -> 149799.77
A36: 45860 | B36: Invoice 7 | C36: ='[1]invoice 07'!E56 -> 130820 | E36: =+E35+C36 -> 280619.77
A37: 45862 | B37: PAID TO MUDDASSIR @79.80 | D37: 152783.21 | E37: =E36-D37 -> 127836.56
A38: 45864 | B38: PAID TO MUDDASSIR ACC 79.80 (17 LAC) | D38: =1700000/79.8 -> 21303.258 | E38: =E37-D38 -> 106533.31
A39: 45867 | B39: paid to MUDDASSIR CASH @79.6 (1CR) | D39: =10000000/79.6 -> 125628.14 | E39: =E38-D39 -> -19094.834
A41: 45868 | B41: Invoice 8 | C41: ='invoice 8'!E34 -> 77890 | E41: =E39+C41 -> 58795.166
A42: 45868 | B42: Invoice 9 | C42: ='Invoice 09'!E33 -> 72940 | E42: =E41+C42 -> 131735.17
A43: 45868 | B43: Invoice 10 | C43: ='Invoice 10'!E64 -> 140580 | E43: =E42+C43 -> 272315.17
A44: 45868 | B44: Paid to Muddassir Cash @79.60 (2CR) | D44: =20000000/79.6 -> 251256.28 | E44: =E43-D44 -> 21058.884
A46: 45869 | B46: Inovice 11 | C46: ='invoice 11'!E34 -> 61670 | E46: =E44+C46 -> 82728.884
...

Sheet invoice 8
A1: Invoice no 8 | C1: Tracking(883044458379) | E1: Dated:30-07-2025
A2: S.No | B2: Imei | C2: Description | D2: Status | E2: Price | F2: Comments
A3: 1 | B3: 352066341531346 | C3: Ipad 13" W+C Black 256gb | D3: Non-Active | E3: 3600
A4: 2 | B4: 352066341326796 | C4: Ipad 13" W+C Black 256gb | D4: Non-Active | E4: 3600
A5: 3 | B5: 352066341775315 | C5: Ipad 13" W+C Black 256gb | D5: Active | E5: 3450
A6: 4 | B6: 354895821446817 | C6: Ipad 13" W+C Black 256gb | D6: Non-Active | E6: 3600
A7: 5 | B7: 356864561466094 | C7: Iphone 16 PM BT 256gb | D7: Non-Active | E7: 2400
A8: 6 | B8: 352315406131249 | C8: Iphone 16 PM BT 256gb | D8: Non-Active | E8: 2400
A9: 7 | B9: 358862981257646 | C9: Iphone 16 PM BT 256gb | D9: Non-Active | E9: 2400
A10: 8 | B10: 354331127564343 | C10: Iphone 16 PM BT 256gb | D10: Non-Active | E10: 2400
A11: 9 | B11: 353393817564075 | C11: Iphone 16 PM BT 256gb | D11: Non-Active | E11: 2400
A12: 10 | B12: 355469924308545 | C12: Iphone 16 PM BT 256gb | D12: Non-Active | E12: 2400
A13: 11 | B13: 355783829149865 | C13: Iphone 16 PM BT 256gb | D13: Non-Active | E13: 2400
A14: 12 | B14: 350319294583984 | C14: Iphone 16 PM BT 256gb | D14: Non-Active | E14: 2400
A15: 13 | C15: Iphone 16 PM BT KIT Only (Detail Req) | E15: 2100
A16: 14 | B16: 356339497280964 | C16: Iphone 16 PM DT 256gb | D16: Non-Active | E16: 2580
A17: 15 | B17: 353393819911035 | C17: Iphone 16 PM DT 256gb | D17: Non-Active | E17: 2580
A18: 16 | B18: 356864560093519 | C18: Iphone 16 PM DT 256gb | D18: Active | E18: 2530
A19: 17 | B19: 353393819089626 | C19: Iphone 16 PM DT 256gb | D19: Non-Active | E19: 2580
A20: 18 | B20: 353393819782402 | C20: Iphone 16 PM DT 256gb | D20: Non-Active | E20: 2580
A21: 19 | B21: 355008280690813 | C21: Iphone 16 PM DT 256gb | D21: Non-Active | E21: 2580
A22: 20 | B22: 354737613393759 | C22: Iphone 16 PM DT 256gb | D22: Non-Active | E22: 2700
A23: 21 | B23: 355300185349706 | C23: Iphone 16 PM DT 256gb | D23: Non-Active | E23: 2580
A24: 22 | B24: 357590879687399 | C24: Iphone 16 PM DT 256gb | D24: Non-Active | E24: 2580
A25: 23 | B25: 353484629925149 | C25: Iphone 16 PM DT 256gb | D25: Non-Active | E25: 2580
A26: 24 | B26: 356339493842050 | C26: Iphone 16 PM DT 256gb | D26: Non-Active | E26: 2580
A27: 25 | C27: Iphone 16 PM DT KIT Only (Detail Req) | E27: 2200
A28: 26 | B28: 358862981128672 | C28: Iphone 16 PM WT 256gb | D28: Non-Active | E28: 2500
A29: 27 | B29: 357463447819375 | C29: Iphone 16 Pro DT 128gb | D29: Non-Active | E29: 2070
A30: 28 | C30: Iwatch KIT only (condition Req)
A31: 29 | B31: 356706681701754 | C31: Iwatch Ultra 2 | D31: Non-Active | E31: 2410
A32: 30 | B32: 358712821665492 | C32: Iwatch Ultra 2 | D32: Non-Active | E32: 2410
A33: 31 | B33: 356706680451202 | C33: Iwatch Ultra 2 | E33: 2300
E34: =SUM(E3:E33) -> 77890

Sheet Invoice 09
A1: Invoice no 09 | C1: Tracking(883043369848) | E1: Dated:30-07-2025
A2: S.No | B2: Imei | C2: Description | D2: Status | E2: Price | F2: Comments
A3: 1 | B3: 354563839418992 | C3: 16 256GB pink | D3: non active | E3: 1550
A4: 2 | B4: 354959417626503 | C4: 16 pro 256GB DT | D4: non active | E4: 2150
A5: 3 | B5: 358282725417200 | C5: 16 pro 256GB DT | D5: non active | E5: 2150
A6: 4 | B6: 356864561432963 | C6: 16 pro max 256gb BT | D6: non active | E6: 2400
A7: 5 | B7: 353393814681906 | C7: 16 pro max 256GB BT | D7: non active | E7: 2400
A8: 6 | B8: 355469925296442 | C8: 16 pro max 256GB BT | D8: non active | E8: 2400
A9: 7 | B9: 355469925413245 | C9: 16 pro max 256GB BT | D9: non active | E9: 2400
A10: 8 | B10: 358245529041443 | C10: 16 pro max 256GB BT | D10: non active | E10: 2400
A11: 9 | B11: 353393818408496 | C11: 16 pro max 256GB DT | D11: non active | E11: 2580
A12: 10 | B12: 357205988073767 | C12: 16 pro max 256GB DT | D12: non active | E12: 2580
A13: 11 | B13: 358594368942397 | C13: 16 pro max 256GB DT | D13: non active | E13: 2580
A14: 12 | B14: 353393818700074 | C14: 16 pro max 256GB DT | D14: non active | E14: 2580
... A29: 27 | B29: 352066341940364 | C29: ipad 13 inch 512GB | D29: non active | E29: 3700
A30: 28 | C30: samsung s25 ultra (GB req) | D30: non active
A31: 29 | C31: samsung s25 ultra (GB req) | D31: non active
A32: 30 | C32: samsung s25 ultra (GB req) | D32: non active
E33: =SUM(E3:E32) -> 72940

Sheet Invoice 10
A1: Invoice no 10 | C1: Tracking(883045782080) | E1: Dated:30-07-2025
A2: S.No | B2: Imei | C2: Description | D2: Status | E2: Price | F2: comments
A3: 1 | B3: 352919734174597 | C3: Galaxy S10+ Tab 256gb Gray | E3: 2100
A4: 2 | B4: 350158864156122 | C4: Galaxy S10+ Tab 256gb Gray | E4: 2100
A5: 3 | B5: 357241835060756 | C5: Ipad Air M3 128gb | D5: Non-Active | E5: 2200
A6: 4 | B6: 353357701231083 | C6: Ipad Pro 11" W+C 256gb Black | D6: Non-Active | E6: 3350
A7: 5 | B7: 352066342015596 | C7: Ipad Pro 13" W+C 256gb Black | D7: Non-Active | E7: 3600
A8: 6 | B8: 352066341330137 | C8: Ipad Pro 13" W+C 256gb Black | D8: Non-Active | E8: 3600
A9: 7 | B9: 352066341420805 | C9: Ipad Pro 13" W+C 256gb Black | D9: Non-Active | E9: 3600
A10: 8 | B10: 354895821467821 | C10: Ipad Pro 13" W+C 256gb Black | D10: Non-Active | E10: 3600
A11: 9 | B11: 354895821318222 | C11: Ipad Pro 13" W+C 256gb Black | D11: Non-Active | E11: 3600
A12: 10 | B12: 352066342028508 | C12: Ipad Pro 13" W+C 256gb Black | E12: =3600-150 -> 3450
A13: 11 | B13: 352066342319071 | C13: Ipad Pro 13" W+C 256gb Black | D13: Non-Active | E13: 3600
A14: 12 | B14: 356334540698548 | C14: Ipad Pro 13" W+C 256gb Black | D14: Non-Active | E14: 3600
A15: 13 | B15: 354895821475311 | C15: Ipad Pro 13" W+C 256gb Black | D15: Non-Active | E15: 3600
A16: 14 | B16: 352066342079741 | C16: Ipad Pro 13" W+C 256gb Black | D16: Non-Active | E16: 3600
A17: 15 | B17: 352066342299190 | C17: Ipad Pro 13" W+C 512gb Black | D17: Non-Active | E17: 3700
A18: 16 | B18: Required | C18: Ipad Pro 13" W+C 2TB Black | E18: 4100
A19: 17 | B19: 358282724721727 | C19: Iphone 16 Pro BT 512gb | D19: Non-Active | E19: 2200
A20: 18 | B20: 355469921016745 | C20: Iphone 16 PM DT 256gb | D20: Non-Active | E20: 2580
A21: 19 | B21: 355469921391569 | C21: Iphone 16 PM DT 256gb | D21: Non-Active | E21: 2580
A22: 20 | B22: 354331125336868 | C22: Iphone 16 PM DT 256gb | D22: Non-Active | E22: 2580
A23: 21 | B23: 353393815788486 | C23: Iphone 16 PM DT 256gb | D23: Non-Active | E23: 2580
A24: 22 | B24: 351614400599703 | C24: Iphone 16 PM DT 256gb | D24: Non-Active | E24: 2580
A25: 23 | B25: 357205986351538 | C25: Iphone 16 PM DT 256gb | D25: Active | E25: 2530
A26: 24 | B26: 357205986260382 | C26: Iphone 16 PM DT 256gb | D26: Active | E26: 2530
A27: 25 | B27: 356339495491070 | C27: Iphone 16 PM DT 256gb | D27: Non-Active | E27: 2580
A28: 26 | B28: 353484626480205 | C28: Iphone 16 PM DT 256gb | D28: Non-Active | E28: 2580
A29: 27 | B29: 353484626399603 | C29: Iphone 16 PM DT 256gb | D29: Non-Active | E29: 2580
A30: 28 | B30: 355067545436495 | C30: Iphone 16 PM DT 256gb | D30: Non-Active | E30: 2580
... A42: 40 | B42: 358536504869216 | C42: Iphone 16 Pro DT 256gb | D42: Non-Active | E42: 2200
A43: 41 | B43: 358282725472734 | C43: Iphone 16 Pro DT 256gb (Not for Sale) | D43: Non-Active | E43: 0 | F43: (Not for Sale)
A44: 42 | B44: 356043382959583 | C44: Iphone 16 Pro NT 128gb | D44: Non-Active | E44: 1950
A45: 43 | B45: 351895494900341 | C45: Iphone 16 Pro NT 256gb | D45: Non-Active | E45: 2050
A46: 44 | B46: 352161331206338 | C46: Iphone 16 Plus Black 128gb (Not for Sale) | D46: Non-Active | E46: 0 | F46: (Not for Sale)
A47: 45 | B47: 352942561742401 | C47: Iphone 16 Plus Pink 128gb (Not for Sale) | D47: Non-Active | E47: 1600 | F47: phone retrun daengye
A48: 46 | B48: 350836183781767 | C48: Iwatch Series 10 46mm Jet Black | D48: Non-Active | E48: 1300
A49: 47 | B49: 351791641632061 | C49: Iwatch Series 10 42mm Rose Gold | D49: Non-Active | E49: 1220
A50: 48 | B50: 357810544318422 | C50: Iwatch Series 10 46mm Jet Black | D50: Non-Active | E50: 1300
A51: 49 | B51: 358712821473749 | C51: Iwatch Ultra 2 | D51: Active | E51: 2000 | F51: only watch without straps
...

Sheet invoice 11
A1: Invoice no 11 | C1: Tracking | E1: Dated:02-08-2025
A2: S.No | B2: Imei | C2: Description | D2: Status | E2: Price | F2: Comments
A3: 1 | B3: k3vc2xl9jk | C3: ipad pro 13 inch 512GB space black (not for sale) | D3: Non Active | E3: 0 | F3: not for sale
A4: =A3+1 -> 2 | B4: hc71xp496j | C4: apple watch ultra 2 49 mm black ti | D4: Non Active | E4: 2410
A5: =A4+1 -> 3 | B5: m1xj125t20 | C5: apple watch ultra 2 49 mm black ti | D5: Non Active | E5: 2410
A6: =A5+1 -> 4 | B6: hf5v9v07qj | C6: apple watch series 10 46mm | D6: Non Active | E6: 1220
A7: =A6+1 -> 5 | B7: cppj93jm2n | C7: 16 pro max black titanium 256 GB | D7: serial not clear | E7: 2400
A8: =A7+1 -> 6 | B8: lj4twf4wm4 | C8: 16 pro max black titanium 256 GB | D8: Non Active | E8: 2400
A9: =A8+1 -> 7 | B9: gfjdv7k5wo | C9: 16 pro max natural titanium 256 GB | D9: Active | E9: 2450
A10: =A9+1 -> 8 | B10: lhdy6wdlvv | C10: 16 pro max desert titanium 512 GB (not for sale) | E10: 0 | F10: not for sale
A11: =A10+1 -> 9 | B11: kq3h7thjxg | C11: 16 pro max desert titanium 512 GB (not for sale) | E11: 0 | F11: not for sale
A12: =A11+1 -> 10 | B12: 358915380007432 | C12: galaxy s25 ultra titanium black 512 GB | D12: Non Active | E12: 1850
A13: =A12+1 -> 11 | B13: 352512146092935 | C13: galaxy s25 ultra titanium black 256 GB | D13: Non Active | E13: 1800
A14: =A13+1 -> 12 | B14: 352512146242332 | C14: galaxy s25 ultra titanium black 512 GB | D14: Non Active | E14: 1850
A15: =A14+1 -> 13 | B15: 352512146253271 | C15: galaxy s25 ultra titanium black 512 GB | D15: Non Active | E15: 1850
A16: =A15+1 -> 14 | B16: 358915390049660 | C16: galaxy s25 ultra titanium black 512 GB | D16: Non Active | E16: 1850
A17: =A16+1 -> 15 | B17: lwn2lw95pf | C17: 16 pro max black titanium 256 GB | D17: Non Active | E17: 2400
A18: =A17+1 -> 16 | B18: kv9w1y60qq | C18: 16 pro max desert titanium 1TB | D18: Non Active | E18: 2750
A19: =A18+1 -> 17 | B19: dfcq077fq2 | C19: 16 pro max desert titanium 1TB | D19: Non Active | E19: 2750
A20: =A19+1 -> 18 | B20: ckk4t41khx | C20: 16 pro max desert titanium 1TB | D20: Non Active | E20: 2750
A21: =A20+1 -> 19 | B21: d6xpp76202 | C21: 16 pro max black titanium 256 GB | D21: Non Active | E21: 2400
A22: =A21+1 -> 20 | B22: lr4y6m7xjh | C22: 16 pro max desert titanium 1TB | D22: Non Active | E22: 2750
A23: =A22+1 -> 21 | B23: hp1v90wyp7 | C23: 16 pro max desert titanium 512 GB (not for sale) | D23: Non Active | E23: 0 | F23: not for sale
A24: =A23+1 -> 22 | B24: g3xmq9k2lr | C24: 16 pro max desert titanium 512GB | D24: Non Active | E24: 2700
A25: =A24+1 -> 23 | B25: ghk377x9mf | C25: 16 pro max desert titanium 512GB | D25: Non Active | E25: 2700
A26: =A25+1 -> 24 | B26: d6xpg972lx | C26: 16 pro max desert titanium 512GB | D26: Non Active | E26: 2700
A27: =A26+1 -> 25 | B27: t4lt1jh147 | C27: 16 pro max black titanium 512GB | D27: Non Active | E27: 2600
A28: =A27+1 -> 26 | B28: myq9x52tmq | C28: 16 pro max black titanium 512GB | D28: Non Active | E28: 2600
A29: =A28+1 -> 27 | B29: kqvk2jxp07 | C29: 16 pro max desert titanium 256GB | D29: Non Active | E29: 2700
A30: =A29+1 -> 28 | B30: jgd43dmcw4 | C30: 16 pro max black titanium 256GB | D30: Non Active | E30: 2400
A31: =A30+1 -> 29 | B31: lp752ylx7w | C31: 16 pro max desert titanium 256GB | D31: Non Active | E31: 2580
A32: =A31+1 -> 30 | B32: gwfxlqg9q7 | C32: 16 pro max black titanium 256GB | D32: Non Active | E32: 2400
E34: =SUM(E3:E33) -> 61670

Sheet invoice 12
B2: Invoice no 12 | D2: Tracking | F2: Dated:02-08-2025
B3: S.No | C3: Imei | D3: Description | E3: Status | F3: Price | G3: Comments
B4: 1 | C4: 356706680325976 | D4: APPLE WATCH ULTRA2 49 NT TI NV OB- | E4: non active | F4: 2410
B5: 2 | C5: 352942561891059 | D5: IPHONE 16 PLUS PNK 128GB | E5: non active | F5: 1600
B6: 3 | C6: 352942561739464 | D6: IPHONE 16 PLUS PNK 128GB | E6: non active | F6: 1600
B7: 4 | C7: 352113551465078 | D7: IPHONE 16 PLUS PNK 128GB | E7: non active | F7: 1600
B8: 5 | C8: 352113551349108 | D8: IPHONE 16 PLUS PNK 128GB | E8: non active | F8: 1600
B9: 6 | C9: 352942560034180 | D9: IPHONE 16 PLUS PNK 128GB (Not For Sale) | E9: non active | F9: 1600 | G9: phone will retrun
B10: 7 | C10: 352942560220888 | D10: IPHONE 16 PLUS PNK 128GB (Not For Sale) | E10: non active | F10: 1700 | G10: phone will retrun rate 256gb
B11: 8 | C11: 359103740143804 | D11: IPHONE 16 PLUS TL 128GB (Not For Sale) | E11: non active | F11: 0
B12: 9 | C12: 352161333156770 | D12: IPHONE 16 PLUS WHT 128GB | E12: non active | F12: 1600
B13: 10 | C13: 352161333103186 | D13: IPHONE 16 PLUS WHT 128GB | E13: non active | F13: 1600
B14: 11 | C14: 352161333450355 | D14: IPHONE 16 PLUS WHT 128GB | E14: non active | F14: 1600
B15: 12 | C15: 359297747836699 | D15: IPHONE 16 PRO BLACK 128GB | E15: non active | F15: 1900
B16: 13 | C16: 358282725230504 | D16: IPHONE 16 PRO BLACK 128GB | E16: non active | F16: 1900
B17: 14 | C17: 358282725039335 | D17: IPHONE 16 PRO BLACK 128GB | E17: non active | F17: 1900
B18: 15 | C18: 356102154611689 | D18: IPHONE 16 PRO BLACK 256GB | E18: non active | F18: 2050
B19: 16 | C19: 353393817621412 | D19: IPHONE 16 PRO MAX BLACK 256GB | E19: non active | F19: 2400
B20: 17 | C20: 356308869025459 | D20: IPHONE 16 PRO MAX BLACK 256GB | E20: non active | F20: 2400
B21: 18 | C21: 351614405090443 | D21: IPHONE 16 PRO MAX BLACK 256GB | E21: non active | F21: 2400
B22: 19 | C22: 350773434693303 | D22: IPHONE 16 PRO MAX BLACK 256GB | E22: non active | F22: 2400
... B51: 48 | C51: 359696881197299 | D51: IPHONE 16 UMR 256GB | E51: non active | F51: 1600
B52: 49 | C52: 352512146761431 | D52: samsung S25U 256 GB pre own (Not For Sale) | F52: 0
B53: 50 | C53: 352512143815304 | D53: samsung S25U 256GB | F53: 1800
B54: 51 | C54: 3.5251215e+15 | D54: samsung S25U 256GB | F54: 1800
B55: 52 | C55: 358754771133667 | D55: samsung S25U 256GB | F55: 1750
B56: 53 | C56: 358754771670387 | D56: samsung S25U 256GB | F56: 1800
B57: 54 | C57: 352512146261084 | D57: samsung S25U 256GB | F57: 1800
B58: 55 | C58: 352512146703374 | D58: samsung S25U 256GB | F58: 1800
B59: 56 | C59: 352512146790876 | D59: samsung S25U 256GB | F59: 1800
B60: 57 | C60: 352512146739600 | D60: samsung S25U 256GB | F60: 1680 | G60: atnt box | H60: 1750
B61: 58 | C61: 352512146739063 | D61: samsung S25U 256GB | F61: 1800
B62: 59 | C62: 358574637860612 | D62: samsung S25U 256GB | F62: 1800
B63: 60 | C63: 352512146741259 | D63: samsung S25U 256GB | F63: 1800
F65: =SUM(F4:F64) -> 114190
B72: 5 | C72: 358862982908593 | D72: IPHONE 16 PRO MAX BLACK 256GB | E72: non active | F72: 2450 | G72: 2400
B73: 6 | C73: 358536507391838 | D73: IPHONE 16 PRO MAX WHITE 256GB | E73: non active | F73: 2570 | G73: 2500
B74: 7 | C74: 353393818423230 | D74: IPHONE 16 PRO MAX NATURAL 256GB | E74: non active | F74: 2570 | G74: 2500
F75: =SUM(F72:F74) -> 7590 | G75: =SUM(G71:G74) -> 7400
B76: 8 | C76: k3vc2xl9jk | D76: ipad pro 13 inch 512GB space black (Not For Sale)
...

Sheet Invoice 13
A1: Invoice no 13 | C1: Tracking | E1: Dated:05-08-2025
A2: S.No | B2: Imei | C2: Description | D2: Status | E2: Price | F2: Comments
A3: 1 | B3: 351657591040474 | C3: Ipad Pro 11" W+C 1TB Black | D3: Non Active | E3: 3700
A4: 2 | B4: 352066342104184 | C4: Ipad Pro 13" W+C 2TB Black | D4: Non Active | E4: 4100
A5: 3 | B5: 352066342437857 | C5: Ipad Pro 13" W+C 2TB Black | D5: Non Active | E5: 4100
A6: 4 | B6: 352066342349250 | C6: Ipad Pro 13" W+C 2TB Black | D6: Non Active | E6: 4100
A7: 5 | B7: 357590873460900 | C7: Iphone 16 PM BT 256gb | D7: Non Active | E7: 0 | F7: Not for sale | G7: r | H7: 2400
A8: 6 | B8: 358862980240197 | C8: Iphone 16 PM BT 256gb | D8: Non Active | E8: 2400
A9: 7 | B9: 359906326817488 | C9: Iphone 16 PM BT 256gb | D9: Non Active | E9: 2400
A10: 8 | B10: 351210975135556 | C10: Iphone 16 PM BT 256gb | E10: 2400
A11: 9 | B11: 355008280298831 | C11: Iphone 16 PM DT 256gb | D11: Non Active | E11: 2580
A12: 10 | B12: 355008284212325 | C12: Iphone 16 PM DT 256gb | D12: Non Active | E12: 2580
A13: 11 | B13: 353484625464515 | C13: Iphone 16 PM DT 256gb | D13: Non Active | E13: 2580 | H13: not purchase
A14: 12 | B14: 352315403585843 | C14: Iphone 16 PM DT 256gb | D14: Non Active | E14: 0 | F14: Not for sale | G14: r | H14: 2580
A15: 13 | B15: 352315403717560 | C15: Iphone 16 PM DT 256gb | D15: Active | E15: 2530 | G15: 2580
A16: 14 | B16: 357590873019052 | C16: Iphone 16 PM DT 256gb | D16: Active | E16: 2530 | G16: 2580
A17: 15 | B17: 357205988221697 | C17: Iphone 16 PM DT 256gb | D17: Non Active | E17: 2580
A18: 16 | B18: 357205986286841 | C18: Iphone 16 PM DT 256gb | D18: Non Active | E18: 2580
A19: 17 | B19: 356864562014174 | C19: Iphone 16 PM DT 256gb | D19: Non Active | E19: 2580
A20: 18 | B20: 355008284462490 | C20: Iphone 16 PM DT 256gb | D20: Non Active | E20: 2580
A21: 19 | B21: 356339491145340 | C21: Iphone 16 PM DT 256gb | D21: Non Active | E21: 2580
A22: 20 | B22: 351614401728079 | C22: Iphone 16 PM DT 256gb | D22: Non Active | E22: 2580
A23: 21 | B23: 357590877927673 | C23: Iphone 16 PM DT 256gb | D23: Non Active | E23: 2580
A24: 22 | B24: 354331128857837 | C24: Iphone 16 PM DT 256gb | D24: Active | E24: 2530 | G24: 2580
A25: 23 | B25: 355783823728664 | C25: Iphone 16 PM DT 256gb | D25: Non Active | E25: 2580
A26: 24 | B26: 356339491037844 | C26: Iphone 16 PM DT 256gb | D26: Non Active | E26: 2580
A27: 25 | B27: 357590873376197 | C27: Iphone 16 PM DT 256gb | D27: Non Active | E27: 2580
A28: 26 | B28: 351614403446597 | C28: Iphone 16 PM NT 256gb | D28: Non Active | E28: 2500
A29: 27 | B29: 356339491156289 | C29: Iphone 16 PM NT 256gb | D29: Non Active | E29: 2500
A30: 28 | B30: 355469926855857 | C30: Iphone 16 PM NT 256gb | D30: Non Active | E30: 2500
A31: 29 | B31: 358862981027833 | C31: Iphone 16 PM WT 256gb | D31: Non Active | E31: 2500
A32: 30 | B32: 357017254562906 | C32: Iphone 16 Pro BT 128gb | D32: Non Active | E32: 1950
A33: 31 | B33: 357017254663548 | C33: Iphone 16 Pro BT 128gb | D33: Non Active | E33: 1950
A34: 32 | B34: 359297747838281 | C34: Iphone 16 Pro BT 128gb | D34: Non Active | E34: 1950
A35: 33 | B35: 356102151926478 | C35: Iphone 16 Pro BT 256gb | D35: Non Active | E35: 0 | F35: Not for sale | G35: n | H35: 1950 | I35: 128gb purchased | J35: remove
A36: 34 | B36: 356102152263996 | C36: Iphone 16 Pro BT 256gb | D36: Non Active | E36: 0 | F36: Not for sale | G36: r | H36: 1950
A37: 35 | B37: 350319294504535 | C37: Iphone 16 Pro DT 128gb | D37: Non Active | E37: 0 | F37: Not for sale | G37: r | H37: 1950
A38: 36 | B38: 351895498493533 | C38: Iphone 16 Pro DT 256gb | D38: Non Active | E38: 2200 | G38: 2070
A39: 37 | B39: 350328825338909 | C39: Iphone 16 Pro NT 256gb | D39: Non Active | E39: 2100 | G39: 2000 | I39: 128gb purchased
A40: 38 | B40: 350328826000060 | C40: Iphone 16 Pro NT 128gb | D40: Non Active | E40: 2000
...

Sheet invoice 14
A1: Invoice no 14 | B1: Label by Rehman (WareHouse) 883370708860 , 883370708871 | E1: Dated:13-08-2025
A2: S.No | B2: Imei | C2: Description | D2: Status | E2: Price | F2: Comments
A3: 1 | B3: 350158864156411 | C3: Galaxy Tab S10+ 256gb | E3: 2100 | F3: ok
A4: 2 | B4: 351159273970938 | C4: Ipad A16 128GB | D4: Non-Active | E4: 2200
A5: 3 | B5: 358334540381634 | C5: Ipad Pro 13" W+C 256gb | D5: Non-Active | E5: 3600
A6: 4 | B6: 352066342214322 | C6: Ipad Pro 13" W+C 256gb | D6: Activated | E6: 3500
A7: 5 | B7: 352066342468399 | C7: Ipad Pro 13" W+C 256gb | D7: Non-Active | E7: 3600
A8: 6 | B8: 352066342278699 | C8: Ipad Pro 13" W+C 256gb | D8: Non-Active | E8: 3600
A9: 7 | B9: 356334541198241 | C9: Ipad Pro 13" W+C 256gb | D9: Non-Active | E9: 3600
A10: 8 | B10: 359696883582001 | C10: Iphone 16 Pink 128gb | D10: Non-Active | E10: 1450
A11: 9 | B11: 353393811729831 | C11: Iphone 16 PM BT 256gb | D11: Non-Active | E11: 2400
A12: 10 | B12: 355688666584118 | C12: Iphone 16 PM BT 256gb | D12: Activated | E12: 2400
A13: 11 | B13: 351614406735442 | C13: Iphone 16 PM BT 256gb | D13: Non-Active | E13: 2400
A14: 12 | B14: 354210973939868 | C14: Iphone 16 PM BT 256gb | D14: Non-Active | E14: 2400
A15: 13 | B15: 355008284435355 | C15: Iphone 16 PM BT 256gb | D15: Non-Active | E15: 2400
... A45: 43 | B45: 357810544973093 | C45: Iwatch Series 10 46mm black | D45: Non-Active | E45: 1220
A46: 44 | B46: 352905160496331 | C46: Iwatch Ultra 2 Ti black not for sale | D46: Non-Active | E46: 0 | F46: Not for Sale
A47: 45 | B47: 358712820290433 | C47: Iwatch Ultra 2 Ti navy not for sale | D47: Non-Active | E47: 0 | F47: Not for Sale
A48: 46 | B48: 357494472144173 | C48: Iwatch Ultra 2 Ti black not for sale | D48: Non-Active | E48: 0 | F48: Not for Sale
A49: 47 | B49: 356706681477883 | C49: Iwatch Ultra 2 not for sale | D49: Non-Active | E49: 0 | F49: Not for Sale
A50: 48 | B50: 7910 | C50: Iwatch Ultra 2 not for sale | D50: Non-Active | E50: 0 | F50: Not for Sale
A51: 49 | B51: Required | C51: Iwatch Ultra 2 not for sale | D51: Non-Active | E51: 0 | F51: Not for Sale
A52: 50 | B52: 352905160737064 | C52: Iwatch Ultra 2 not for sale | D52: Non-Active | E52: 0 | F52: Not for Sale
A53: 51 | B53: H93GPKJ579 | C53: Iwatch Ultra 2 not for sale | D53: Non-Active | E53: 0 | F53: Not for Sale
A54: 52 | B54: 352512147049694 | C54: Samsung S25 Ultra TB 256gb | E54: 1800
A55: 53 | B55: 358754771073400 | C55: Samsung S25 Ultra TB 256gb | E55: 1800
A56: 54 | B56: 352512147080251 | C56: Samsung S25 Ultra TB 256gb | E56: 1800
A57: 55 | B57: 352512146297930 | C57: Samsung S25 Ultra TG 256gb | E57: 1800
A58: 56 | B58: 352512146463391 | C58: Samsung S25 Ultra TG 256gb | E58: 1800
A59: 57 | B59: 359373961214168 | C59: Samsung S25 Ultra TSB 256gb | E59: 1800
A60: 58 | B60: 359373961005000 | C60: Samsung S25 Ultra TSB 256gb | E60: 1800
A61: 59 | B61: 359373960917662 | C61: Samsung S25 Ultra TSB 256gb | E61: 1800
A62: 60 | B62: 350472953091953 | C62: Samsung Z Fold 7 256gb Jet Black | E62: 3250
E64: =SUM(E3:E63) -> 120770

Sheet Invoice 15
A1: Invoice no 15 | B1: Label by Rehman (WareHouse) 883370027775 | E1: Dated:14-08-2025
A2: S.No | B2: Imei | C2: Description | D2: Status | E2: Price | F2: Comments
A3: 1 | B3: 353685832093729 | C3: Iphone 16 Pink 128gb | D3: Actiavted | E3: 1400
A4: 2 | B4: 355008285632521 | C4: Iphone 16 PM BT 256gb | D4: Actiavted | E4: 2350
A5: 3 | B5: 355008285938977 | C5: Iphone 16 PM BT 256gb | D5: Non-Active | E5: 2400
A6: 4 | B6: 351614404387295 | C6: Iphone 16 PM BT 256gb | D6: Actiavted | E6: 2350
A7: 5 | B7: 358862980911862 | C7: Iphone 16 PM BT 256gb | D7: Actiavted | E7: 2350
A8: 6 | B8: 355067546883356 | C8: Iphone 16 PM BT 256gb | D8: Non-Active | E8: 2400
A9: 7 | B9: 358862980337571 | C9: Iphone 16 PM BT 256gb | D9: Non-Active | E9: 2400
A10: 8 | B10: 350773435270929 | C10: Iphone 16 PM BT 256gb | D10: Non-Active | E10: 2400
A11: 9 | B11: 350773435425440 | C11: Iphone 16 PM BT 256gb | D11: Non-Active | E11: 2400
A12: 10 | B12: 350773435485709 | C12: Iphone 16 PM DT 256gb | D12: Non-Active | E12: 2580
A13: 11 | B13: 354331128732899 | C13: Iphone 16 PM DT 256gb | D13: Non-Active | E13: 2580
A14: 12 | B14: 354331128699494 | C14: Iphone 16 PM DT 256gb | D14: Non-Active | E14: 2580
... A26: 24 | B26: 359072844892238 | C26: Iphone 16 Pro NT 256gb | D26: Actiavted | E26: 2050
A27: 25 | B27: 358754771642733 | C27: Samsung S25 Ultra TB 256gb | E27: 1800
A28: 26 | B28: 352512147003998 | C28: Samsung S25 Ultra TB 512gb | E28: 1850
A29: 27 | B29: 352512146899933 | C29: Samsung S25 ultra TG 256gb | E29: 1800
A30: 28 | B30: 359373961212030 | C30: Samsung S25 Ultra TSB 256gb | E30: 1800
A31: 29 | B31: 352512145942114 | C31: Samsung S25 Ultra TSB 256gb | E31: 1800
A32: 30 | B32: 359373960851739 | C32: Samsung S25 Ultra TSB 256gb | E32: 1800
E33: =SUM(E3:E32) -> 66050
