Workbook

Sheet close
D9: Stock | F9: AUD | G9: AED
E10: Total Stock In Australia Value | F10: 130001.91 | G10: =F10*2.55 -> 331504.87
E11: Total Stock In Dubai Value | F11: =G11/2.55 -> 40064 | G11: 102163.2
E12: Less: GST | F12: -15460 | G12: =F12*2.55 -> -39423
E13: Final Stock Value | G13: =SUM(G10:G12) -> 394245.07
E14: Dubai Local Purchased Stock | G14: 127865 | I14: 372911
D15: Payment
E16: Cash In Hand Dubai | G16: 530815
D18: Receivable | E18: From Waheed Bhai | G18: 67567.84
E19: From Abdul Rehman Bhai | G19: 35995.79
E20: GST Refund Pending | F20: 90397.72 | G20: =F20*2.55 -> 230514.19
E21: Gift Card Balance JB Hifi / Harvey | F21: 3501 | G21: =F21*2.55 -> 8927.55
G22: =SUM(G13:G21) -> 1395930.4
D25: Payables | E25: AMGT Cards $36016.19 USD | G25: =36016.19*3.674 -> 132323.48
E26: AB Card Balance | G26: 12213.3
E27: AR Credit Card | G27: 6118.27
E28: AR Investment | G28: 175000
E29: Abdul Majid Bhai $13754.7 CAD | G29: =13754.7*2.67 -> 36725.049
E30: Jawed Bhai | F30: 84000 | G30: =F30*2.55 -> 214200
G31: =SUM(G25:G30) -> 576580.1
E33: Net Profit | G33: =G22-G31 -> 819350.34
E37: Sell Purchase Profit | G37: 899001
E38: Expenses | G38: -291967
E40: Cash In Hand Dubai | G40: 530815
D42: Receivable | E42: From Waheed Bhai | G42: 65225.34
E43: From Abdul Rehman Bhai | G43: 35995.79
E44: GST Refund Pending | F44: 85522.81 | G44: =F44*2.5 -> 213807.02
E45: Gift Card Balance JB Hifi / Harvey | F45: 3501 | G45: =F45*2.55 -> 8927.55
G46: =SUM(G37:G45) -> 1461804.7
D49: Payables | E49: AMGT Cards $36016.19 USD | G49: 132947
E50: AB Card Balance | G50: 12213.3
E51: AR Credit Card | G51: 6118.27
E52: AR Investment | G52: 175000
E53: Abdul Majid Bhai | G53: 41625.05
E54: Jawed Bhai | F54: 84000 | G54: =F54*2.45 -> 205800
E55: Faisal Bhai | G55: 60000
G56: =SUM(G49:G55) -> 633703.62
E58: Net Profit | G58: =G46-G56 -> 828101.09
E60: AR Profit Add | G60: =G58/2 -> 414050.54
E61: WB Profit Add | G61: =G58/2 -> 414050.54
...

Sheet Cards Payments
D6: Ashfaq Sahab Card
C7: Date | D7: Particular | E7: Dr | F7: Cr | G7: Balance
C9: 45488 | D9: Opening From Zameer Bhai | E9: 32682.5 | G9: =G8+E9-F9 -> 32682.5
C10: 45491 | D10: Purchasing | E10: 9141.22 | G10: =G9+E10-F10 -> 41823.72
C11: 45491 | D11: Purchasing | E11: 10969.47 | G11: =G10+E11-F11 -> 52793.19
C12: 45492 | D12: Purchasing | E12: 2737.9 | G12: =G11+E12-F12 -> 55531.09
C13: 45492 | D13: Purchasing | E13: 7301.07 | G13: =G12+E13-F13 -> 62832.16
C14: 45492 | D14: Cash Deposit by Faisal bhai | F14: 20000 | G14: =G13+E14-F14 -> 42832.16
C15: 45492 | D15: Purchasing | E15: 5475.81 | G15: =G14+E15-F15 -> 48307.97
C16: 45492 | D16: Refund | F16: 5101.73 | G16: =G15+E16-F16 -> 43206.24
C17: 45492 | D17: Purchasing | E17: 10951.6 | G17: =G16+E17-F17 -> 54157.84
C18: 45492 | D18: Purchasing | E18: 3650.54 | G18: =G17+E18-F18 -> 57808.38
C19: 45497 | D19: Purchasing 2142 AUD @2.523 | E19: 5407.27 | G19: =G18+E19-F19 -> 63215.65
C20: 45497 | D20: Purchasing 4284 AUD @2.523 | E20: 10814.54 | G20: =G19+E20-F20 -> 74030.19
C21: 45497 | D21: Purchasing 1428 AUD @2.523 | E21: 3604.85 | G21: =G20+E21-F21 -> 77635.04
C22: 45497 | D22: Purchasing 7140 AUD @2.523 | E22: 18024.23 | G22: =G21+E22-F22 -> 95659.27
C23: 45497 | D23: Purchasing 8568 AUD @2.523 | E23: 21629.08 | G23: =G22+E23-F23 -> 117288.35
C24: 45497 | D24: Purchasing 2856 AUD @2.523 | E24: 7209.7 | G24: =G23+E24-F24 -> 124498.05
C25: 45502 | D25: Harvey | E25: 5348.06 | G25: =G24+E25-F25 -> 129846.11
C26: 45504 | D26: Payment By A/R | F26: 129000 | G26: =G25+E26-F26 -> 846.11
C27: 45516 | D27: Payment By A/R | F27: 54801.43 | G27: =G26+E27-F27 -> -53955.32
C28: 45517 | D28: Refund | F28: 5613.73 | G28: =G27+E28-F28 -> -59569.05
C29: 45517 | D29: Bussings Purchasing | E29: 75260 | G29: =G28+E29-F29 -> 15690.95 | I29: =75260/30000 -> 2.5086667
C30: 45517 | D30: Refund | F30: 5613.73 | G30: =G29+E30-F30 -> 10077.22
C31: 45517 | D31: Refund | F31: 4210.3 | G31: =G30+E31-F31 -> 5866.92
C32: 45517 | D32: Refund | F32: 7017.17 | G32: =G31+E32-F32 -> -1150.25
C33: 45517 | D33: Refund | F33: 11227.46 | G33: =G32+E33-F33 -> -12377.71
C34: 45517 | D34: Refund | F34: 4897.37 | G34: =G33+E34-F34 -> -17275.08
C35: 45517 | D35: Refund | F35: 8401.52 | G35: =G34+E35-F35 -> -25676.6
C36: 45517 | D36: Refund | F36: 4200.76 | G36: =G35+E36-F36 -> -29877.36
C37: 45517 | D37: Refund | F37: 4200.76 | G37: =G36+E37-F37 -> -34078.12
C38: 45517 | D38: Refund | F38: 5601.01 | G38: =G37+E38-F38 -> -39679.13
C39: 45517 | D39: Refund | F39: 5601.01 | G39: =G38+E39-F39 -> -45280.14
C40: 45517 | D40: Refund | F40: 9801.77 | G40: =G39+E40-F40 -> -55081.91
C41: 45517 | D41: Refund | F41: 9801.77 | G41: =G40+E41-F41 -> -64883.68
... C50: 45517 | D50: Refund | F50: 26604.8 | G50: =G49+E50-F50 -> -180569.28
C51: 45523 | D51: Purchasing Bunnings | E51: 35350.33 | G51: =G50+E51-F51 -> -145218.95
C52: 45546 | D52: Harvey Norman Domayne | E52: 2021.67 | G52: =G51+E52-F52 -> -143197.28 | H52: =J52*I52 -> 151083.93 | I52: 2.53 | J52: =1629.99+2397+1000+298+298+298+690+298+598+598+3500+894+3500+894+894+299+299+299+7491+8541+297+8541+5694+594+594+596+596+2384+299+299+598+1529.98+598+297+297+299+299+298+297+297+297 -> 59716.97
C53: 45546 | D53: Harvey Norman Av/it Po | E53: 6065.01 | G53: =G52+E53-F53 -> -137132.27
C54: 45546 | D54: Jb Hi Fi Macquarie $522 | F54: 1229.17 | G54: =G53+E54-F54 -> -138361.44
...

Sheet Problem
B3: 45542 | C3: Shipping Charges Pending | D3: Whatsapp py msg krdya he list
B5: 45542 | C5: Last purchasing Kissy howi he?? Ref1021 wali
B6: 45546 | C6: Refund Charges pending
C7: jo Pcs Returned howe hein unki GST amount ??
C8: Old 62 pcs Returned Pending
C10: Closing Report GST Amount
G18: Closing 31-AUG-2024
G20: Old Purchasing 62Units | I20: 56619.68
G21: New Purchasing 400 Units | I21: 357286.16
G22: Total Purchasing | I22: =SUM(I20:I21) -> 413905.84
G25: AMGT Receivable | I25: 77862.79
G26: A/R Receivable | I26: 31312
G27: Waheed Bhai Receivable | I27: 161424
G28: GST Receivable | I28: 100802
G30: Total Receivable amount | I30: =SUM(I25:I29) -> 371400.79
G32: Total Value (413905.8+371400.8) | I32: =I22+I30 -> 785306.63
G34: Jawed Bhai Payable $81000 | I34: -204120
G35: AR Investment | I35: -103870
G36: WB Invesment
G37: Credit Card Payable | I37: -57181
B39: Date | C39: Card No | D39: Units | E39: Amount AUD
C40: Invoice No.1
B41: 45457 | C41: 6866 | D41: 3units | E41: 1791 | F41: =1791/3 -> 597
B42: 45457 | C42: 6866 | D42: 3units | E42: 1791 | F42: =1791/3 -> 597
B43: 45459 | C43: 6866 | D43: 4units | E43: 2388 | F43: =2388/4 -> 597
B44: 45457 | C44: 6866 | D44: 4units | E44: 2388 | F44: =2388/4 -> 597
B45: 45457 | C45: 6866 | D45: 2units | E45: 1194 | F45: =1194/2 -> 597
B46: 45448 | C46: 6866 | D46: 4units | E46: 2088 | F46: =2088/4 -> 522
B47: 45458 | C47: 6866 | D47: 19units | E47: 11343 | F47: =11343/19 -> 597
B48: 45458 | C48: 6866 | D48: 6units | E48: 3582 | F48: =3582/6 -> 597
B50: Date | C50: Card No | D50: Units | E50: Amount AUD
C51: Invoice No.2
B52: 45459 | C52: 6866 | D52: 7units | E52: 4179 | F52: =4179/7 -> 597
B53: 45459 | C53: 6866 | D53: 8units | E53: 4776 | F53: =4776/8 -> 597
B54: 45459 | C54: 6866 | D54: 7units | E54: 4179 | F54: =4179/7 -> 597
B55: 45460 | C55: 6866 | D55: 8units | E55: 4776 | F55: =4776/8 -> 597
B56: 45458 | C56: 6866 | D56: 9units | E56: 5373 | F56: =5373/9 -> 597
B57: 45459 | C57: 6866 | D57: 12units | E57: 7164 | F57: =7164/12 -> 597 | J57: 14709.5
B59: Date | C59: Card No | D59: Units | E59: Amount AUD
C60: Invoice No.3
...

Sheet Total
A3: Payment From/To | C3: Date | D3: Shipment | E3: Pur/Sell | F3: Details | G3: Dollar | H3: Rate | I3: Purchasing | J3: Sell | K3: Total AED | M3: Stock Qnty
A5: WB | C5: 45397 | D5: Ref#1001V2 | E5: Purchasing | F5: 1st Shipment Purchasing Invoice (1) Starlink V2 Device 16Units $5774.55 | G5: 5774.55 | H5: 2.42 | I5: =G5*H5 -> 13974.411 | K5: =K4+I5-J5 -> 13974.411
A6: WB | C6: 45397 | D6: Ref#1002 V2 | E6: Purchasing | F6: 2nd Shipment Purchasing Invoice (2) Starlink V2 Device 11Units $3970.01 | G6: =11*360.91 -> 3970.01 | H6: 2.42 | I6: =G6*H6 -> 9607.4242 | K6: =K5+I6-J6 -> 23581.835
A7: WB | C7: 45397 | D7: Ref#1001V2 | E7: Exp | F7: 1st Shipping Invoice V2 $1516.06 | G7: 1516.06 | H7: 2.42 | I7: =G7*H7 -> 3668.8652 | K7: =K6+I7-J7 -> 27250.7
A8: WB | C8: 45397 | D8: Ref#1002 V2 | E8: Exp | F8: Sasco Shipping Charges (1st Invoice) | I8: 660 | K8: =K7+I8-J8 -> 27910.7
A9: WB | D9: Ref#1002 V2 | E9: Exp | F9: Sasco Shipping Charges (2nd Invoice) | I9: 650 | K9: =K8+I9-J9 -> 28560.7
A10: AR | C10: 45420 | D10: Ref#1001V2 | E10: Sell | F10: Sell By A/R V2 20pcs @1450 | J10: =20*1450 -> 29000 | K10: =K9+I10-J10 -> -439.2996
A11: AR | C11: 45427 | D11: Ref#1002 V2 | E11: Sell | F11: V2 Sold AMGT 5pcs @1190 (09/05/2024) | J11: =5*1190 -> 5950 | K11: =K10+I11-J11 -> -6389.2996
A12: AR | C12: 45428 | D12: Ref#1002 V2 | E12: Sell | F12: Sold To A/R 2pcs @1000 | J12: =2*1000 -> 2000 | K12: =K11+I12-J12 -> -8389.2996
A13: … | K13: =K12+I13-J13 -> -8389.2996
A14: AR | C14: 45419 | D14: Ref#1003V3 | E14: Exp | F14: V3 106pcs Import Charges (Paid By A/R Dubai) | I14: 4230 | K14: =K13+I14-J14 -> -4159.2996
A15: AR | C15: 45420 | D15: Ref#1003V3 | E15: Exp | F15: Hamali Charges (by Amgt 09pcs sell) | I15: 10 | K15: =K14+I15-J15 -> -4149.2996
A16: WB | C16: 45423 | D16: Ref#1003V3 | E16: Exp | F16: Car Petrol | G16: 58 | H16: 2.42 | I16: =G16*H16 -> 140.36 | K16: =K15+I16-J16 -> -4008.9396
A17: WB | C17: 45423 | D17: Ref#1003V3 | E17: Exp | F17: Van Petrol | G17: 28 | H17: 2.42 | I17: =G17*H17 -> 67.76 | K17: =K16+I17-J17 -> -3941.1796
A18: WB | C18: 45423 | D18: Ref#1003V3 | E18: Exp | F18: Van Hire | G18: 101 | H18: 2.42 | I18: =G18*H18 -> 244.42 | K18: =K17+I18-J18 -> -3696.7596
A19: WB | C19: 45423 | D19: Ref#1003V3 | E19: Purchasing | F19: 1 Unit Purchase Waheed Bhai Card | G19: 522.04 | H19: 2.42 | I19: =G19*H19 -> 1263.3368 | K19: =K18+I19-J19 -> -2433.4228
A20: WB | C20: 45423 | D20: Ref#1003V3 | E20: Exp | F20: Shipping Charges | G20: 4327.63 | H20: 2.42 | I20: =G20*H20 -> 10472.865 | K20: =K19+I20-J20 -> 8039.4418
A21: AR | C21: 45423 | D21: Ref#1003V3 | E21: Purchasing | F21: 7units Purchase A/R Card | G21: 3654.28 | H21: 2.42 | I21: =G21*H21 -> 8843.3576 | K21: =K20+I21-J21 -> 16882.799
A22: AB | C22: 45423 | D22: Ref#1003V3 | E22: Purchasing | F22: 46Units Purchase Ashfaq Sahab Card | G22: 24013.84 | H22: 2.42 | I22: =G22*H22 -> 58113.493 | K22: =K21+I22-J22 -> 74996.292
A23: AB | C23: 45423 | D23: Ref#1003V3 | E23: Purchasing | F23: Card Payment Ashfaq Sahab | G23: 18944 | H23: 2.42 | I23: =G23*H23 -> 45844.48 | K23: =K22+I23-J23 -> 120840.77
A24: AR | C24: 45423 | D24: Ref#1003V3 | E24: Purchasing | F24: Card Payment Abdul Rehman bhai | G24: 7696 | H24: 2.42 | I24: =G24*H24 -> 18624.32 | K24: =K23+I24-J24 -> 139465.09
A25: WB | C25: 45423 | D25: Ref#1003V3 | E25: Purchasing | F25: Card Payment Waheed bhai | G25: 524.8 | H25: 2.42 | I25: =G25*H25 -> 1270.016 | K25: =K24+I25-J25 -> 140735.11
A26: WB | D26: Ref#1003V3 | E26: Exp | F26: Less GST $47.49 x106 | G26: =-47.49*106 -> -5033.94 | H26: 2.42 | J26: =5033.94*2.42 -> 12182.135 | K26: =K25+I26-J26 -> 128552.97
A27: AR | C27: 45419 | D27: Ref#1003V3 | E27: Sell | F27: Sold to Encell Shop 20pcs @1790 | J27: =1790*20 -> 35800 | K27: =K26+I27-J27 -> 92752.973
A28: AR | C28: 45420 | D28: Ref#1003V3 | E28: Sell | F28: Sell to AMGT V3 09pcs @1800 | J28: =9*1800 -> 16200 | K28: =K27+I28-J28 -> 76552.973
A29: AR | C29: 45420 | D29: Ref#1003V3 | E29: Sell | F29: Sold to Encell Shop 10pcs @1800 | J29: =10*1800 -> 18000 | K29: =K28+I29-J29 -> 58552.973
A30: AR | C30: 45427 | D30: Ref#1003V3 | E30: Sell | F30: Sold To AMGT V3 2pcs @1800 (09/05/2024) | J30: =2*1800 -> 3600 | K30: =K29+I30-J30 -> 54952.973
A31: AR | C31: 45427 | D31: Ref#1003V3 | E31: Sell | F31: Sold To AMGT V3 2pcs @1750 (09/05/2024) | J31: =2*1750 -> 3500 | K31: =K30+I31-J31 -> 51452.973
A32: AR | C32: 45427 | D32: Ref#1003V3 | E32: Sell | F32: Sold To AMGT V3 5pcs @1740 (13/05/2024) | J32: =5*1740 -> 8700 | K32: =K31+I32-J32 -> 42752.973
A33: AR | C33: 45427 | D33: Ref#1003V3 | E33: Sell | F33: Sold To AMGT V3 16pcs @1650 (13/05/2024) | J33: =16*1650 -> 26400 | K33: =K32+I33-J33 -> 16352.973
A34: AR | C34: 45427 | D34: Ref#1003V3 | E34: Sell | F34: Sold to Encell Shop 26pcs @1750 | J34: =26*1750 -> 45500 | K34: =K33+I34-J34 -> -29147.027
A35: AR | C35: 45427 | D35: Ref#1003V3 | E35: Sell | F35: Sold to Encell Shop 5pcs @1700 | J35: =5*1700 -> 8500 | K35: =K34+I35-J35 -> -37647.027
A36: AR | C36: 45427 | D36: Ref#1003V3 | E36: Sell | F36: Sold To AMGT V3 1pcs @1700 (15/05/2024) | J36: =1*1700 -> 1700 | K36: =K35+I36-J36 -> -39347.027
A37: AR | C37: 45427 | D37: Ref#1003V3 | E37: Sell | F37: Sold To AMGT V3 10pcs @1695 (15/05/2024) | J37: =10*1695 -> 16950 | K37: =K36+I37-J37 -> -56297.027
A38: …. | F38: Ref#1001 to 1003 (V2 27.Units & V3 106.Units) | I38: 56297.03 | K38: =K37+I38-J38 -> 0.0034
A39: AR | C39: 45440 | D39: V3 35pcs | E39: Exp | F39: V3 Import Charges 35pcs | I39: 1230 | K39: =K38+I39-J39 -> 1230.0034
A40: ??? | C40: 45440 | D40: V3 35pcs | E40: Purchasing | F40: 35 pcs Purchased @474.58 | G40: =474.58*35 -> 16610.3 | H40: 2.44 | I40: =G40*H40 -> 40529.132 | K40: =K39+I40-J40 -> 41759.135 | L40: WB
A41: WB | C41: 45440 | D41: V3 35pcs | E41: Exp | F41: Other Expense Paid by Waheed Bhai | G41: 126 | H41: 2.44 | I41: =G41*H41 -> 307.44 | K41: =K40+I41-J41 -> 42066.575
A42: AR | C42: 45440 | D42: V3 35pcs | E42: Exp | F42: Hamali Charges Paid by AR | I42: 30 | K42: =K41+I42-J42 -> 42096.575
A43: ??? | C43: 45443 | D43: V3 35pcs | E43: Exp | F43: Shipping Charges | G43: 1638.29 | H43: 2.44 | I43: =G43*H43 -> 3997.4276 | K43: =K42+I43-J43 -> 46094.003 | L43: AB
...

Sheet Pending Work
C4: 45566 | D4: Purchased 100 Units $5000 Dollar Advance Payment
C5: 45591 | D5: Starlink V4 12Units Short ??? Msg To AR
C6: 45591 | D6: Purchasing Pending
C7: 45591 | D7: Cash Handover to AMGT Office
C8: 45591 | D8: 1400 $ Handover to AMGT Office
C9: 45591 | D9: 50 Australian Dollar to AMGT Office
C10: 45591 | D10: Australia Stock Confirmation Pending Msg Send to Waheed Bhai
C12: 45593 | D12: Purchasing Pending
C13: 45593 | D13: Extra Cash Pending By A/R 15297 Aed
C14: 45593 | D14: GST Pending
C15: 45593 | D15: Pending Collections..??
C17: 45596 | D17: Shipping Charges Pending ??
C18: 45596 | D18: Gift Card Balances
F23: Date | G23: Details | H23: V4 | I23: Mini | J23: Camera | K23: Charge 5 | L23: Essential 2 | M23: PS 5 | N23: IP 16PM 256 | O23: DJI Mavic | P23: Intax Wide | Q23: Intax Mini | R23: Xtreme 4 | S23: Xtreme 3
F25: 45579 | G25: Last Closing Units | H25: 73 | I25: 121 | J25: 1
F26: 45580 | G26: Purchased msg by A/R | H26: 55 | I26: 10
F27: 45582 | G27: Send to Dubai | H27: -55 | I27: -10
F28: 45584 | G28: Send to Dubai | H28: -42 | I28: -119
F29: 45584 | G29: Purchase 20 Units Mini $745 | H29: 0 | I29: 20
F30: 45588 | G30: Mini Purchased WB Card | I30: 8
F32: 45591 | G32: Charge.5 45Units $142 | K32: 45
F33: 45591 | G33: Flip Essential 2 14Units $68 | L33: 14
F34: 45591 | G34: PS5 10 Units $669 | M34: 10
F35: 45591 | G35: IP 16ProMax 256GB 1.Unit $2147 | N35: 1
F36: 45591 | G36: Starlink Mini 30 Units $745 | I36: 30
E37: Cancelled Purchased | F37: 45591 | G37: Charge.5 100 Units $145 | K37: =100-100 -> 0
E38: Cancelled Purchased | F38: 45591 | G38: Flip Essential 2 100 Units $68 | L38: =100-100 -> 0
F39: 45591 | G39: PS5 2 Units $675 | M39: 2
F40: 45591 | G40: Charge.5 100 Units $133.3 | K40: 100
F41: 45591 | G41: Charge.5 34 Units $133.3 | K41: 34
E42: Returned | F42: 45591 | G42: Starlink Mini 10 Units $768 (Returned)
F43: 45591 | G43: Instax Camera 7units $95 | J43: 7
F45: 45593 | G45: Starlink Mini 100 Units $750 | I45: 100
E46: 8 units Returned | F46: 45593 | G46: DJI MavicPro 10Units $2500 (8unit Returned) | O46: =10-8 -> 2
F47: 45593 | G47: PS5 2 Units $669 | M47: 2
F49: 45596 | G49: Send to Dubai Starlink V4 23 Units | H49: -23
F50: 45601 | G50: Instax Wide 400 8units $189 | P50: 8
F51: 45601 | G51: Instax Mini 99 10Units $230 | Q51: 10
F52: 45605 | G52: 20 Units V4 Purchase $500 | H52: 20
F53: 45607 | G53: Send to Dubai | H53: -26 | I53: -53 | J53: -7 | K53: -79 | L53: -14 | M53: -14 | O53: -2 | P53: -8 | Q53: -10
...

Sheet Sheet2
E3: Pending Collection
D4: Date | E4: Details | F4: V4 | G4: Mini | H4: Starlink HP Kit | I4: Charge 5 | J4: Essential 2 | K4: MacBook M4
C8: ok | D8: 45612 | E8: JBL Charge 5 30Units $131 | I8: =30-27 -> 3
C11: ok | D11: 45617 | E11: Starlink mini 1 Units $599 WB | G11: 1
C12: ok
O13: Details | Q13: Unit | R13: $ Rate | S13: $ Total | T13: Deposit | U13: Balance | V13: AED Rate | W13: Total AED
D14: 45638 | E14: Starlink Mini 100Units $649 WB Card 5000 DDEPOSIT NZ | G14: 100 | O14: Starlink Mini 100Units $649 WB Card 5000 Deposit NZ | Q14: 100 | R14: 649 | S14: =Q14*R14 -> 64900 | T14: -5000 | U14: =S14+T14 -> 59900 | V14: 2.19 | W14: =U14*V14 -> 131181
C16: 32UNIT PAYMENT BALANCE | D16: 45644 | E16: JBL Charge 5 60Units $132 WB Card | I16: =60-28 -> 32 | O16: JBL Charge 5 32Units $132 WB Card | Q16: 32 | R16: 132 | S16: =Q16*R16 -> 4224 | T16: 0 | U16: =S16+T16 -> 4224 | V16: 2.375 | W16: =U16*V16 -> 10032
D18: 45652 | E18: JBL Charge 5 40units $140-10% WB Card $700 Deposit | I18: 40 | O18: JBL Charge 5 40units $140-10% WB Card $700 Deposit | Q18: 40 | R18: 126 | S18: =Q18*R18 -> 5040 | T18: -700 | U18: =S18+T18 -> 4340 | V18: 2.33 | W18: =U18*V18 -> 10112.2
D19: 45652 | E19: Apple MacBook Pro M4 3Unit $2968-10% WB Card 890$ D | K19: 3 | O19: Apple MacBook Pro M4 3Unit $2968-10% WB Card 890$ D | Q19: 3 | R19: 2671.2 | S19: =Q19*R19 -> 8013.6 | T19: -890 | U19: =S19+T19 -> 7123.6 | V19: 2.33 | W19: =U19*V19 -> 16597.988
C20: not paid | D20: 45652 | E20: JBL Charge 5 75units $128 WB Card | I20: 75 | O20: JBL Charge 5 75units $128 WB Card (Not Paid) | Q20: 75 | R20: 128 | S20: =Q20*R20 -> 9600 | T20: 0 | U20: =S20+T20 -> 9600 | V20: 2.33 | W20: =U20*V20 -> 22368
D21: 45652 | E21: JBL Charge5 60Units $140-10% WB Card $500 D | I21: 60 | O21: JBL Charge5 60Units $140-10% WB Card $500 D | Q21: 60 | R21: 126 | S21: =Q21*R21 -> 7560 | T21: -500 | U21: =S21+T21 -> 7060 | V21: 2.33 | W21: =U21*V21 -> 16449.8
W22: =SUM(W14:W21) -> 206740.99
E23: Remaining Units | F23: =SUM(F6:F22) -> 0 | G23: =SUM(G6:G22) -> 101 | H23: =SUM(H6:H22) -> 0 | I23: =SUM(I6:I22) -> 210 | J23: =SUM(J6:J22) -> 0 | K23: =SUM(K6:K22) -> 3
O27: Mac Book Pro 2Units $2968-10% WB Card | P27: 2
O28: Apple MacBook Pro M4 3Unit $2968-10% WB Card | P28: 3
O29: MacBook M4 1Unit $2968+$40-10% WB Card | P29: 1
O30: MacBook 2Units $2948-10% WB Card | P30: 2
O33: MacBook M3 1Unit $2158+$40 WB Card | P33: 1
O34: MacBook M3 1Unit $2158 WB Card | P34: 1

Sheet Ledgers
D2: AR | J2: Group | K2: AR Payments
C3: Date | D3: Details | E3: Payment | F3: Received | G3: Balance
B5: WB.P | C5: 45394 | D5: From A/R Laguna Payment | E5: =97774/77 -> 1269.7922 | G5: =G4+E5-F5 -> 1269.7922 | H5: ok
B6: WB.P | C6: 45394 | D6: From A/R Laguna Payment | E6: =164448/77 -> 2135.6883 | G6: =G5+E6-F6 -> 3405.4805 | H6: ok
B7: WB.P | C7: 45397 | D7: From A/R Paid to Waheed Bhai (agha m.aftab A/C) | E7: 30 | G7: =G6+E7-F7 -> 3435.4805 | H7: ok
B8: WB.P | C8: 45410 | D8: From A/R Laguna Payment | E8: =97774/77 -> 1269.7922 | G8: =G7+E8-F8 -> 4705.2727 | H8: ok
B9: WB.P | C9: 45410 | D9: From A/R Laguna Payment | E9: =164448/77 -> 2135.6883 | G9: =G8+E9-F9 -> 6840.961 | H9: ok
B10: Sasco | C10: 45412 | D10: From A/R by Sasco (9744.30 dollar) @2.44 | E10: 23870 | G10: =G9+E10-F10 -> 30710.961 | J10: ok
B11: Sasco | C11: 45397 | D11: Sasco Shipping Charges (1st Invoice) | E11: 660 | G11: =G10+E11-F11 -> 31370.961 | J11: ok
B12: Sasco | D12: Sasco Shipping Charges (2nd Invoice) | E12: 650 | G12: =G11+E12-F12 -> 32020.961 | J12: ok
B13: Sell | C13: 45420 | D13: Sell By A/R V2 20pcs @1450 | F13: 29000 | G13: =G12+E13-F13 -> 3020.961 | H13: ok
B14: Payment | C14: 45420 | D14: Paid to Ashfaq sahb V3 Purchasing | E14: 45000 | G14: =G13+E14-F14 -> 48020.961 | H14: ok
B15: Sell | C15: 45427 | D15: V2 Sold AMGT 5pcs @1190 (09/05/2024) | F15: 5950 | G15: =G14+E15-F15 -> 42070.961 | H15: ok
B16: Sell | C16: 45428 | D16: Sold To A/R 2pcs @1000 | F16: 2000 | G16: =G15+E16-F16 -> 40070.961 | H16: ok
B17: Payment | C17: 45419 | D17: V3 106pcs Import Charges (Paid By A/R Dubai) | E17: 4230 | G17: =G16+E17-F17 -> 44300.961 | H17: ok
B18: Payment | C18: 45420 | D18: Hamali Charges (by Amgt 09pcs sell) | E18: 10 | G18: =G17+E18-F18 -> 44310.961 | H18: ok
B19: Payment | C19: 45423 | D19: 7units Purchase A/R Card | E19: 8843.36 | G19: =G18+E19-F19 -> 53154.321 | H19: ok
B20: Payment | C20: 45423 | D20: Card Payment Abdul Rehman bhai | E20: 18624.32 | G20: =G19+E20-F20 -> 71778.641 | H20: ok
B21: WB.P | C21: 45420 | D21: Paid From A/R to Faisal Bhai Behalf of Waheed Bhai | E21: 3896.1 | G21: =G20+E21-F21 -> 75674.741 | H21: ok
B22: Sell | C22: 45419 | D22: Sold to Encell Shop 20pcs @1790 | F22: 35800 | G22: =G21+E22-F22 -> 39874.741 | H22: ok
B23: Sell | C23: 45420 | D23: Sell to AMGT V3 09pcs @1800 | F23: 16200 | G23: =G22+E23-F23 -> 23674.741 | H23: ok
B24: Sell | C24: 45420 | D24: Sold to Encell Shop 10pcs @1800 | F24: 18000 | G24: =G23+E24-F24 -> 5674.741 | H24: ok
B25: Payment | C25: 45427 | D25: Ashfaq Sahab Remaining Payment Returned V3 | E25: 1830 | G25: =G24+E25-F25 -> 7504.741 | H25: ok
B26: Sell | C26: 45427 | D26: Sold To AMGT V3 2pcs @1800 (09/05/2024) | F26: 3600 | G26: =G25+E26-F26 -> 3904.741 | H26: ok
B27: Sell | C27: 45427 | D27: Sold To AMGT V3 2pcs @1750 (09/05/2024) | F27: 3500 | G27: =G26+E27-F27 -> 404.74104 | H27: ok
B28: Sell | C28: 45427 | D28: Sold To AMGT V3 5pcs @1740 (13/05/2024) | F28: 8700 | G28: =G27+E28-F28 -> -8295.259 | H28: ok
B29: Sell | C29: 45427 | D29: Sold To AMGT V3 16pcs @1650 (13/05/2024) | F29: 26400 | G29: =G28+E29-F29 -> -34695.259 | H29: ok
B30: Sell | C30: 45427 | D30: Sold to Encell Shop 26pcs @1750 | F30: 45500 | G30: =G29+E30-F30 -> -80195.259 | H30: ok
B31: Sell | C31: 45427 | D31: Sold to Encell Shop 5pcs @1700 | F31: 8500 | G31: =G30+E31-F31 -> -88695.259 | H31: ok
B32: Sell | C32: 45427 | D32: Sold To AMGT V3 1pcs @1700 (15/05/2024) | F32: 1700 | G32: =G31+E32-F32 -> -90395.259 | H32: ok
B33: Sell | C33: 45427 | D33: Sold To AMGT V3 10pcs @1695 (15/05/2024) | F33: 16950 | G33: =G32+E33-F33 -> -107345.26 | H33: ok
B34: Sasco | C34: 45428 | D34: Send To australia By A/R (AUD 8782.5 @2.50) | E34: 22000 | G34: =G33+E34-F34 -> -85345.259 | J34: msg 22k/20k
B35: Sasco | C35: 45432 | D35: Send To australia By A/R (AUD 23152.5 @2.505) | E35: 58000 | G35: =G34+E35-F35 -> -27345.259 | J35: ok
B36: Payment | C36: 45440 | D36: Import Charges V3 35pcs | E36: 1230 | G36: =G35+E36-F36 -> -26115.259 | H36: ok
B37: Payment | C37: 45440 | D37: Hamali Charges Paid by AR | E37: 30 | G37: =G36+E37-F37 -> -26085.259 | H37: ok
B38: Payment | C38: 45444 | D38: Encell Shop Rent Paid by Wajahat | E38: 1333 | G38: =G37+E38-F38 -> -24752.259 | H38: ok
B39: Payment | C39: 45447 | D39: Fahib Salary M/O May-2024 (15000 PKR) | E39: 194.81 | G39: =G38+E39-F39 -> -24557.449 | H39: ok
B40: WB.P | C40: 45442 | D40: Online A/R A/C (Withdraw By Waheed Bhai) | E40: 1264.58 | G40: =G39+E40-F40 -> -23292.869 | H40: ok
B41: Sell | C41: 45442 | D41: Sell Encell Shop 2pcs | F41: 3240 | G41: =G40+E41-F41 -> -26532.869 | H41: ok
B42: Sell | C42: 45442 | D42: Sell Encell Shop 18pcs | F42: 29520 | G42: =G41+E42-F42 -> -56052.869 | H42: ok
...

Sheet Refund & GC
C4: Date | D4: Invoice | E4: Shipment Details | F4: Amount
B6: AR Card | C6: 45549 | D6: Ref#001 | E6: 2unit IP 16PM 256GB Returned @2147 | F6: =2147*2 -> 4294
B7: AR Card | C7: 45549 | D7: Ref#001 | E7: 1unit IP 16PM 512GB Returned @2497 | F7: =2497*1 -> 2497
B9: AB Card | C9: 45549 | D9: Ref#002 | E9: total Shipment Returned $1000 Advance | F9: 1000
B11: AB Card | C11: 45550 | D11: Ref#003 | E11: 3.unit 16PM 512Gb Returned | F11: 3500
B12: AB Card | C12: 45550 | D12: Ref#003 | E12: 3.unit 16PM 512Gb Returned | F12: 3500
B13: AB Card | C13: 45550 | D13: Ref#003 | E13: 6.unit 16PM 512Gb Returned | F13: 7491
E14: Total Refund Amount | F14: =SUM(F6:F13) -> 22282
B16: WB | C16: 45560 | E16: Refund To WB Card | F16: -7000
B18: WB | C18: 45565 | E18: Refund To WB Card | F18: -1000
C19: 45565 | E19: 2nd Gift Card | F19: -6791
E22: Balance | F22: =SUM(F14:F21) -> 7491
B32: AB Card | C32: 45550 | D32: Ref#004 | E32: 4.unit 16PM 512Gb Returned Add Gift Card | F32: =2497*4 -> 9988
E34: Gift Card Balance | F34: 9988
D36: 45558 | E36: Starlink Mini 2Unit $759 | F36: =2*759 -> 1518
D37: 45558 | E37: Starlink V4 2Unit $297 | F37: =297*2 -> 594
D38: 45558 | E38: Starlink Mini 2Unit $759 | F38: =2*759 -> 1518
D39: 45558 | E39: Starlink Mini 1Unit $299 | F39: 299
D40: 45558 | E40: Less: WB Card | F40: -361
D41: 45559 | E41: V4 1.unit Gift Card $299 | F41: 299
D42: 45559 | E42: Mini 1.unit Gift Card $796 | F42: 796
D43: 45559 | E43: V4 1.unit Gift Card $299 | F43: 299
D44: 45559 | E44: Mini 1.unit Gift Card $796 | F44: 796
D45: 45559 | E45: V4 1.unit Gift Card $299 | F45: 299
D46: 45560 | E46: V4 6Units Gift Card $299 | F46: =6*299 -> 1794
D47: 45560 | E47: Mini 1Unit Gift Card $796 | F47: 796
D48: 45563 | E48: Starlink V4 6Units Gift Card $299 | F48: =299*6 -> 1794
D49: 45563 | E49: Gift Card Purchased $250 | F49: 250
E52: Total | F52: =SUM(F36:F51) -> 10691
E54: Net Balance GC | F54: =F34-F52 -> -703
E57: 2nd Gift Card JB HiFi | F57: 6791
D60: 45565 | E60: 2unit V4 $299 | F60: =2*299 -> 598
D61: 45566 | E61: 2unit V4 $299 | F61: =2*299 -> 598
D62: 45567 | E62: 2unit V4 $299 | F62: =2*299 -> 598
D63: 45568 | E63: Starlink V4 4Unit GC Card $298 | F63: =298*4 -> 1192
D64: 45569 | E64: Starlink V4 4units Gift Card Jbhifi $299 | F64: =299*4 -> 1196
D65: 45570 | E65: Starlink V4 2units Gift Card Jbhifi $299 | F65: =299*2 -> 598
E73: Total | F73: =SUM(F59:F72) -> 4780
E75: Net Balance GC | F75: =F57-F73 -> 2011
E78: 3rd Gift Card Harvey Norman | F78: =298*15 -> 4470
...

Sheet Prchasing Entry
D2: Date | E2: Shipment | F2: Details | G2: Units | H2: Card | J2: Amount | R2: AUD
N3: Purchase | O3: Send | P3: Pending | Q3: Available
E4: Ref# 1021 | F4: Last Remaining Units Mini | G4: 19 | K4: Mini | M4: Total Mini | N4: 265 | O4: 144 | P4: =5 -> 5 | Q4: =N4-O4-P4 -> 116 | R4: 93555 | S4: 2.55 | T4: =R4*S4 -> 238565.25
M5: Total V4 | N5: 450 | O5: 377 | P5: =2+2+1+1+23+2 -> 31 | Q5: =N5-O5-P5 -> 42 | R5: 12562 | S5: 2.55 | T5: =R5*S5 -> 32033.1
A6: WB Msg | C6: Received | D6: 45548 | E6: Ref# 1022 | F6: Starlink mini 10 units @799 (WB Card) | G6: 10 | H6: WB | J6: =799*10 -> 7990 | K6: Mini | Q6: 3
A8: AR Msg | C8: Received | D8: 45549 | E8: Ref# 1024 | F8: Starlink V4 3units $230 ARB Card | G8: 3 | H8: ARB | J8: =230*3 -> 690 | K8: V4
A9: AR Msg | C9: Received | D9: 45549 | E9: Ref# 1024 | F9: JB HiFi V4 3Units $230 AB Card | G9: 3 | H9: AB | J9: =230*3 -> 690 | K9: V4
A10: AR Msg | C10: Received | D10: 45549 | E10: Ref# 1024 | F10: BCF V4 6Units $297 ARB Card | G10: 6 | H10: ARB | J10: =297*6 -> 1782 | K10: V4
A11: AR Msg | C11: Received | D11: 45549 | E11: Ref# 1024 | F11: Bunnings V4 3units $298 AB Card | G11: 3 | H11: AB | J11: =298*3 -> 894 | K11: V4
A12: AR Msg | C12: PD | D12: 45549 | E12: Ref# 1024 | F12: BCF V4 10Units $297 ARB Card | G12: 10 | H12: ARB | J12: =297*10 -> 2970 | K12: V4
A13: AR Msg | C13: Received | D13: 45549 | E13: Ref# 1024 | F13: OfficeWorks 1Unit $297 ARB Card | G13: 1 | H13: ARB | J13: 297 | K13: V4
A14: AR Msg | C14: Received | D14: 45549 | E14: Ref# 1024 | F14: Starlink V4 2Units $298 AB Card | G14: 2 | H14: AB | J14: =298*2 -> 596 | K14: V4
A15: AR Msg | C15: Received | D15: 45549 | E15: Ref# 1024 | F15: OfficeWorks 1Unit $297 WB Card | G15: 1 | H15: WB | J15: 297 | K15: V4
A16: AR Msg | C16: Received | D16: 45549 | E16: Ref# 1024 | F16: Starlink V4 1Unit $298 WB Card | G16: 1 | H16: WB | J16: 298 | K16: V4
A17: AR Msg | C17: Received | D17: 45549 | E17: Ref# 1024 | F17: Bunnings V4 1unit $298 WB Card | G17: 1 | H17: WB | J17: 298 | K17: V4
A18: AR Msg | C18: Received | D18: 45549 | E18: Ref# 1024 | F18: Starlink V4 3Units $230 WB Card | G18: 3 | H18: WB | J18: =230*3 -> 690 | K18: V4
A20: WB Msg | C20: Received | D20: 45550 | E20: Ref# 1025 | F20: Starlink V4 AB Card 8units $299 | G20: 8 | H20: AB | J20: =8*299 -> 2392 | K20: V4
A21: WB Msg | C21: Received | D21: 45550 | E21: Ref# 1025 | F21: Starlink V4 AB Card 9units $298 | G21: 9 | H21: AB | J21: =9*298 -> 2682 | K21: V4
A22: WB Msg | C22: Received | D22: 45550 | E22: Ref# 1025 | F22: Starlink V4 WB Card 8units $298 | G22: 8 | H22: WB | J22: =8*298 -> 2384 | K22: V4
A23: WB Msg | C23: Received | D23: 45550 | E23: Ref# 1025 | F23: Starlink V4 WB Card 3units $299 | G23: 3 | H23: WB | J23: =3*299 -> 897 | K23: V4
A24: WB Msg | C24: Received | D24: 45550 | E24: Ref# 1025 | F24: Starlink V4 WB Card 4unit $297 | G24: 4 | H24: WB | J24: =4*297 -> 1188 | K24: V4
A25: WB Msg | C25: Received | D25: 45550 | E25: Ref# 1025 | F25: Starlink V4 WB Card 5units $298 | G25: 5 | H25: WB | J25: =5*298 -> 1490 | K25: V4
A27: WB Msg | C27: Received | D27: 45551 | E27: Ref# 1026 | F27: Starlink AB Card 6units $299 | G27: 6 | H27: AB | J27: =299*6 -> 1794 | K27: V4
A28: WB Msg | C28: Received | D28: 45551 | E28: Ref# 1026 | F28: Starlink AB Card 12units $298 | G28: 12 | H28: AB | J28: =298*12 -> 3576 | K28: V4
A29: WB Msg | C29: Received | D29: 45551 | E29: Ref# 1026 | F29: Starlink AB Card 5units $297 | G29: 5 | H29: AB | J29: =297*5 -> 1485 | K29: V4
A30: WB Msg | C30: Received | D30: 45551 | E30: Ref# 1026 | F30: Starlink WB Card 7units $297 | G30: 7 | H30: WB | J30: =297*7 -> 2079 | K30: V4
A31: WB Msg | C31: Received | D31: 45551 | E31: Ref# 1026 | F31: Starlink WB Card 2units $299 | G31: 2 | H31: WB | J31: =299*2 -> 598 | K31: V4
A32: WB Msg | C32: P.D | D32: 45551 | E32: Ref# 1026 | F32: Starlink Mini AB Card 2units $759 +$6 | G32: 2 | H32: AB | J32: =765*2 -> 1530 | K32: Mini
A33: WB Msg | C33: P.D | D33: 45551 | E33: Ref# 1026 | F33: Starlink Mini WB Card 2units $798 | G33: 2 | H33: WB | J33: =798*2 -> 1596 | K33: Mini
A35: WB Msg | C35: Received | D35: 45552 | E35: Ref# 1027 | F35: Starlink V4 AB Card 7units $299 | G35: 7 | H35: AB | J35: =299*7 -> 2093 | K35: V4
A36: WB Msg | C36: PD | D36: 45552 | E36: Ref# 1027 | F36: Starlink V4 WB Card 1unit $298 | G36: 1 | H36: WB | J36: =298*1 -> 298 | K36: V4
A37: WB Msg | C37: Received | D37: 45552 | E37: Ref# 1027 | F37: Starlink V4 WB Card 1unit $312 | G37: 1 | H37: WB | J37: =1*312 -> 312 | K37: V4
A38: WB Msg | C38: Received | D38: 45552 | E38: Ref# 1027 | F38: Starlink V4 WB Card 3unit $297 | G38: 3 | H38: WB | J38: =297*3 -> 891 | K38: V4
A39: WB Msg | C39: PD 1unit | D39: 45552 | E39: Ref# 1027 | F39: Starlink V4 ARB Card 2unit $298 | G39: 2 | H39: ARB | J39: =298*2 -> 596 | K39: V4
A41: WB Msg | C41: Received | D41: 45553 | E41: Ref# 1028 | F41: Starlink V4 AB Card 9units $298 | G41: 9 | H41: AB | J41: =298*9 -> 2682 | K41: V4
A42: WB Msg | C42: Received | D42: 45553 | E42: Ref# 1028 | F42: Starlink V4 WB Card 51units $298 | G42: 51 | H42: WB | J42: =298*51 -> 15198 | K42: V4
A43: WB Msg | C43: Received | D43: 45553 | E43: Ref# 1028 | F43: Starlink Mini WB Card 10units $755 | G43: 10 | H43: WB | J43: =755*10 -> 7550 | K43: Mini
A44: WB Msg | C44: Received | D44: 45553 | E44: Ref# 1028 | F44: Starlink Mini WB Card 54units $790 | G44: 54 | H44: WB | J44: =790*54 -> 42660 | K44: Mini
A45: AR Msg | C45: Received | D45: 45553 | E45: Ref# 1028 | F45: Starlink V4 ARB Card 1unit $297 | G45: 1 | H45: ARB | J45: =297*1 -> 297 | K45: V4
A46: AR Msg | C46: Received | D46: 45553 | E46: Ref# 1028 | F46: Starlink V4 ARB Card 1unit $298 | G46: 1 | H46: ARB | J46: 298 | K46: V4
...

Sheet Sell Sheet
C2: DATE | E2: Details | F2: Units | G2: Rate | H2: Amount
C3: 45562 | E3: Sell v4 50units | F3: 50 | G3: 1170 | H3: =F3*G3 -> 58500
C4: 45562 | E4: Sell Mini 1Unit | F4: 1 | G4: 2250 | H4: =F4*G4 -> 2250
C5: 45562 | E5: Sell Mini 50 Units | F5: 50 | G5: 2230 | H5: =F5*G5 -> 111500
C6: 45562 | E6: Sell v4 30units | F6: 30 | G6: 1175 | H6: =F6*G6 -> 35250
C8: 45566 | E8: Sell Mini 33units | F8: 33 | G8: 2200 | H8: =F8*G8 -> 72600
C9: 45566 | E9: Sell v4 44units | F9: 44 | G9: 1180 | H9: =F9*G9 -> 51920
C10: 45566 | E10: Sell v4 40units | F10: 40 | G10: 1180 | H10: =F10*G10 -> 47200
C12: 45576 | E12: Starlink V4 Sell By Faisal Bhai | F12: 104 | G12: 1230 | H12: =F12*G12 -> 127920
C13: 45576 | E13: Starlink V4 Sell By Faisal Bhai | F13: 109 | G13: 1235 | H13: =F13*G13 -> 134615
C14: 45576 | E14: Starlink Mini Sell By Faisal Bhai | F14: 5 | G14: 2200 | H14: =F14*G14 -> 11000
C15: 45576 | E15: Starlink Mini Sell By Faisal Bhai | F15: 10 | G15: 2180 | H15: =F15*G15 -> 21800
C16: 45576 | E16: Starlink Mini Sell By Faisal Bhai | F16: 2 | G16: 2140 | H16: =F16*G16 -> 4280
... C20: 45576 | E20: Starlink Mini Sell By Faisal Bhai | F20: 15 | G20: 2200 | H20: =F20*G20 -> 33000
E54: Total Sell | F54: =SUM(F3:F53) -> 521
C57: Date | E57: Details | F57: Rate | G57: Units | H57: Total
C58: 45474 | E58: Starlink V3 Sell to Encell Shop | F58: 1530 | G58: 48 | H58: =F58*G58 -> 73440
C59: 45474 | E59: Starlink V3 Sell to Encell Shop | F59: 1530 | G59: 24 | H59: =F59*G59 -> 36720
C60: 45478 | E60: Starlink V3 Sell to Encell Shop | F60: 1500 | G60: 31 | H60: =F60*G60 -> 46500
C61: 45482 | E61: Starlink V3 Sell to Encell Shop | F61: 1425 | G61: 23 | H61: =F61*G61 -> 32775
C62: 45482 | E62: Starlink V3 Sell to Encell Shop | F62: 1470 | G62: 5 | H62: =F62*G62 -> 7350
C63: 45484 | E63: Starlink V3 Sell to Encell Shop | F63: 1425 | G63: 10 | H63: =F63*G63 -> 14250
C64: 45484 | E64: Starlink V3 Sell to Encell Shop | F64: 1370 | G64: 20 | H64: =F64*G64 -> 27400
C65: 45484 | E65: Starlink V3 Sell to Encell Shop | F65: 1390 | G65: 37 | H65: =F65*G65 -> 51430
C66: 45491 | E66: Starlink V3 Sell to Encell Shop | F66: 1240 | G66: 30 | H66: =F66*G66 -> 37200
C67: 45491 | E67: Starlink V3 Sell to Encell Shop | F67: 1230 | G67: 22 | H67: =F67*G67 -> 27060
C68: 45491 | E68: Starlink V3 Sell to Encell Shop | F68: 1220 | G68: 43 | H68: =F68*G68 -> 52460
C69: 45497 | E69: Starlink V3 Sell to Encell Shop | F69: 1180 | G69: 8 | H69: =F69*G69 -> 9440
... C93: 45553 | E93: Starlink V4 Sell By Rabi | F93: 1170 | G93: 10 | H93: =F93*G93 -> 11700
C94: 45553 | E94: Starlink V4 Sell By Rabi | F94: 1170 | G94: 5 | H94: =F94*G94 -> 5850 | K94: Starlink Mini | L94: 74 Units
C95: 45562 | E95: Starlink V4 Sell By Faisal Bhai | F95: 1170 | G95: 50 | H95: =F95*G95 -> 58500 | K95: Starlink V4 | L95: 1,272 Units
C96: 45562 | E96: Starlink Mini Sell By Faisal Bhai | F96: 2250 | G96: 1 | H96: =F96*G96 -> 2250
C97: 45562 | E97: Starlink Mini Sell By Faisal Bhai | F97: 2230 | G97: 50 | H97: =F97*G97 -> 111500
C98: 45562 | E98: Starlink V4 Sell By Faisal Bhai | F98: 1175 | G98: 30 | H98: =F98*G98 -> 35250
G100: =SUM(G58:G99) -> 1346 | H100: =SUM(H58:H99) -> 1726535

Sheet AB CArd
A4: AB | C4: 45423 | D4: Ref#1003V3 | E4: Purchasing | F4: 46Units Purchase Ashfaq Sahab Card | G4: 24013.84 | H4: 2.42 | I4: =G4*H4 -> 58113.493 | K4: =K3+I4-J4 -> 58113.493 | M4: 46
A5: AB | C5: 45423 | D5: Ref#1003V3 | E5: Purchasing | F5: Card Payment Ashfaq Sahab | G5: 18944 | H5: 2.42 | I5: =G5*H5 -> 45844.48 | K5: =K4+I5-J5 -> 103957.97 | M5: 36
A6: AB | C6: 45468 | D6: Ref# 1007 V3 | E6: Purchasing | F6: Ashfaq Shab Card 57.5 Units @474 | G6: =57.5*474 -> 27255 | H6: 2.44 | I6: =G6*H6 -> 66502.2 | K6: =K5+I6-J6 -> 170460.17
A7: AB | C7: 45468 | D7: Ref# 1007 V3 | E7: Purchasing | F7: Ashfaq Shab Card 24 Units @474 | G7: =24*474 -> 11376 | H7: 2.44 | I7: =G7*H7 -> 27757.44 | K7: =K6+I7-J7 -> 198217.61
A8: AB/WB | C8: 45473 | D8: Ref# 1008 V3 | E8: Purchasing | F8: Petrol Expense (Ab + WB Card) | G8: 165 | H8: 2.44 | I8: =G8*H8 -> 402.6 | K8: =K7+I8-J8 -> 198620.21
A9: AB | C9: 45473 | D9: Ref# 1008 V3 | E9: Purchasing | F9: 4pcs Harvey Norman $500 | G9: =4*500 -> 2000 | H9: 2.44 | I9: =G9*H9 -> 4880 | K9: =K8+I9-J9 -> 203500.21
A10: AB | C10: 45473 | D10: Ref# 1008 V3 | E10: Purchasing | F10: 3 JB hi fi $500 | G10: =3*500 -> 1500 | H10: 2.44 | I10: =G10*H10 -> 3660 | K10: =K9+I10-J10 -> 207160.21
A11: AB | C11: 45473 | D11: Ref# 1008 V3 | E11: Purchasing | F11: 3 JB Hi fi $522 | G11: =3*522 -> 1566 | H11: 2.44 | I11: =G11*H11 -> 3821.04 | K11: =K10+I11-J11 -> 210981.25
A12: AB | C12: 45473 | D12: Ref# 1008 V3 | E12: Purchasing | F12: 1 JB Hi fi $522 (Pending ) | G12: 522 | H12: 2.44 | I12: =G12*H12 -> 1273.68 | K12: =K11+I12-J12 -> 212254.93
A13: AB | C13: 45473 | D13: Ref# 1008 V3 | E13: Purchasing | F13: 46 Bunnings $522 | G13: =46*522 -> 24012 | H13: 2.44 | I13: =G13*H13 -> 58589.28 | K13: =K12+I13-J13 -> 270844.21
A14: Refund | C14: 45473 | D14: Ref# 1008 V3 | E14: Purchasing | F14: Refundable Amount 46 Pcs @75 | G14: =46*75 -> 3450 | H14: 2.44 | I14: =G14*H14 -> 8418 | K14: =K13+I14-J14 -> 279262.21
A15: WB/AB | C15: 45502 | D15: Ref# 1009 V3 | E15: Purchasing | F15: 28pcs @$359 (1960 WB + 8092 AB) | G15: =28*350 -> 9800 | H15: 2.44 | I15: =G15*H15 -> 23912 | K15: =K14+I15-J15 -> 303174.21
A16: AB | C16: 45488 | D16: Ref# 1009 V3 | E16: Purchasing | F16: 11pcs Purchased (AB Card) @831.21 Aed | I16: =831.21*11 -> 9143.31 | K16: =K15+I16-J16 -> 312317.52
A17: AB | C17: 45477 | D17: Ref# 1010 V3 | E17: Purchasing | F17: Ticket Charges (Ashfaq Sahab Card ) | G17: 773 | H17: 2.44 | I17: =G17*H17 -> 1886.12 | K17: =K16+I17-J17 -> 314203.64
A18: AB | C18: 45477 | D18: Ref# 1010 V3 | E18: Purchasing | F18: Shipping Charges + Surcharge (Ashfaq Sahab Card) | G18: 5100 | H18: 2.44 | I18: =G18*H18 -> 12444 | K18: =K17+I18-J18 -> 326647.64
A19: WB/AB | C19: 45477 | D19: Ref# 1010 V3 | E19: Purchasing | F19: 92 pcs Purchased $359 (32078 Ashfaq Sahab Card / $290+$710 Waheed Bhai Card) | G19: =359*92 -> 33028 | H19: 2.44 | I19: =G19*H19 -> 80588.32 | K19: =K18+I19-J19 -> 407235.96
C20: 45491 | D20: Ref# 1012 V3 | E20: Purchasing | F20: 49units purchased @357 AB | G20: =357*49 -> 17493 | H20: 2.525 | I20: =G20*H20 -> 44169.825 | K20: =K19+I20-J20 -> 451405.79
C21: 45497 | D21: Ref# 1015 V3 | E21: Purchasing | F21: 74units @357 AB | G21: =357*74 -> 26418 | H21: 2.52 | I21: =G21*H21 -> 66573.36 | K21: =K20+I21-J21 -> 517979.15
C22: 45502 | D22: Ref# 1017 V3 | E22: Purchasing | F22: Sydney 6units AB Card @358 | G22: =358*6 -> 2148 | H22: 2.52 | I22: =G22*H22 -> 5412.96 | K22: =K21+I22-J22 -> 523392.11
I24: =SUM(I4:I23) -> 523392.11
I26: -4882.38
I27: -4676.61
I28: -4676.61
I29: -1408.31
I30: -5101.73
I31: =SUM(I24:I30) -> 502646.47
I34: 513906.11 | J34: =I34-I31 -> 11259.642
D38: Date | E38: Shipment | F38: Details | G38: Sell | H38: Cash Payment | I38: Balance
D40: 45420 | E40: Ref#1001V2 | F40: Sell By A/R V2 20pcs @1450 | G40: =20*1450 -> 29000 | I40: =I39+G40-H40 -> 29000 | J40: ok
D41: 45427 | E41: Ref#1002 V2 | F41: V2 Sold AMGT 5pcs @1190 (09/05/2024) | G41: =5*1190 -> 5950 | I41: =I40+G41-H41 -> 34950 | J41: ok
D42: 45428 | E42: Ref#1002 V2 | F42: Sold To A/R 2pcs @1000 | G42: =2*1000 -> 2000 | I42: =I41+G42-H42 -> 36950 | J42: ok
D43: 45419 | E43: Ref#1003V3 | F43: Sold to Encell Shop 20pcs @1790 | G43: =1790*20 -> 35800 | I43: =I42+G43-H43 -> 72750 | J43: ok
D44: 45420 | E44: Ref#1003V3 | F44: Sell to AMGT V3 09pcs @1800 | G44: =9*1800 -> 16200 | I44: =I43+G44-H44 -> 88950 | J44: ok
D45: 45420 | E45: Ref#1003V3 | F45: Sold to Encell Shop 10pcs @1800 | G45: =10*1800 -> 18000 | I45: =I44+G45-H45 -> 106950 | J45: ok
D46: 45427 | E46: Ref#1003V3 | F46: Sold To AMGT V3 2pcs @1800 (09/05/2024) | G46: =2*1800 -> 3600 | I46: =I45+G46-H46 -> 110550 | J46: ok
D47: 45427 | E47: Ref#1003V3 | F47: Sold To AMGT V3 2pcs @1750 (09/05/2024) | G47: =2*1750 -> 3500 | I47: =I46+G47-H47 -> 114050 | J47: ok
D48: 45427 | E48: Ref#1003V3 | F48: Sold To AMGT V3 5pcs @1740 (13/05/2024) | G48: =5*1740 -> 8700 | I48: =I47+G48-H48 -> 122750 | J48: ok
D49: 45427 | E49: Ref#1003V3 | F49: Sold To AMGT V3 16pcs @1650 (13/05/2024) | G49: =16*1650 -> 26400 | I49: =I48+G49-H49 -> 149150 | J49: ok
D50: 45427 | E50: Ref#1003V3 | F50: Sold to Encell Shop 26pcs @1750 | G50: =26*1750 -> 45500 | I50: =I49+G50-H50 -> 194650 | J50: ok
D51: 45427 | E51: Ref#1003V3 | F51: Sold to Encell Shop 5pcs @1700 | G51: =5*1700 -> 8500 | I51: =I50+G51-H51 -> 203150 | J51: ok
...

Sheet Starlink Stock
C2: Date | D2: Shipment | F2: Details | G2: Australia Qnty | J2: Dubai Balance Stock
C3: 45536 | F3: Old Balance | G3: 462
C4: 45539 | D4: Ref# 1019 V3 | E4: Purchased | F4: Received In Dubai Flat307 | G4: -400 | J4: 400
C5: 45539 | D5: Ref# 1019 V3 | E5: Ship | F5: Sold by A/R 04/09 to 07/09 | G5: 0 | J5: -400
C7: 45540 | D7: Ref# 1020 V4 | E7: Purchased | F7: Purchased | G7: 40
C8: 45547 | D8: Ref# 1021 | E8: Purchased | F8: Purchased Starlink Mini | G8: 42
C9: 45547 | D9: Ref# 1017 V3 | E9: Ship | F9: Old pcs 60 Send to Dubai | G9: -60 | J9: 60
C10: 45547 | D10: Ref# 1020 V4 | E10: Ship | F10: 40 units Send to dubai | G10: -40 | J10: 40
C11: 45547 | D11: Ref# 1021 | E11: Ship | F11: 23 units mini Send to Dubai | G11: -23 | J11: 23
C12: 45547 | D12: Ref# 1008 V3 | E12: - | F12: 1unit Returned AB Card | G12: -1 | J12: 0
C13: 45547 | D13: Ref# 1017 V3 | E13: - | F13: 1unit Missing Australia | G13: -1 | J13: 0
C14: 45548 | D14: Ref# 1022 | E14: Purchased | F14: Purchased Starlink Mini | G14: 10 | J14: 0
C15: 45548 | D15: Ref# 1021 | E15: Sell | F15: Sell Starlink Mini by A/R | J15: -23
C16: 45553 | D16: Ref# 1017 V3 | E16: Sell | F16: 30units Sell By Rabi @1175 | J16: -30
C17: 45553 | D17: Ref# 1017 V3 | E17: Sell | F17: 20units Sell By Rabi @1170 | J17: -20
C18: 45553 | D18: Ref# 1017 V3 | E18: Sell | F18: 10units Sell By Rabi @1170 | J18: -10
C19: 45549 | D19: Ref# 1020 V4 | E19: Sell | F19: 30Units Sell to Rabi @1165 | J19: -30
C20: 45553 | D20: Ref# 1020 V4 | E20: Sell | F20: 5Units Sell to Rabi @1170 | J20: -5
A21: Done | C21: 45553 | D21: Ref# 1020 V4 | E21: Sell | F21: 5Units Sell to Encell Shop @1170 | J21: -5
C23: 45549 | D23: Ref# 1024 V4 | E23: Purchased | F23: Starlink V4 Purchased | G23: 34
C24: 45550 | D24: Ref# 1025 V4 | E24: Purchased | F24: Starlink V4 Purchased | G24: 37
C25: 45551 | D25: Ref# 1026 V4 | E25: Purchased | F25: Starlink V4 Purchased | G25: 32
C26: 45551 | D26: Ref# 1026 Mini | E26: Purchased | F26: Starlink Mini Purchased | G26: 4
C27: 45552 | D27: Ref# 1027 V4 | E27: Purchased | F27: Starlink V4 Purchased | G27: 14
C28: 45553 | D28: Ref# 1028 V4 | E28: Purchased | F28: Starlink V4 Purchased | G28: 60
C29: 45553 | D29: Ref# 1028 Mini | E29: Purchased | F29: Starlink Mini Purchased | G29: 64
C30: 45554 | D30: Ref# 1029 V4 | E30: Purchased | F30: Starlink V4 Purchased | G30: 5
C31: 45554 | D31: Ref# 1029 Mini | E31: Purchased | F31: Starlink Mini Purchased | G31: 7
C32: 45556 | D32: Ref# 1030 Mini | E32: Purchased | F32: Starlink Mini Purchased | G32: 30
C33: 45558 | D33: Ref# 1031 V4 | E33: Purchased | F33: Starlink V4 Purchased | G33: 15
C34: 45558 | D34: Ref# 1031 Mini | E34: Purchased | F34: Starlink Mini Purchased | G34: 5
... C38: 45560 | D38: Ref# 1033 Mini | E38: Purchased | F38: Starlink Mini Purchased | G38: 1
C39: 45560 | E39: Ship | F39: Send to Dubai (V4 164Units Mini 84Units) | G39: =-164-84 -> -248 | J39: 248
C40: 45561 | D40: Ref# 1034 V4 | E40: Purchased | F40: Starlink V4 Purchased | G40: 6
C41: 45562 | E41: Sell | F41: Sell v4 50units | J41: -50
C42: 45562 | E42: Sell | F42: Sell Mini 1Unit | J42: -1
C43: 45562 | E43: Sell | F43: Sell Mini 50 Units | J43: -50
C44: 45562 | E44: Sell | F44: Sell v4 30units | J44: -30
C45: 45562 | D45: Ref# 1035 V4 | E45: Purchased | F45: Starlink V4 Purchased | G45: 14
C46: 45562 | D46: Ref# 1036 V4 | E46: Purchased | F46: Starlink V4 Purchased | G46: 100
...

Sheet Purchasing From July
C3: Date | D3: Shipment | E3: Details | F3: Units | G3: Per.Unit | H3: Amount | J3: GST
C4: 45473 | D4: Ref# 1008 V3 | E4: 59 Units Purchased V3 | F4: 59 | G4: =H4/F4 -> 518.64407 | H4: 30600 | J4: 3210 | K4: 1 unit Returned
C6: 45473 | D6: Ref# 1009 V3 | E6: 42 Units Purchased V3 | F6: 42 | G6: =H6/F6 -> 348.19643 | H6: 14624.25 | J6: 1370
A8: ok | C8: 45477 | D8: Ref# 1010 V3 | E8: 92 Units Purchased V3 | F8: 92 | G8: =H8/F8 -> 359 | H8: =359*92 -> 33028 | J8: 3002.65
A10: ok | C10: 45488 | D10: Ref# 1011 V3 | E10: 54 Units Purchased V3 | F10: 54 | G10: =H10/F10 -> 358.96296 | H10: 19384 | J10: 1763
A12: ok | C12: 45491 | D12: Ref# 1012 V3 | E12: 56 Units Purchased V3 | F12: 56 | G12: =H12/F12 -> 357 | H12: 19992 | J12: 1818
A14: ok | C14: 45491 | D14: Ref# 1013 V3 | E14: 250 Units Purchased V3 | F14: 250 | G14: =H14/F14 -> 357 | H14: =357*250 -> 89250 | J14: 8113
A16: ok | C16: 45495 | D16: Ref# 1014 V3 | E16: 113 Units Purchased V3 | F16: 113 | G16: =H16/F16 -> 357 | H16: 40341 | J16: 3667 | K16: Returned
A18: ok | C18: 45497 | D18: Ref# 1015 V3 | E18: 76 Units Purchased V3 | F18: 76 | G18: =H18/F18 -> 357 | H18: 27132 | J18: 2480
A20: ok | C20: 45501 | D20: Ref# 1016 V3 | E20: 37 Units Purchased V3 | F20: 37 | G20: =H20/F20 -> 359 | H20: 13283 | J20: 1207 | K20: Returned
A22: ok | C22: 45502 | D22: Ref# 1017 V3 | E22: 61 Units Purchased V3 | F22: 61 | G22: =H22/F22 -> 358.90164 | H22: 21893 | J22: =1795+196 -> 1991
A24: ok | C24: 45517 | D24: Ref# 1019 V3 | E24: 400 Units Purchased V3 | F24: 400 | G24: =H24/F24 -> 357 | H24: 142800 | J24: 12981
E26: Total GST M/O JULY & AUG | F26: =SUM(F4:F25) -> 1240 | J26: =SUM(J4:J25) -> 41602.65
C28: Date | D28: Shipment | E28: Details | F28: Units | H28: Amount | J28: GST
C29: 45540 | D29: Ref# 1020 V4 | E29: 40 units @358 WB | F29: 40 | G29: =H29/F29 -> 358 | H29: =358*40 -> 14320 | J29: 1301.82
C31: 45549 | D31: Ref#1024 V4 | E31: 34 Units Purchased | F31: 34 | G31: =H31/F31 -> 279.47059 | H31: 9502 | J31: 950.2
C33: 45550 | D33: Ref#1025 V4 | E33: 37 Units Purchased | F33: 37 | G33: =H33/F33 -> 298.18919 | H33: 11033 | J33: 1103.3
C35: 45551 | D35: Ref#1026 V4 | E35: 34 Units Purchased | F35: 34 | G35: =H35/F35 -> 280.35294 | H35: 9532 | J35: 953.2
C37: 45552 | D37: Ref#1027 V4 | E37: 14 Units Purchased | F37: 14 | G37: =H37/F37 -> 299.28571 | H37: 4190 | J37: 419
C39: 45553 | D39: Ref#1028 V4 | E39: 62 Units Purchased | F39: 62 | G39: =H39/F39 -> 297.98387 | H39: 18475 | J39: 1847.5
C41: 45554 | D41: Ref#1029 V4 | E41: 5 Units Purchased | F41: 5 | G41: =H41/F41 -> 298.2 | H41: 1491 | J41: 149.1
C43: 45558 | D43: Ref#1031 V4 | E43: 15 Units Purchased | F43: 15 | G43: =H43/F43 -> 297.53333 | H43: 4463 | J43: 446.3
C45: 45559 | D45: Ref#1032 V4 | E45: 19 Units Purchased | F45: 19 | G45: =H45/F45 -> 298.21053 | H45: 5666 | J45: 566.6
C47: 45560 | D47: Ref#1033 V4 | E47: 12 Units Purchased | F47: 11 | G47: =H47/F47 -> 302.18182 | H47: 3324 | J47: 332.4
C49: 45561 | D49: Ref#1034 V4 | E49: 6 Units Purchased | F49: 6 | G49: =H49/F49 -> 300.5 | H49: 1803 | J49: 180.3
C51: 45562 | D51: Ref#1035 V4 | E51: 14 Units Purchased | F51: 14 | G51: =H51/F51 -> 297.85714 | H51: 4170 | J51: 417
C53: 45562 | D53: Ref#1036 V4 | E53: 100 Units Purchased | F53: 100 | G53: =H53/F53 -> 298 | H53: 29800 | J53: 2709
C55: 45563 | D55: Ref#1037 V4 | E55: 14 Units Purchased | F55: 14 | G55: =H55/F55 -> 297.14286 | H55: 4160 | J55: 416
C57: 45564 | D57: Ref#1038 V4 | E57: 3 Units Purchased | F57: 0 | G57: =H57/F57 -> #DIV/0! | H57: 893
C59: 45565 | D59: Ref#1039 V4 | E59: 15 Units Purchased | F59: 15 | G59: =H59/F59 -> 298.66667 | H59: 4480 | J59: 448
E60: Total GST M/O SEP | F60: =SUM(F29:F59) -> 420 | J60: =SUM(J29:J59) -> 12239.72
C63: Date | D63: Shipment | E63: Details | F63: Units | H63: Amount | J63: GST
C64: 45547 | D64: Ref# 1021 Mini | E64: 42 Units Purchased | F64: 42 | G64: =H64/F64 -> 770.83333 | H64: 32375 | J64: 2251.78
C66: 45548 | D66: Ref# 1022 Mini | E66: Starlink mini 10 units @799 (WB Card) | F66: 10 | G66: =H66/F66 -> 799 | H66: =799*10 -> 7990 | J66: 799
C68: 45551 | D68: Ref#1026 Mini | E68: 4 Units Purchased | F68: 4 | G68: =H68/F68 -> 781.5 | H68: 3126 | J68: 312.6
C70: 45553 | D70: Ref#1028 Mini | E70: 64 Units Purchased | F70: 64 | G70: =H70/F70 -> 784.53125 | H70: 50210 | J70: 5021
C72: 45554 | D72: Ref#1029 Mini | E72: 7 Units Purchased | F72: 7 | G72: =H72/F72 -> 790 | H72: 5530 | J72: 553
C74: 45556 | D74: Ref#1030 Mini | E74: 30 Units Purchased | F74: 30 | G74: =H74/F74 -> 799 | H74: 23970 | J74: 2154
C76: 45558 | D76: Ref#1031 Mini | E76: 5 Units Purchased | F76: 5 | G76: =H76/F76 -> 756.2 | H76: 3781 | J76: 378.1
C78: 45559 | D78: Ref#1032 Mini | E78: 22 Units Purchased | F78: 22 | G78: =H78/F78 -> 757.81818 | H78: 16672 | J78: 1667.2
...

Sheet GST Charges
D5: Date | E5: Shipment | F5: GST | G5: Ledger
D6: 45397 | E6: V2 16pcs Shipment invoice | F6: 577.45 | G6: Waheed bhai
D7: 45397 | E7: V2 11pcs Shipment invoice | F7: 397 | G7: Waheed bhai
D8: 45397 | E8: 1st shipping invoice | F8: 29.09 | G8: Waheed bhai
D9: 45439 | E9: V3 106pcs GST $47.49 each | F9: 5033.94 | G9: Waheed bhai
E10: GST V2 Shipping Invoice $37.12 | F10: 37.12 | G10: Waheed bhai
D11: 45472 | E11: Ref#1007 12.5 units GST Charges | F11: =4512/94*12.5 -> 600 | G11: Waheed bhai
D12: 45502 | E12: Received And Adjust Waheed Bhai Ledger
E13: Total | F13: =SUM(F6:F12) -> 6674.6
D18: Date | E18: Shipment | F18: GST | G18: Ledger
D19: 45440 | E19: Ref#1004 35 pcs GST Charges | F19: 1665.3 | G19: Business
E20: 35pcs Shipping Charges GST | F20: 16.49 | G20: Business
D21: 45449 | E21: Ref#1005 60pcs V3 Starlink GST | F21: 2847.5 | G21: Business
E22: 60pcs Shipping Charges GST | F22: 27.72 | G22: Business
D23: 45450 | E23: Ref#1006 47pcs V3 Starlink GST | F23: 2177.5 | G23: Business
E24: 47pcs Shipping Charges GST | F24: 24.36 | G24: Business
D25: 45472 | E25: Ref#1007 92Units GST Charges | F25: 4512 | G25: Business
D26: 45488 | E26: Ref#1010 92units GST | F26: 3002.65 | G26: Business
D27: 45502 | E27: Received And Adjust Waheed Bhai Ledger | F27: -13673.52 | G27: Business
D30: Date | E30: Shipment | F30: GST | G30: Ledger
D31: 45509 | E31: Ref#1008 59units GST | F31: 3210 | G31: Business
D32: 45491 | E32: Ref#1009 42units GST | F32: 1370 | G32: Business
D33: 45488 | E33: Ref#1011 54units GST | F33: 1763 | G33: Business
D34: 45491 | E34: Ref#1012 56Units | F34: 1818 | G34: Business
D35: 45491 | E35: Ref#1013 250Units | F35: 8113 | G35: Business
E36: 250units Shipping Charges GST | F36: 150 | G36: Business
D37: 45495 | E37: Ref#1014 113Units GST | F37: 1130 | G37: Business
D38: 45509 | E38: Ref#1015 76Units | F38: 2480 | G38: Business
E39: 76units Shipping Charges GST | F39: 55 | G39: Business
D40: 45508 | E40: Ref#1016 37Units GST | F40: 1207 | G40: Business
D41: 45509 | E41: Ref#1017 55Units | F41: 1795 | G41: Business
D42: 45509 | E42: Ref#1017 6Units | F42: 196 | G42: Business
E44: Total | F44: =SUM(F19:F43) -> 23887
D48: Date | E48: Shipment | F48: Refundable | G48: Ledger
D49: 45468 | E49: Ref#1007 81.5pcs Refundable Charges | F49: 6109.24 | G49: Business
D50: 45473 | E50: 46pcs Refundable Charges $75 | F50: =46*75 -> 3450 | G50: Business
E51: Total | F51: =SUM(F49:F50) -> 9559.24
D55: Date | E55: Shipment | F55: Refundable | G55: Ledger
D56: 45468 | E56: Refundable Charges Ref#1007 12.5Units @597-522.04 =74.96 | F56: =74.96*12.5 -> 937 | G56: Waheed bhai
E57: Total | F57: =SUM(F56) -> 937
...

Sheet Expense Sheet
D4: Date | E4: Card No | F4: Units | G4: Amount AUD | N4: AB CARD | O4: 6012
E5: Invoice No.1 | N5: AB CARD | O5: 6866
D6: 45457 | E6: 6866 | F6: 3units | G6: 1791
D7: 45457 | E7: 6866 | F7: 3units | G7: =597*3 -> 1791
D8: 45459 | E8: 6866 | F8: 4units | G8: 2388
D9: 45457 | E9: 6866 | F9: 4units | G9: 2388
D10: 45457 | E10: 6866 | F10: 2units | G10: =597*2 -> 1194
D11: 45448 | E11: 6866 | F11: 4units | G11: =522*4 -> 2088
D12: 45458 | E12: 6866 | F12: 19units | G12: =19*597 -> 11343
D13: 45458 | E13: 6866 | F13: 6units | G13: =6*597 -> 3582
E14: Invoice No.2
D15: 45459 | E15: 6866 | F15: 7units | G15: =7*597 -> 4179
D16: 45459 | E16: 6866 | F16: 8units | G16: =8*597 -> 4776
D17: 45459 | E17: 6866 | F17: 7units | G17: 4179
D18: 45460 | E18: 6866 | F18: 8units | G18: =8*597 -> 4776
D19: 45458 | E19: 6866 | F19: 9units | G19: =9*597 -> 5373
D20: 45459 | E20: 6866 | F20: 12units | G20: =12*597 -> 7164
E21: Invoice No.3
D22: 45460 | E22: 6012 | F22: 4units | G22: =4*597 -> 2388
D23: 45459 | E23: 6012 | F23: 4units | G23: =4*597 -> 2388
D24: 45460 | E24: 6012 | F24: 4units | G24: =4*597 -> 2388
D25: 45459 | E25: 6012 | F25: 5units | G25: =5*597 -> 2985
D26: 45459 | E26: 6012 | F26: 8units | G26: =8*597 -> 4776
D27: 45449 | E27: 6866 | F27: 8units | G27: =8*522.03 -> 4176.24
D28: 45460 | E28: 6866 | F28: 11units | G28: 6866
D29: 45449 | E29: 6866 | F29: 7units | G29: =7*522.03 -> 3654.21
E31: Total | G31: =SUM(G6:G30) -> 86633.45
D33: Date | E33: Card No | F33: Units | G33: Amount AUD
D34: 45460 | E34: 070 | F34: 5units | G34: 2686
G35: =SUM(G34:G34) -> 2686
D39: Date | E39: Card No | F39: Amount AUD
D40: 45517 | E40: 6012 | F40: 5613.73
D41: 45517 | E41: 6012 | F41: 5613.73
D42: 45517 | E42: 6012 | F42: 4210.3
D43: 45517 | E43: 6012 | F43: 7017.17
D44: 45517 | E44: 6012 | F44: 11227.46
F46: =SUM(F40:F45) -> 33682.39
D48: Date | E48: Card No | F48: Amount AUD
D49: 45517 | E49: 6866 | F49: 4897.37
D50: 45517 | E50: 6866 | F50: 8401.52
...

Sheet Sheet1
D3: Date | E3: Invoice | F3: Model | G3: Qty | H3: Price | I3: Total $ | J3: Rate | K3: Per Unit Aed | L3: Total Aed | N3: Invoice | O3: Party | P3: Sell Per Unit | Q3: Total Per Unit
C4: AR Card | D4: 45549 | E4: Ref#001 | F4: IP 16ProMax 256GB | G4: 2 | H4: 2147 | I4: =G4*H4 -> 4294 | J4: 2.53 | K4: =H4*J4 -> 5431.91 | L4: =K4*G4 -> 10863.82
C5: AR Card | D5: 45549 | E5: Ref#001 | F5: IP 16ProMax 512GB | G5: 3 | H5: 2497 | I5: =G5*H5 -> 7491 | J5: 2.53 | K5: =H5*J5 -> 6317.41 | L5: =K5*G5 -> 18952.23
C7: WB Card | D7: 45550 | E7: Ref#002 | F7: IP 16ProMax 512GB | G7: 1 | H7: 2497 | I7: =G7*H7 -> 2497 | J7: 2.53 | K7: =H7*J7 -> 6317.41 | L7: =K7*G7 -> 6317.41
C8: AB Card | D8: 45550 | E8: Ref#002 | F8: IP 16ProMax 512GB | G8: 2 | H8: 2497 | I8: =G8*H8 -> 4994 | J8: 2.53 | K8: =H8*J8 -> 6317.41 | L8: =K8*G8 -> 12634.82
C10: AB Card | D10: 45551 | E10: Ref#003 | F10: IP 16ProMax 1TB | G10: 3 | H10: 2847 | I10: =G10*H10 -> 8541 | J10: 2.53 | K10: =H10*J10 -> 7202.91 | L10: =K10*G10 -> 21608.73
C11: AB Card | D11: 45551 | E11: Ref#003 | F11: IP 16Pro 256GB | G11: 3 | H11: 1997 | I11: =G11*H11 -> 5991 | J11: 2.53 | K11: =H11*J11 -> 5052.41 | L11: =K11*G11 -> 15157.23
C13: WB Card | D13: 45556 | E13: Ref#005 | F13: IP 16ProMax 256GB | G13: 11 | H13: 2149 | I13: =G13*H13 -> 23639 | J13: 2.53 | K13: =H13*J13 -> 5436.97 | L13: =K13*G13 -> 59806.67
C14: NB Card | D14: 45556 | E14: Ref#005 | F14: IP 16ProMax 256GB | G14: 8 | H14: 2149 | I14: =G14*H14 -> 17192 | J14: 2.53 | K14: =H14*J14 -> 5436.97 | L14: =K14*G14 -> 43495.76
F16: Total Purchasing | I16: =SUM(I4:I15) -> 74639 | L16: =SUM(L4:L15) -> 188836.67
F17: Less GST 10% | I17: -7463.9 | L17: -18883.67
F19: Shipping Charges $700 | L19: =700*2.53 -> 1771
F20: Clearing Charges | L20: 1155
F21: NET PURCHASING | L21: =SUM(L16:L20) -> 172879
F23: Sell To AMGT 33 Units | L23: -195520
F25: Profit Amount | L25: 22641
C29: AMGT | D29: 45556 | F29: 2 Unit IP 16 ProMax 256GB | G29: 4298 | H29: 2940.69 | I29: 3.674 | J29: =H29*I29 -> 10804.095
D30: 45556 | F30: 2 Unit IP 16 ProMax 256GB | G30: 4298 | H30: 2940.69 | I30: 3.674 | J30: =H30*I30 -> 10804.095
D31: 45556 | F31: 2 Unit IP 16 ProMax 256GB | G31: 4298 | H31: 2940.69 | I31: 3.674 | J31: =H31*I31 -> 10804.095
D32: 45556 | F32: 2 Unit IP 16 ProMax 256GB | G32: 4298 | H32: 2940.69 | I32: 3.674 | J32: =H32*I32 -> 10804.095
D33: 45556 | F33: 2 Unit IP 16 ProMax 1TB | G33: 5698 | H33: 3954.41 | I33: 3.674 | J33: =H33*I33 -> 14528.502
D34: 45574 | F34: 2 Unit IP 16 ProMax 256GB | G34: 4298 | H34: 2899.86 | I34: 3.674 | J34: =H34*I34 -> 10654.086
D35: 45574 | F35: 2 Unit IP 16 ProMax 256GB | G35: 4298 | H35: 2899.86 | I35: 3.674 | J35: =H35*I35 -> 10654.086
D36: 45574 | F36: 2 Unit IP 16 ProMax 256GB | G36: 4298 | H36: 2899.86 | I36: 3.674 | J36: =H36*I36 -> 10654.086
D37: 45574 | F37: 2 Unit IP 16 ProMax 256GB | G37: 4298 | H37: 2899.86 | I37: 3.674 | J37: =H37*I37 -> 10654.086
D38: 45574 | F38: 2 Unit IP 16 ProMax 256GB | G38: 4298 | H38: 2899.86 | I38: 3.674 | J38: =H38*I38 -> 10654.086
D39: 45574 | F39: 2 Unit IP 16 ProMax 256GB | G39: 4298 | H39: 2899.86 | I39: 3.674 | J39: =H39*I39 -> 10654.086
D40: 45574 | F40: 2 Unit IP 16 ProMax 256GB | G40: 4298 | H40: 2899.86 | I40: 3.674 | J40: =H40*I40 -> 10654.086
G42: =SUM(G29:G41) -> 52976 | H42: =SUM(H29:H41) -> 36016.19 | J42: =SUM(J29:J41) -> 132323.48
C45: WB Card | D45: 45556 | F45: 4 Unit IP 16 ProMax 1TB $2849 | G45: =2849*4 -> 11396 | H45: 2.55 | I45: =G45*H45 -> 29059.8 | J45: 29059.8
F46: 25 Unit IP 16 ProMax 256GB $2149 | G46: =2149*25 -> 53725 | H46: 2.55 | I46: =G46*H46 -> 136998.75 | J46: 136998.75
I47: =SUM(I45:I46) -> 166058.55

Sheet Sheet3
B4: Prchasing
C5: Unit | D5: Rate | E5: Amount | H5: Total Purchase | I5: =E14 -> 639025
B6: V4 | C6: 204 | D6: 1210 | E6: =C6*D6 -> 246840 | H6: Total Sell | I6: =E42 -> 914485
B7: V4 | C7: 42 | D7: 1160 | E7: =C7*D7 -> 48720
B8: V4 | C8: 183 | D8: 1225 | E8: =C8*D8 -> 224175 | H8: Balance | I8: =I6-I5 -> 275460
C9: =SUM(C6:C8) -> 429
B11: Mini | C11: 37 | D11: 2120 | E11: =C11*D11 -> 78440
B12: Mini | C12: 19 | D12: 2150 | E12: =C12*D12 -> 40850 | H12: v4 Balance | I12: =104+109+429 -> 642 | J12: =593 -> 593 | K12: =I12-J12 -> 49
C13: =SUM(C11:C12) -> 56 | H13: Mini Balance | I13: =56+48+12 -> 116 | J13: =84 -> 84 | K13: =I13-J13 -> 32
C14: Total Purchase | E14: =SUM(E6:E13) -> 639025
B17: Sell
C18: Unit | D18: Rate | E18: Amount
B19: V4 | C19: 104 | D19: 1230 | E19: =C19*D19 -> 127920
C20: 204 | D20: 1230 | E20: =C20*D20 -> 250920
C21: 150 | D21: 1235 | E21: =C21*D21 -> 185250
C22: 10 | D22: 1250 | E22: =C22*D22 -> 12500
C23: 20 | D23: 1235 | E23: =C23*D23 -> 24700
C24: 1 | D24: 1235 | E24: =C24*D24 -> 1235
C25: 50 | D25: 1240 | E25: =C25*D25 -> 62000
C26: 8 | D26: 1235 | E26: =C26*D26 -> 9880
C27: 5 | D27: 1250 | E27: =C27*D27 -> 6250
C28: 30 | D28: 1245 | E28: =C28*D28 -> 37350
C29: 1 | D29: 1250 | E29: =C29*D29 -> 1250
C30: 10 | D30: 1250 | E30: =C30*D30 -> 12500
C31: =SUM(C19:C30) -> 593
B32: Mini | C32: 5 | D32: 2200 | E32: =C32*D32 -> 11000
C33: 10 | D33: 2180 | E33: =C33*D33 -> 21800
C34: 2 | D34: 2140 | E34: =C34*D34 -> 4280
C35: 15 | D35: 2100 | E35: =C35*D35 -> 31500
C36: 3 | D36: 2150 | E36: =C36*D36 -> 6450
C37: 10 | D37: 2200 | E37: =C37*D37 -> 22000
C38: 19 | D38: 2200 | E38: =C38*D38 -> 41800
C39: 10 | D39: 2200 | E39: =C39*D39 -> 22000
C40: 10 | D40: 2190 | E40: =C40*D40 -> 21900
C41: =SUM(C32:C40) -> 84
C42: Total Sell | E42: =SUM(E19:E41) -> 914485
E48: Date | F48: Units | G48: Invoice Amount | H48: GST
E50: 45477 | F50: 92 units Shipping +surchage | G50: 5100
E51: 45488 | F51: 42 unit Shipping | G51: 2082
E52: 45493 | F52: 56 Unit Shipping | G52: 2556 | H52: 55
...
