Workbook

Sheet Balance Sheet
H2: Pending Item & Work
C4: Karachi Cash | D4: =#REF! -> #REF!
C5: Karachi Expense | D5: =#REF! -> #REF!
H6: 1900 dollar Handover to Waheed Bhai Ar Received 500 Exp 1400 Pending
C7: Dubai Cash | D7: =#REF! -> #REF! | H7: Taha Bhai Payable 24,079 PKR
C8: Dubai Expense | D8: =#REF! -> #REF!
C10: Meezan Bank Karachi | D10: 0 | G10: 45567 | H10: Canada Phone Purchasing & Sell Pending
C11: Dubai Bank A/C | D11: =#REF! -> #REF! | H11: AMGT 2units Pending Invoice
H12: meezan Entries Pending
H13: Taha Payment Balance 5387 PKR
H14: 7000 Ahsan CBA Aed Balance PKR Paid
H15: Qari Abdullah 10,000 Balance
H17: Mudassir Bhai 3 unit Purchased (Imei Pending)
H18: Mudassir Bhai Stock USA Office ???
C19: PARTY NAME | D19: BALANCE
C21: NAME | D21: BALANCES (PKR)
B22: ok | C22: Mudassir A/R | D22: ='Customer Ledger'!F511 -> 116642
B23: ok | C23: EuroNext Shop | D23: ='Customer Ledger'!F721 -> -901922.5
B24: ok | C24: Danish | D24: ='Customer Ledger'!F762 -> 560000
C25: Raaz | D25: ='Customer Ledger'!F569 -> -2500
B26: ok | C26: Daniyal | D26: ='Customer Ledger'!F554 -> 336350
C27: IRFAN | D27: ='Customer Ledger'!F398 -> 45000
C28: Waleed | D28: ='Customer Ledger'!F529 -> 100000
C29: RAZI | D29: ='Customer Ledger'!F386 -> 100000
C30: NAME | D30: BALANCES (AED)
C31: Machine Cargo Payment | D31: ='Customer Ledger'!F362 -> 4350
C32: Muhammad Usman | D32: ='Vendor Ledger'!F27 -> -5416.23
C33: ABDUL MAJID BHAI | D33: ='Customer Ledger'!F302 -> -32370
C34: ='Customer Ledger'!C210 -> Umer Gujranwala | D34: ='Customer Ledger'!F219 -> 100
C35: Salman (Al-Badar) | D35: ='Customer Ledger'!F372 -> 11314.38 | E35: $8820

Sheet Customer Ledger
A3: Customer Name : | C3: Saad & Wajahat Encell Shop
B5: Date | C5: Particular | D5: Dr | E5: Cr | F5: Balance
B7: 45405 | C7: Bill No SI0001 | D7: =Sell.Invoice!F23 -> 11550 | F7: =F6+D7-E7 -> 11550
B8: 45405 | C8: Bill No SI0002 | D8: =Sell.Invoice!F43 -> 9100 | F8: =F7+D8-E8 -> 20650
B9: 45405 | C9: Bill No SI0003 | D9: =Sell.Invoice!F63 -> 25500 | F9: =F8+D9-E9 -> 46150
B10: 45405 | C10: Bill No SI0004 | D10: =Sell.Invoice!F90 -> 15850 | F10: =F9+D10-E10 -> 62000
B11: 45405 | C11: Bill No SI0005 | D11: 11500 | F11: =F10+D11-E11 -> 73500
B12: 45405 | C12: Cash Received From Wajahat | E12: 19700 | F12: =F11+D12-E12 -> 53800
B13: 45406 | C13: Cash Received From Wajahat | E13: 10000 | F13: =F12+D13-E13 -> 43800
B14: 45407 | C14: Cash Received From Wajahat | E14: 30000 | F14: =F13+D14-E14 -> 13800
B15: 45408 | C15: Cash Received From Wajahat | E15: 50 | F15: =F14+D15-E15 -> 13750
B16: 45409 | C16: Discount | E16: 800 | F16: =F15+D16-E16 -> 12950
B17: 45415 | C17: Bill No SI0007 | D17: 111200 | F17: =F16+D17-E17 -> 124150
B18: 45418 | C18: Cash Received From Saad | E18: 40000 | F18: =F17+D18-E18 -> 84150
B19: 45418 | C19: IP 11 24pcs Discount 65x24 | E19: 1560 | F19: =F18+D19-E19 -> 82590
B20: 45418 | C20: IP 11ProMax 38pcs Discount 38x20 | E20: 760 | F20: =F19+D20-E20 -> 81830
B21: 45418 | C21: Cash Received From Wajahat (Machine Cargo Charges ) | E21: 4170 | F21: =F20+D21-E21 -> 77660
B22: 45418 | C22: Bill No SR0008 | E22: 6390 | F22: =F21+D22-E22 -> 71270
B23: 45418 | C23: Bill No SI0009 | D23: 2100 | F23: =F22+D23-E23 -> 73370
B24: 45419 | C24: Cash Received From Saad | E24: 1000 | F24: =F23+D24-E24 -> 72370
B25: 45419 | C25: Bill No SI0010 (V3) | D25: 35800 | F25: =F24+D25-E25 -> 108170
B26: 45420 | C26: Bill No SI0012 (V3) | D26: 18000 | F26: =F25+D26-E26 -> 126170
B27: 45420 | C27: Cash Received From Wajahat | E27: 53800 | F27: =F26+D27-E27 -> 72370
B28: 45420 | C28: Cash Received From Wajahat | E28: 10000 | F28: =F27+D28-E28 -> 62370
B29: 45423 | C29: Bill No SI0013 | D29: 36720 | F29: =F28+D29-E29 -> 99090
B30: 45426 | C30: Cash From Saad | E30: 50000 | F30: =F29+D30-E30 -> 49090
B31: 45426 | C31: Cash From Saad | E31: 1300 | F31: =F30+D31-E31 -> 47790
B32: 45429 | C32: Bill No SI0014 | D32: 5670 | F32: =F31+D32-E32 -> 53460
B33: 45430 | C33: Bill No SI0015 | D33: 16300 | F33: =F32+D33-E33 -> 69760
B34: 45430 | C34: Bill No SI0017 (V3 Invoice 14/05/2024) | D34: 54000 | F34: =F33+D34-E34 -> 123760
B35: 45432 | C35: Cash Received From Saad | E35: 54000 | F35: =F34+D35-E35 -> 69760
B36: 45432 | C36: Bill No SR0018 | E36: 1650 | F36: =F35+D36-E36 -> 68110
B37: 45432 | C37: Cash Received From Saad | E37: 30000 | F37: =F36+D37-E37 -> 38110
B38: 45435 | C38: Paid to Razi (Cargo Charges) | E38: 180 | F38: =F37+D38-E38 -> 37930
B39: 45436 | C39: Bill No SR0019 | E39: 2100 | F39: =F38+D39-E39 -> 35830
B40: 45437 | C40: Bill No SI0020 | D40: 22700 | F40: =F39+D40-E40 -> 58530
B41: 45440 | C41: Cash Received From Wajahat (V3 import Charges + hamali charges) | E41: 1260 | F41: =F40+D41-E41 -> 57270
B42: 45441 | C42: Bill No SI0022 | D42: 34960 | F42: =F41+D42-E42 -> 92230
B43: 45441 | C43: Cash Received By A/R | E43: 34960 | F43: =F42+D43-E43 -> 57270
B44: 45442 | C44: Cash Received From Saad | E44: 35000 | F44: =F43+D44-E44 -> 22270
...

Sheet final closing
D4: 45484 | E4: From Encell Shop (V3) | F4: 93080 | H4: =H3+F4-G4 -> 93080
D5: 45484 | E5: V3 Expense | G5: 100 | H5: =H4+F5-G5 -> 92980
D6: 45484 | E6: Irfan Customer (Discount By AR) | G6: 70 | H6: =H5+F6-G6 -> 92910
D7: 45485 | E7: Payment From Razi | F7: 10360 | H7: =H6+F7-G7 -> 103270
D8: 45485 | E8: Payment From Umar | F8: 1500 | H8: =H7+F8-G8 -> 104770
D9: 45485 | E9: Encell Shop Paid by Saad | F9: 40000 | H9: =H8+F9-G9 -> 144770
D10: 45485 | E10: Cash paid to Gatezone (12pcs Purchased) | G10: 24430 | H10: =H9+F10-G10 -> 120340
D11: 45486 | E11: Cash Paid to Faisal Bhai | G11: 3000 | H11: =H10+F11-G11 -> 117340
D12: 45487 | E12: Paid to Sasco (Payment Transfer Charges V3) | G12: 90 | H12: =H11+F12-G12 -> 117250
D13: 45487 | E13: From Encell Shop | F13: 180 | H13: =H12+F13-G13 -> 117430
D14: 45487 | E14: From Encell Shop | F14: 40 | H14: =H13+F14-G14 -> 117470
D15: 45487 | E15: From Encell Shop | F15: 1150 | H15: =H14+F15-G15 -> 118620
D16: 45487 | E16: 13 pro Max Camera repairing | G16: 180 | H16: =H15+F16-G16 -> 118440
D17: 45487 | E17: AR hamali Charges | G17: 20 | H17: =H16+F17-G17 -> 118420
D18: 45487 | E18: starlink hamali charges | G18: 20 | H18: =H17+F18-G18 -> 118400
D19: 45487 | E19: starlink cargo charges | G19: 1150 | H19: =H18+F19-G19 -> 117250
D20: 45491 | E20: From Encell Shop | F20: 51000 | H20: =H19+F20-G20 -> 168250
D21: 45491 | E21: Send To Australia | G21: 51000 | H21: =H20+F21-G21 -> 117250
D22: 45491 | E22: From Encell Shop | F22: 950 | H22: =H21+F22-G22 -> 118200
D23: 45491 | E23: starlink cargo charges | G23: 950 | H23: =H22+F23-G23 -> 117250
D24: 45491 | E24: From Encell Shop | F24: 20 | H24: =H23+F24-G24 -> 117270
D25: 45491 | E25: starlink hamali charges | G25: 20 | H25: =H24+F25-G25 -> 117250
D26: 45491 | E26: From Encell Shop | F26: 30 | H26: =H25+F26-G26 -> 117280
D27: 45491 | E27: From Encell Shop | F27: 50000 | H27: =H26+F27-G27 -> 167280
D28: 45491 | E28: Deposit A/R Card | G28: 30000 | H28: =H27+F28-G28 -> 137280
D29: 45491 | E29: Deposit Ashfaq Sahab Card | G29: 20000 | H29: =H28+F29-G29 -> 117280
D30: 45493 | E30: Cash From Encell Shop (Handover To Faisal Bhai ) | F30: 14000 | H30: =H29+F30-G30 -> 131280
D31: 45493 | E31: AR Card Deposit | G31: 30000 | H31: =H30+F31-G31 -> 101280
D32: 45494 | E32: AR Card Deposit | G32: 20000 | H32: =H31+F32-G32 -> 81280
D33: 45495 | E33: Paid to Faisal Bhai by Wajahat | G33: 3000 | H33: =H32+F33-G33 -> 78280
E34: Faheem | G34: 400 | H34: =H33+F34-G34 -> 77880
H35: =H34+F35-G35 -> 77880
D41: Cash In Hand | E41: =#REF! -> #REF!
D42: Cash At meezan Bank | E42: 0
D43: Cash at ENBD Card | E43: 18604
D44: Cash at Dubai Islamic Bank | E44: ='AR Bank Accounts'!#REF!-25000 -> #REF!
D45: Receivable PKR | E45: 4747428
D46: Receivable Aed | E46: 25732
D47: Stock Value | E47: 63968
D49: Payable PKR | E49: -2226667
...

Sheet Vendor Ledger
A3: Vendor Name : | C3: Muhammad Usman
B5: Date | C5: Particular | D5: Dr | E5: Cr | F5: Balance
B7: 45405 | C7: Bill No PI0001 | E7: =Pur.Invoice!F21 -> 18375 | F7: =F6+D7-E7 -> -18375
B8: 45405 | C8: Bill No PI0002 | E8: =Pur.Invoice!F43 -> 23650 | F8: =F7+D8-E8 -> -42025
B9: 45405 | C9: Bill No PI0003 | E9: =Pur.Invoice!F74 -> 9999.99 | F9: =F8+D9-E9 -> -52024.99
B10: 45405 | C10: Bill No PI0004 | E10: =Pur.Invoice!F123 -> 31000 | F10: =F9+D10-E10 -> -83024.99
B11: 45406 | C11: From A/R Meezan A/C 15lacs | D11: 19607.84 | F11: =F10+D11-E11 -> -63417.15
B12: 45406 | C12: From EuroNext Meezan A/C 2.5lacs | D12: 3267.97 | F12: =F11+D12-E12 -> -60149.18
B13: 45406 | C13: From EuroNext Meezan A/C 2.5lacs | D13: 3267.97 | F13: =F12+D13-E13 -> -56881.21
B14: 45419 | C14: Paid By A/R | D14: 26000 | F14: =F13+D14-E14 -> -30881.21
B15: 45421 | C15: adjustment By A/R | D15: 30001.21 | F15: =F14+D15-E15 -> -880
F16: =F15+D16-E16 -> -880
C17: Paid By A/R For New Shipment | D17: 50000 | F17: =F16+D17-E17 -> 49120
B18: 45453 | C18: Shipment Clearing Charges | D18: 760 | E18: 760 | F18: =F17+D18-E18 -> 49120
B19: 45453 | C19: Bill No PI0003 | E19: 129728.22 | F19: =F18+D19-E19 -> -80608.22 | G19: Updated 02/07/2024 | H19: 2 iphone 15 kit discount $10
B20: 45456 | C20: From Encell Shop | D20: 50000 | F20: =F19+D20-E20 -> -30608.22 | H20: 1 iphone 15pm kit discount $30
B21: 45474 | C21: 5pcs Returned Invoice PR0022 | D21: 13887.72 | F21: =F20+D21-E21 -> -16720.5 | H21: Watch ultra Purchased
B22: 45497 | C22: 24pcs Returned PR0029 | D22: 1304.27 | F22: =F21+D22-E22 -> -15416.23
B23: 45500 | C23: Payment By Wajahat | D23: 10000 | F23: =F22+D23-E23 -> -5416.23
F24: =F23+D24-E24 -> -5416.23
F25: =F24+D25-E25 -> -5416.23
F26: =F25+D26-E26 -> -5416.23
C27: TOTAL BALANCE | F27: =F26+D27-E27 -> -5416.23
A30: Vendor Name : | C30: ALI KARACHI
B32: Date | C32: Particular | D32: Dr | E32: Cr | F32: Balance
C34: Old Balance | D34: 94813.52 | F34: =F33+D34-E34 -> 94813.52
B35: 45405 | C35: Bill No PI0005 | E35: 154324 | F35: =F34+D35-E35 -> -59510.48
B36: 45420 | C36: Payment By A/R To AMGT | D36: 40000 | F36: =F35+D36-E36 -> -19510.48
B37: 45420 | C37: Payment By A/R To AMGT | D37: 20000 | F37: =F36+D37-E37 -> 489.52
B38: 45420 | C38: Payment By A/R To AMGT | D38: 10000 | F38: =F37+D38-E38 -> 10489.52
B39: 45412 | C39: Unlocking Mar-2024 | E39: 534.86 | F39: =F38+D39-E39 -> 9954.66
C40: Hamali Charges | E40: 40 | F40: =F39+D40-E40 -> 9914.66
B41: 45423 | C41: Payment | D41: 3455 | F41: =F40+D41-E41 -> 13369.66
B42: 45426 | C42: Bill No PI0006 | E42: 56288 | F42: =F41+D42-E42 -> -42918.34
B43: 45427 | C43: Cash Payment From Encell Shop | D43: 50000 | F43: =F42+D43-E43 -> 7081.66
B44: 45427 | C44: Hamali Charges | E44: 10 | F44: =F43+D44-E44 -> 7071.66
B45: 45442 | C45: Paid by A/R | D45: 35000 | F45: =F44+D45-E45 -> 42071.66
B46: 45442 | C46: Cash ??? | E46: 4903 | F46: =F45+D46-E46 -> 37168.66
B47: 45443 | C47: Unlocking May-2024 | E47: 527.77 | F47: =F46+D47-E47 -> 36640.89
B48: 45447 | C48: Bill No PI0012 | E48: 44886 | F48: =F47+D48-E48 -> -8245.11 | G48: 1632
...

Sheet IMEI Record
B2: Vendor Name | C2: Ali Karachi
B3: Date | C3: 45409
B4: Bill # | C4: PI0005
C5: Model | D5: Imei
C7: iPhone 13 Pro Max | D7: 359272538672231
C8: iPhone 13 Pro Max | D8: 358226363284224
C9: iPhone 13 Pro Max | D9: 352206206248129
C10: iPhone 13 Pro Max | D10: 352569487339366
C11: iPhone 13 Pro Max | D11: 352569482118625
C12: iPhone 11 Pro | D12: 353243103508718
C13: iPhone 11 Pro Max | D13: 353901105081428
C14: iPhone 11 Pro Max | D14: 353898100810571
C15: iPhone 11 Pro Max | D15: 353906102600203
C17: iPhone 13 Pro Max | D17: 358677238942364
C18: iPhone 13 Pro Max | D18: 356370168789391
... C149: iPhone 13 Pro Max | D149: 350419539067031
B151: Vendor Name | C151: Ali Karachi
B152: Date | C152: 45426
B153: Bill # | C153: PI0006
C154: Model | D154: Imei
B157: Invoice 1 | C157: Apple / iPhone 13 Pro Max / A2484 / 256GB / Gold / ATT / LOCKED / TPS B+ | D157: 350419531801221
C158: Apple / iPhone 13 Pro Max / A2484 / 256GB / Gold / ATT / LOCKED / TPS B+ | D158: 350879908057279
C159: Apple / iPhone 13 Pro Max / A2484 / 256GB / Gold / ATT / LOCKED / TPS B+ | D159: 353282623901839
C160: Apple / iPhone 13 / A2482 / 128GB / Midnight / Other / LOCKED / TPS B+ | D160: 357774339917303
C161: Apple / iPhone 13 Pro Max / A2484 / 256GB / Sierra Blue / Other / LOCKED / TPS B+ | D161: 350566102429814
C162: Apple / iPhone 13 Pro Max / A2484 / 256GB / Sierra Blue / Other / LOCKED / TPS B+ | D162: 353210482274550
C163: Apple / iPhone 13 / A2482 / 128GB / Green / Other / LOCKED / TPS B+ | D163: 350555046945225
C164: Apple / iPhone 13 / A2482 / 128GB / Green / Other / LOCKED / TPS B+ | D164: 354455405036508
C165: Apple / iPhone 13 / A2482 / 128GB / Green / Other / LOCKED / TPS B+ | D165: 359175929817986
C166: Apple / iPhone 11 Pro Max / A2161 / 512GB / Green / T-Mobile / LOCKED / TPS C+ | D166: 352838116444875
C167: Apple / iPhone 11 Pro Max / A2161 / 256GB / Grey / Unlocked / UNLOCKED / TPS C+ | D167: 352843112285413
C168: Apple / iPhone 11 Pro Max / A2161 / 256GB / Grey / Unlocked / UNLOCKED / TPS C+ | D168: 352844114944262
C169: Apple / iPhone 11 Pro Max / A2161 / 256GB / Grey / Unlocked / UNLOCKED / TPS C+ | D169: 352849114333382
... C177: Apple / iPhone 11 Pro Max / A2218 / 256GB / Grey / Unlocked / UNLOCKED / TPS C+ | D177: 353916104988365
B179: Invoice 2 | C179: Apple / iPhone 12 Pro Max / A2342 / 256GB / Graphite / ATT / LOCKED / TPS A+ | D179: 358686416816894
C180: Apple / iPhone 12 Pro Max / A2342 / 256GB / Graphite / Other / LOCKED / TPS A+ | D180: 354741660139735
C181: Apple / iPhone 13 Pro Max / A2484 / 256GB / Gold / Other / LOCKED / TPS A+ | D181: 352569484750532
C182: Apple / iPhone 13 Pro Max / A2484 / 256GB / Sierra Blue / ATT / LOCKED / TPS B+ | D182: 352396477711747
C183: Apple / iPhone 13 Pro Max / A2484 / 256GB / Sierra Blue / ATT / LOCKED / TPS B+ | D183: 357447886566522
C184: Apple / iPhone 13 / A2482 / 128GB / Blue / Other / LOCKED / TPS B+ | D184: 350225646859065
...

Sheet Sell.Invoice
B3: Sell Invoice
B5: Bill No: | C5: SI0001
B7: Name: | C7: Saad & Wajahat Encell Shop | D7: Date: | E7: 45405
B8: Contact
B9: Add:
B11: S.No | C11: Particulars | D11: Rate | E11: Qnty | F11: Amount
B13: 1 | C13: S22 Ultra | D13: 962.5 | E13: 4 | F13: =D13*E13 -> 3850
B14: 2 | C14: Note 20Ultra | D14: 962.5 | E14: 1 | F14: =D14*E14 -> 962.5
B15: 3 | C15: S21 | D15: 962.5 | E15: 3 | F15: =D15*E15 -> 2887.5
B16: 4 | C16: S21Plus | D16: 962.5 | E16: 1 | F16: =D16*E16 -> 962.5
B17: 5 | C17: S23 Ultra | D17: 962.5 | E17: 2 | F17: =D17*E17 -> 1925
B18: 6 | C18: S23Plus | D18: 962.5 | E18: 1 | F18: =D18*E18 -> 962.5
B23: Total | F23: =SUM(F13:F22) -> 11550
L25: EuroNext | M25: SI0025
B26: Sell Invoice
B28: Bill No: | C28: SI0002
B30: Name: | C30: Saad & Wajahat Encell Shop | D30: Date: | E30: 45405
B31: Contact
B32: Add:
B34: S.No | C34: Particulars | D34: Rate | E34: Qnty | F34: Amount
B36: 1 | C36: IP 11 64Gb Box | D36: 620 | E36: 5 | F36: =D36*E36 -> 3100
B37: 2 | C37: IP 15Pro 128Gb (Lock) | D37: 2050 | E37: 1 | F37: =D37*E37 -> 2050
B38: 3 | C38: S24 Ultra | D38: 2600 | E38: 1 | F38: =D38*E38 -> 2600
B39: 4 | C39: S24 | D39: 1350 | E39: 1 | F39: =D39*E39 -> 1350
B43: Total | F43: =SUM(F36:F42) -> 9100
B46: Sell Invoice
B48: Bill No: | C48: SI0003
B50: Name: | C50: Saad & Wajahat Encell Shop | D50: Date: | E50: 45405
B51: Contact
B52: Add:
B54: S.No | C54: Particulars | D54: Rate | E54: Qnty | F54: Amount
B56: 1 | C56: S24 | D56: 1350 | E56: 4 | F56: =D56*E56 -> 5400
B57: 2 | C57: S24 Ultra | D57: 2600 | E57: 7 | F57: =D57*E57 -> 18200
B58: 3 | C58: Fold 5 | D58: 1900 | E58: 1 | F58: =D58*E58 -> 1900
B63: Total | F63: =SUM(F56:F62) -> 25500
B66: Sell Invoice
B68: Bill No: | C68: SI0004
B70: Name: | C70: Saad & Wajahat Encell Shop | D70: Date: | E70: 45405
B71: Contact
B72: Add:
...

Sheet Pur.Invoice
B3: Purchased Invoice
B5: Bill No: | C5: PI0001
B7: Name: | C7: Muhammad Usman | D7: Date: | E7: 45405
B8: Contact
B9: Add:
B11: S.No | C11: Particulars | D11: Rate | E11: Qnty | F11: Amount
B13: 1 | C13: IP 11 Box | D13: 625 | E13: 5 | F13: =D13*E13 -> 3125
B14: 2 | C14: IP 15ProMax | D14: 2400 | E14: 4 | F14: =D14*E14 -> 9600
B15: 3 | C15: IP 15Pro | D15: 2000 | E15: 1 | F15: =D15*E15 -> 2000
B16: 4 | C16: S24 Ultra | D16: 2350 | E16: 1 | F16: =D16*E16 -> 2350
B17: 5 | C17: S24 | D17: 1300 | E17: 1 | F17: =D17*E17 -> 1300
B21: Total | F21: =SUM(F13:F20) -> 18375
B25: Purchased Invoice | L25: EuroNext | M25: SI0025
B27: Bill No: | C27: PI0002
B29: Name: | C29: Muhammad Usman | D29: Date: | E29: 45405
B30: Contact
B31: Add:
B33: S.No | C33: Particulars | D33: Rate | E33: Qnty | F33: Amount
B35: 1 | C35: S24 box | D35: 1300 | E35: 4 | F35: =D35*E35 -> 5200
B36: 2 | C36: Z Fold 5 | D36: 2000 | E36: 1 | F36: =D36*E36 -> 2000
B37: 3 | C37: S24 Ultra | D37: 2350 | E37: 7 | F37: =D37*E37 -> 16450
B43: Total | F43: =SUM(F35:F42) -> 23650
B45: Purchased Invoice
B47: Bill No: | C47: PI0003
B49: Name: | C49: Muhammad Usman | D49: Date: | E49: 45405
B50: Contact
B51: Add:
B53: S.No | C53: Particulars | D53: Rate | E53: Qnty | F53: Amount
B55: 1 | C55: Google Pixel 7 Locked | D55: 555.555 | E55: 1 | F55: =D55*E55 -> 555.555
B56: 2 | C56: S22 Ultra 128GB | D56: 555.555 | E56: 1 | F56: =D56*E56 -> 555.555
B57: 3 | C57: S22 Ultra 256GB | D57: 555.555 | E57: 1 | F57: =D57*E57 -> 555.555
B58: 4 | C58: A54 128GB Locked | D58: 555.555 | E58: 1 | F58: =D58*E58 -> 555.555
B59: 5 | C59: Flip5 256GB Locked | D59: 555.555 | E59: 1 | F59: =D59*E59 -> 555.555
B60: 6 | C60: Note20 ultra 128GB Locked | D60: 555.555 | E60: 1 | F60: =D60*E60 -> 555.555
B61: 7 | C61: S21 128GB Locked | D61: 555.555 | E61: 2 | F61: =D61*E61 -> 1111.11
B62: 8 | C62: S21 256GB Locked | D62: 555.555 | E62: 1 | F62: =D62*E62 -> 555.555
B63: 9 | C63: S21Plus 128GB Locked | D63: 555.555 | E63: 1 | F63: =D63*E63 -> 555.555
B64: 10 | C64: S22 Ultra 256GB Locked | D64: 555.555 | E64: 1 | F64: =D64*E64 -> 555.555
B65: 11 | C65: S22 Ultra 512GB Locked | D65: 555.555 | E65: 1 | F65: =D65*E65 -> 555.555
B66: 12 | C66: S23 FE 128GB Locked | D66: 555.555 | E66: 1 | F66: =D66*E66 -> 555.555
...

Sheet AR Bank Accounts
D2: AR Dubai Islamic Bank A/C
C3: Date | D3: Details | E3: Debit | F3: Credit | G3: Balance
C4: 45495 | D4: Opening Balance | G4: 46979.46
C5: 45498 | D5: POS Purchase | F5: 41 | G5: =G4+E5-F5 -> 46938.46
C6: 45500 | D6: POS Purchase | F6: 33.5 | G6: =G5+E6-F6 -> 46904.96
C7: 45501 | D7: POS Purchase | F7: 15.5 | G7: =G6+E7-F7 -> 46889.46
C8: 45501 | D8: POS Purchase | F8: 1.5 | G8: =G7+E8-F8 -> 46887.96
C9: 45504 | D9: POS Purchase | F9: 13.6 | G9: =G8+E9-F9 -> 46874.36
C10: 45504 | D10: POS Purchase | F10: 19.5 | G10: =G9+E10-F10 -> 46854.86
C11: 45504 | D11: POS Purchase | F11: 315 | G11: =G10+E11-F11 -> 46539.86
C12: 45504 | D12: POS Purchase | F12: 8 | G12: =G11+E12-F12 -> 46531.86
C13: 45504 | D13: POS Purchase | F13: 18.5 | G13: =G12+E13-F13 -> 46513.36
C14: 45505 | D14: POS Purchase | F14: 10 | G14: =G13+E14-F14 -> 46503.36
C15: 45505 | D15: Salary | E15: 20000 | G15: =G14+E15-F15 -> 66503.36
C16: 45506 | D16: Service Charges | F16: 1.2 | G16: =G15+E16-F16 -> 66502.16
C17: 45506 | D17: Outgoing Domestic Fund Transfer | F17: 108 | G17: =G16+E17-F17 -> 66394.16
C18: 45506 | D18: Service Charges | F18: 1.2 | G18: =G17+E18-F18 -> 66392.96
C19: 45506 | D19: Outgoing Domestic Fund Transfer | F19: 108 | G19: =G18+E19-F19 -> 66284.96
C20: 45506 | D20: Bank Charges | F20: 1 | G20: =G19+E20-F20 -> 66283.96
C21: 45506 | D21: Service Charges | F21: 1.2 | G21: =G20+E21-F21 -> 66282.76
C22: 45506 | D22: Outgoing Domestic Fund Transfer | F22: 108 | G22: =G21+E22-F22 -> 66174.76
C23: 45510 | D23: DU Payment | F23: 35 | G23: =G22+E23-F23 -> 66139.76
C24: 45510 | D24: DU Payment | F24: 65 | G24: =G23+E24-F24 -> 66074.76
C25: 45510 | D25: POS Purchase EMIRATES | F25: 1170 | G25: =G24+E25-F25 -> 64904.76
C26: 45512 | D26: POS Purchase | F26: 39 | G26: =G25+E26-F26 -> 64865.76
C27: 45512 | D27: POS Purchase (royal paris hotel) | F27: 18 | G27: =G26+E27-F27 -> 64847.76
... C39: 45522 | D39: Ticket change Charges | F39: 743 | G39: =G38+E39-F39 -> 49840.79
D40: adjustment | G40: =G39+E40-F40 -> 49840.79
C41: 45537 | D41: DU Payment | F41: 20 | G41: =G40+E41-F41 -> 49820.79
C42: 45538 | D42: Chq Book Charges | F42: 26.25 | G42: =G41+E42-F42 -> 49794.54
C43: 45539 | D43: Salary Deposit (Adjust A/R Cash) | E43: 20000 | G43: =G42+E43-F43 -> 69794.54
C44: 45540 | D44: DU Payment | F44: 20 | G44: =G43+E44-F44 -> 69774.54
C45: 45540 | D45: POS Purchased Flydubai | F45: 345.05 | G45: =G44+E45-F45 -> 69429.49
C46: 45543 | D46: POS Royal Paris Hotel | F46: 18 | G46: =G45+E46-F46 -> 69411.49
C47: 45543 | D47: Trasnfer Credit Card A/C | F47: 3000 | G47: =G46+E47-F47 -> 66411.49
C48: 45543 | D48: Trasnfer Credit Card A/C | F48: 14600 | G48: =G47+E48-F48 -> 51811.49
C49: 45545 | D49: POS (Albaik Dubai) | F49: 16 | G49: =G48+E49-F49 -> 51795.49
C50: 45545 | D50: POS (Dubai Taxi) | F50: 34 | G50: =G49+E50-F50 -> 51761.49
C51: 45545 | D51: POS (Sulaiya Supermarket) | F51: 61.98 | G51: =G50+E51-F51 -> 51699.51
C52: 45545 | D52: POS (Albaik Dubai) | F52: 144 | G52: =G51+E52-F52 -> 51555.51
...

Sheet Mudassir Purchasing
F4: Pur. | H4: Sell To | I4: Price
C5: 45429 | D5: Watch Ultra | E5: 355500639429695 | F5: 185000 | G5: Recvd | H5: Sell To Shoaib Bhai | I5: 2475 Aed
C6: 45429 | D6: Watch Ultra | E6: ?? | F6: 185000 | G6: Recvd | H6: Sell To Shoaib Bhai | I6: 2475 Aed
C8: 45441 | D8: IP 15 proMax blue | E8: 352676524721637 | F8: 180000 | G8: Recvd | H8: Sell To razi | I8: 2430 AED
C10: 45441 | D10: Watch Ultra | E10: ?? | F10: 185000 | G10: USA | J10: Received Encell Shop 24/06/2024
C12: 45442 | D12: IP 15 ProMax White | E12: 358862625559555 | F12: 180000 | G12: USA | H12: Sell To encell Shop | I12: 2500 AED | J12: Received Encell Shop 24/06/2024
C13: 45442 | D13: IP 15 ProMax Natural | E13: 355430975963075 | F13: 190000 | J13: Received Encell Shop 24/06/2024
C14: 45442 | D14: Watch Ultra | E14: 355500636585010 | F14: 180000 | G14: USA | J14: Missing By mistake Send To usman
C15: 45446 | D15: Watch Ultra | E15: 358161185579503 | F15: 180000 | H15: Sell to umair | I15: 2475 AED | J15: Received Encell Shop 27/06/2024 | K15: ok
C16: 45451 | D16: IP 15 ProMax White | E16: 351581974302501 | F16: 180000 | H16: Sell To encell Shop | I16: 2500 AED | J16: Received Encell Shop 27/06/2024 | K16: ok
C17: 45451 | D17: IP 15 ProMax White | E17: 352676525849155 | F17: 180000 | H17: Sell To encell Shop | I17: 2500 AED | J17: Received Encell Shop 27/06/2024 | K17: ok
C18: 45451 | D18: Watch Ultra | E18: 355500637291410 | F18: 180000 | H18: Sell to umair | I18: 2475 AED | J18: Received Encell Shop 27/06/2024 | K18: ok
C19: 45451 | D19: Watch Ultra | E19: 355500639045483 | F19: 180000 | H19: Sell to umair | I19: 2475 AED | J19: Received Encell Shop 27/06/2024 | K19: ok
C20: 45451 | D20: IP 15 ProMax Natural | E20: 355430975754920 | F20: 190000 | H20: Sell To encell Shop | I20: 2720 AED | J20: Received Encell Shop 27/06/2024 | K20: ok
C22: 45453 | D22: Watch Ultra | E22: 355500639599224 | F22: 180000 | H22: Sell to umair | I22: 2475 AED | J22: Received Encell Shop 27/06/2024 | K22: ok
C23: 45454 | D23: Watch Ultra | E23: 355500635523269 | F23: 180000 | H23: Sell to umair | I23: 2475 AED | J23: Received Encell Shop 27/06/2024 | K23: ok
C25: 45455 | D25: Watch Ultra | E25: 355500637698580 | F25: 180000 | J25: Received Encell Shop 11/07/2024
C27: 45457 | D27: Watch Ultra 2 | E27: 355500638142711 | F27: 175000 | H27: Returned 29/07/2024 | J27: Received Encell Shop 11/07/2024
C28: 45457 | D28: Watch Ultra 2 | E28: 355500635621501 | F28: 175000 | J28: Received Encell Shop 11/07/2024
C29: 45457 | D29: Watch Ultra 2 | E29: 355500637698580 | F29: 175000 | J29: Received Encell Shop 11/07/2024
C30: 45457 | D30: Watch Ultra 2 | E30: 357114365908449 | F30: 175000 | J30: Received Encell Shop 11/07/2024
C32: 45463 | D32: Watch Ultra 2 | E32: 355500637735705 | F32: 175000 | J32: Received Encell Shop 11/07/2024
C33: 45469 | D33: Watch Ultra 2 | E33: 357114365969946 | F33: 175000 | H33: Not Received Returned | I33: 45497
C34: 45469 | D34: Watch Ultra 2 | E34: 355500637580994 | F34: 175000 | H34: Not Received Returned | I34: 45497
C36: 45474 | D36: Watch Ultra 2 | E36: 358161187420516 | F36: 175000 | H36: Returned 29/07/2024 | J36: Received Encell Shop 22/07/2024
C37: 45492 | D37: Watch Ultra 2 | E37: 358161188279309 | F37: 175000 | H37: Returned 29/07/2024 | J37: Received Encell Shop 22/07/2024
C39: 45495 | D39: IP 15 Pro 128GB Black | E39: 350404321911646 | F39: 155000 | G39: cancelled | H39: cancelled
C40: 45495 | D40: IP 15 Pro 256GB Black | E40: 356444800452880 | F40: 160000 | H40: USA Office | J40: Received Encell Shop 13/08/2024
C41: 45495 | D41: IP 15 Pro 256GB Black | E41: 350684900665818 | F41: 160000 | H41: USA Office | J41: Received Encell Shop 13/08/2024
C42: 45495 | D42: IP 15 Pro 1TB Black | E42: 350684901224722 | F42: 175000 | H42: USA Office | J42: Received Encell Shop 13/08/2024
C44: 45497 | D44: IP 15 ProMax 256GB Natural | E44: 355430976748020 | F44: 202000 | H44: USA Office | J44: Received Encell Shop 13/08/2024
C45: 45497 | D45: IP 15 ProMax 256GB Natural | E45: 358862626698097 | F45: 202000 | H45: USA Office | J45: Received Encell Shop 13/08/2024
C47: 45503 | D47: Watch Ultra 2 | E47: 358161187828858 | F47: 175000 | G47: Adjust other watch 04/10/2024 | H47: USA Office
C48: 45503 | D48: Watch Ultra 2 | E48: ??? | F48: 0 | G48: cancelled | H48: cancelled
C50: 45503 | D50: IP 15 ProMax 256GB Blue | E50: 352310727115435 | F50: 190000 | G50: Pending | H50: USA Office
C51: 45503 | D51: IP 15 ProMax 256GB Natural | E51: 351646279235530 | F51: 202000 | G51: Pending | H51: USA Office
C52: 45503 | D52: IP 15 ProMax 256GB Black | E52: 352676526208757 | F52: 185000 | G52: Pending | H52: USA Office
B54: Model Update | C54: 45510 | D54: IP 15 128GB Blue | E54: 351335415944581 | F54: 105000 | H54: Mudassir Bhai | J54: Received Encell Shop 13/08/2024
C55: 45510 | D55: IP 15Pro 128GB White | E55: 350839531130745 | F55: 145000 | H55: Mudassir Bhai | J55: Received Encell Shop 13/08/2024
C56: 45510 | D56: IP 15Pro 128GB White | E56: 351418620421437 | F56: 145000 | H56: Mudassir Bhai | J56: Received Encell Shop 13/08/2024
...

Sheet Stock
J2: Returned & sell | X2: Returned | AB2: Returned
C3: Company | D3: Model Name | E3: 45413 | F3: 45414 | G3: 45415 | H3: 45416 | I3: 45417 | J3: 45418 | K3: 45419 | L3: 45420 | M3: 45421 | N3: 45422 | O3: 45423 | P3: 45424 | Q3: 45425 | R3: 45426 | S3: 45427 | T3: 45428 | U3: 45429 | V3: 45430 | W3: 45431 | X3: 45432 | Y3: 45433 | Z3: 45434 | AA3: 45435 | AB3: 45436 | AC3: 45437 | AD3: 45438 | AE3: 45439 | AF3: 45440 | AG3: 45441 | AH3: 45442 | AI3: Remaining Stock | AL3: Company | AM3: Model Name | AN3: Remaining Stock | AO3: Costing | AP3: Total
C5: APPLE | AL5: APPLE
D6: IP 15ProMax 256 | U6: 1 | AG6: -1 | AI6: =SUM(E6:AH6) -> 0 | AM6: =D6 -> IP 15ProMax 256 | AN6: =AI6 -> 0 | AP6: =AN6*AO6 -> 0
D7: IP 15Pro 128Gb | U7: 1 | AI7: =SUM(E7:AH7) -> 1 | AM7: =D7 -> IP 15Pro 128Gb | AN7: =AI7 -> 1 | AO7: 900 | AP7: =AN7*AO7 -> 900
D8: IP 15plus 128GB | U8: 2 | AG8: -1 | AI8: =SUM(E8:AH8) -> 1 | AM8: =D8 -> IP 15plus 128GB | AN8: =AI8 -> 1 | AO8: 1350 | AP8: =AN8*AO8 -> 1350
D9: IP 15 128GB | U9: 2 | AI9: =SUM(E9:AH9) -> 2 | AM9: =D9 -> IP 15 128GB | AN9: =AI9 -> 2 | AO9: 500 | AP9: =AN9*AO9 -> 1000
D10: IP 14ProMax 128Gb | E10: 1 | AI10: =SUM(E10:AH10) -> 1 | AM10: IP 14ProMax 128Gb | AN10: =AI10 -> 1 | AO10: 1600 | AP10: =AN10*AO10 -> 1600
D11: IP 14ProMax 256Gb | E11: 1 | AI11: =SUM(E11:AH11) -> 1 | AM11: IP 14ProMax 256Gb | AN11: =AI11 -> 1 | AO11: 1600 | AP11: =AN11*AO11 -> 1600
D13: IP 13ProMax 512Gb | E13: 1 | AI13: =SUM(E13:AH13) -> 1 | AM13: IP 13ProMax 512Gb | AN13: =AI13 -> 1 | AO13: 1654.98 | AP13: =AN13*AO13 -> 1654.98 | AU13: IPHONE 13ProMax
D14: IP 13ProMax 128Gb | E14: 1 | R14: 2 | V14: -2 | AI14: =SUM(E14:AH14) -> 1 | AM14: IP 13ProMax 128Gb | AN14: =AI14 -> 1 | AO14: 1500 | AP14: =AN14*AO14 -> 1500 | AU14: 45420 | AV14: 6 | AW14: Match
D15: IP 13ProMax 256Gb | E15: 2 | J15: =3-1 -> 2 | R15: 11 | V15: -10 | X15: 1 | AB15: 1 | AG15: -4 | AI15: =SUM(E15:AH15) -> 3 | AM15: IP 13ProMax 256Gb | AN15: =AI15 -> 3 | AO15: 1527.83 | AP15: =AN15*AO15 -> 4583.49 | AU15: 45426 | AV15: 13 | AW15: Purchase By Ali Karachi
D16: IP 13Pro 256Gb | E16: 1 | AI16: =SUM(E16:AH16) -> 1 | AM16: IP 13Pro 256Gb | AN16: =AI16 -> 1 | AO16: 1100 | AP16: =AN16*AO16 -> 1100 | AU16: 45429 | AV16: -2 | AW16: Sell To encell
D17: IP 13 256Gb | E17: 2 | AI17: =SUM(E17:AH17) -> 2 | AM17: IP 13 256Gb | AN17: =AI17 -> 2 | AO17: 800 | AP17: =AN17*AO17 -> 1600 | AU17: 45430 | AV17: -10 | AW17: Sell To encell
D18: IP 13 128Gb | R18: 10 | U18: 1 | V18: -10 | AI18: =SUM(E18:AH18) -> 1 | AM18: IP 13 128Gb | AN18: =AI18 -> 1 | AO18: 300 | AP18: =AN18*AO18 -> 300 | AU18: 45432 | AV18: 1 | AW18: Returned From Encell
AU19: 45435 | AV19: 1 | AW19: Returned From Encell
D20: IP 12ProMax 256GB | E20: 1 | R20: 2 | V20: -1 | AI20: =SUM(E20:AH20) -> 2 | AM20: IP 12ProMax 256GB | AN20: =AI20 -> 2 | AO20: 1129.755 | AP20: =AN20*AO20 -> 2259.51 | AU20: 45442 | AV20: -4 | AW20: Sell To Euronext
D21: IP 12ProMax 128GB | E21: 1 | AI21: =SUM(E21:AH21) -> 1 | AM21: IP 12ProMax 128GB | AN21: =AI21 -> 1 | AO21: 720 | AP21: =AN21*AO21 -> 720
D22: IP 12 Pro 256GB | R22: 2 | AI22: =SUM(E22:AH22) -> 2 | AM22: IP 12 Pro 256GB | AN22: =AI22 -> 2 | AO22: 973.61 | AP22: =AN22*AO22 -> 1947.22 | AU22: Current Inventory | AV22: =SUM(AV14:AV21) -> 5
D23: IP 12 Pro 128GB | E23: 1 | AI23: =SUM(E23:AH23) -> 1 | AM23: IP 12 Pro 128GB | AN23: =AI23 -> 1 | AO23: 921.18 | AP23: =AN23*AO23 -> 921.18
D24: IP 12 64Gb | E24: 1 | AI24: =SUM(E24:AH24) -> 1 | AM24: IP 12 64Gb | AN24: =AI24 -> 1 | AO24: 400 | AP24: =AN24*AO24 -> 400
D25: IP 12 128Gb | E25: 1 | AI25: =SUM(E25:AH25) -> 1 | AM25: IP 12 128Gb | AN25: =AI25 -> 1 | AO25: 500 | AP25: =AN25*AO25 -> 500
D26: IP 12 256Gb | E26: 1 | AI26: =SUM(E26:AH26) -> 1 | AM26: IP 12 256Gb | AN26: =AI26 -> 1 | AO26: 500 | AP26: =AN26*AO26 -> 500
D28: IP 11ProMax 512Gb | R28: 1 | AI28: =SUM(E28:AH28) -> 1 | AM28: IP 11ProMax 512Gb | AN28: =AI28 -> 1 | AO28: 749.5 | AP28: =AN28*AO28 -> 749.5
D29: IP 11ProMax 256Gb | E29: 36 | O29: -36 | R29: 23 | AE29: -23 | AI29: =SUM(E29:AH29) -> 0 | AM29: IP 11ProMax 256Gb | AN29: =AI29 -> 0 | AO29: 863.39 | AP29: =AN29*AO29 -> 0
D30: IP 11ProMax 64Gb | E30: 1 | AI30: =SUM(E30:AH30) -> 1 | AM30: IP 11ProMax 64Gb | AN30: =AI30 -> 1 | AO30: 780.56 | AP30: =AN30*AO30 -> 780.56
D31: IP 11Pro 256Gb | E31: 4 | AI31: =SUM(E31:AH31) -> 4 | AM31: IP 11Pro 256Gb | AN31: =AI31 -> 4 | AO31: 811.56 | AP31: =AN31*AO31 -> 3246.24
D32: IP 11 128Gb | E32: 2 | R32: 1 | AI32: =SUM(E32:AH32) -> 3 | AM32: IP 11 128Gb | AN32: =AI32 -> 3 | AO32: 524.05 | AP32: =AN32*AO32 -> 1572.15
D34: Watch Ultra 2 | X34: 2 | AH34: 1 | AI34: =SUM(E34:AH34) -> 3 | AM34: =D34 -> Watch Ultra 2 | AN34: =AI34 -> 3 | AO34: =185000/76 -> 2434.2105 | AP34: =AN34*AO34 -> 7302.6316 | AQ34: 370000 PKR
D35: IP 7Plus | E35: 1 | AI35: =SUM(E35:AH35) -> 1 | AM35: IP 7Plus | AN35: =AI35 -> 1 | AO35: 300 | AP35: =AN35*AO35 -> 300
C36: SAMSUNG | AI36: =SUM(E36:AH36) -> 0 | AL36: SAMSUNG
D37: S23 FE 128GB | E37: 1 | AI37: =SUM(E37:AH37) -> 1 | AM37: S23 FE 128GB | AN37: =AI37 -> 1 | AO37: 555.6 | AP37: =AN37*AO37 -> 555.6
D39: S20 | E39: 1 | AI39: =SUM(E39:AH39) -> 1 | AM39: S20 | AN39: =AI39 -> 1 | AO39: 555.6 | AP39: =AN39*AO39 -> 555.6
D40: Flip5 256GB | E40: 1 | AI40: =SUM(E40:AH40) -> 1 | AM40: Flip5 256GB | AN40: =AI40 -> 1 | AO40: 555.6 | AP40: =AN40*AO40 -> 555.6
D41: Samsung A54 | E41: 1 | AI41: =SUM(E41:AH41) -> 1 | AM41: Samsung A54 | AN41: =AI41 -> 1 | AO41: 555.6 | AP41: =AN41*AO41 -> 555.6
C43: GOOGLE | D43: Google Pixel 7 | E43: 1 | AI43: =SUM(E43:AH43) -> 1 | AL43: GOOGLE | AM43: Google Pixel 7 | AN43: =AI43 -> 1 | AO43: 555.6 | AP43: =AN43*AO43 -> 555.6
C45: Starlink | D45: V2 | S45: 2 | AG45: -2 | AI45: =SUM(E45:AH45) -> 0 | AL45: Starlink | AM45: V2 | AN45: =AI45 -> 0 | AP45: =AN45*AO45 -> 0
D46: V3 New | AF46: 35 | AG46: -35 | AI46: =SUM(E46:AH46) -> 0 | AM46: =D46 -> V3 New | AN46: =AI46 -> 0
E47: =SUM(E5:E46) -> 64 | J47: =SUM(J5:J46) -> 2 | O47: =SUM(O5:O46) -> -36 | R47: =SUM(R5:R46) -> 52 | S47: =SUM(S5:S46) -> 2 | U47: =SUM(U5:U46) -> 7 | V47: =SUM(V5:V46) -> -23 | AH47: =SUM(AH5:AH46) -> 1 | AI47: =SUM(AI5:AI46) -> 42 | AN47: =SUM(AN5:AN46) -> 42 | AP47: =SUM(AP5:AP46) -> 41165.462
F53: Sell 01/06 | G53: Purchasing | H53: Purchasing | I53: Razi Sell | J53: Sell | N53: Sell | Q53: Purchasing Ali karachi
...

Sheet Australia 2
J3: Date | K3: Details | L3: GST Charges $
J5: 45439 | K5: 35pcs V3 Starlink GST | L5: 1665.3
J6: 45443 | K6: 35pcs Shipping Charges GST | L6: 16.49
J7: 45449 | K7: 60pcs V3 Starlink GST | L7: 2847.5
J8: 45450 | K8: 40pcs V3 Starlink GST | L8: 1890
J9: 45450 | K9: 05pcs V3 Starlink GST | L9: 193
J10: 45450 | K10: 02pcs V3 Starlink GST | L10: 94.5
J11: 45453 | K11: 47pcs Shipping Charges GST | L11: 24.36
J12: 45456 | K12: 60pcs Shipping Charges GST | L12: 27.72
J14: 45468 | K14: 81.5pcs Refundable Charges | L14: 6109.24
J15: 45468 | K15: 81.5pcs GST Charges | L15: =4472.52/94*81.5 -> 3877.77
J16: 45473 | K16: 46pcs Refundable Charges $75 | L16: =46*75 -> 3450
K18: Total | L18: =SUM(L5:L17) -> 20195.88
D22: Jawed bhai Investment
C23: Date | D23: Particular | E23: Dr | F23: Cr | G23: Balance
C25: 45431 | D25: Investment 27000 Dollar 2.44 Dirham Rate | E25: =27000*2.44 -> 65880 | G25: =G24+E25-F25 -> 65880
C26: 45452 | D26: V3 35pcs Profit $10 Each Total $350 19 May To 8June | E26: =350*2.44 -> 854 | G26: =G25+E26-F26 -> 66734
C27: 45452 | D27: V3 15pcs Profit $10 Each Total $150 19 May To 8June | E27: =150*2.44 -> 366 | G27: =G26+E27-F27 -> 67100
C28: 45474 | D28: Jawed Bhai 2nd Profit 9.June To 29.June $500 | E28: =500*2.44 -> 1220 | G28: =G27+E28-F28 -> 68320
C29: 45492 | D29: Jawed Bhai 3rd Profit 30.June To 20July $500 | E29: =500*2.44 -> 1220 | G29: =G28+E29-F29 -> 69540
C30: 45493 | D30: s | E30: =54000*2.44 -> 131760 | G30: =G29+E30-F30 -> 201300
G31: =G30+E31-F31 -> 201300
G32: =G31+E32-F32 -> 201300
G33: =G32+E33-F33 -> 201300
G34: =G33+E34-F34 -> 201300
G35: =G34+E35-F35 -> 201300
D39: Abdul Rehman Bhai Cash
C40: Date | D40: Particular | E40: Dr | F40: Cr | G40: Balance
A42: Add | C42: 45428 | D42: Send To australia By A/R (AUD 8782.5 @2.28) | E42: 20000 | G42: =G41+E42-F42 -> 20000 | H42: ok
A43: Add | C43: 45432 | D43: Send To australia By A/R (AUD 23152.5 @2.505) | E43: 58000 | G43: =G42+E43-F43 -> 78000 | H43: ok
C44: 45441 | D44: Adjustment Waheed Bhai Old Balance Paid by A/R | F44: 19172 | G44: =G43+E44-F44 -> 58828 | H44: ok
A45: Add | C45: 45440 | D45: Import Charges V3 35pcs | E45: 1230 | G45: =G44+E45-F45 -> 60058 | H45: ok
A46: Add | C46: 45440 | D46: V3 35pcs Hamali Charges | E46: 30 | G46: =G45+E46-F46 -> 60088 | H46: ok
A47: Add | C47: 45442 | D47: Online A/R A/C (Withdraw By Waheed Bhai) | E47: 1264.58 | G47: =G46+E47-F47 -> 61352.58 | H47: ok
A48: Add | C48: 45442 | D48: Sell Encell Shop 2pcs | F48: 3240 | G48: =G47+E48-F48 -> 58112.58 | H48: ok
A49: Add | C49: 45442 | D49: Sell Encell Shop 18pcs | F49: 29520 | G49: =G48+E49-F49 -> 28592.58 | H49: ok
A50: Add | C50: 45442 | D50: Sell AMGT Office 15pcs | F50: 24300 | G50: =G49+E50-F50 -> 4292.58 | H50: ok
C51: 45442 | D51: V3 35pcs Profit | E51: =L136 -> 2878.7416 | G51: =G50+E51-F51 -> 7171.3216
A52: Add | C52: 45447 | D52: Fahib Salary M/O May-2024 (15000 PKR) | E52: 194.81 | G52: =G51+E52-F52 -> 7366.1316 | H52: ok
A53: Add | C53: 45448 | D53: Clearing Charges V3 60pcs | E53: 1660 | G53: =G52+E53-F53 -> 9026.1316 | H53: ok
...

Sheet AR Expense 
D3: A/R Karachi Expense Ledger
C4: DATE | D4: DETAILS | E4: IN | F4: OUT | G4: BALANCE
D6: Month of Aug-2024 | G6: 0
C7: 45506 | D7: Online Transfer Sania Abdul Rehman (AR Expense) | F7: 100000 | G7: =G6+E7-F7 -> -100000
C8: 45507 | D8: DVAGO POS Purchased (AR Expense) | F8: 2447 | G8: =G7+E8-F8 -> -102447
C9: 45509 | D9: Zellbury POS (AR Expense) | F9: 4582 | G9: =G8+E9-F9 -> -107029
C10: 45509 | D10: Kababjees (AR Expense) | F10: 1700 | G10: =G9+E10-F10 -> -108729
C11: 45509 | D11: United King (AR Expense) | F11: 877 | G11: =G10+E11-F11 -> -109606
C12: 45509 | D12: ATM Withdraw Askari (AR Expense) | F12: 20000 | G12: =G11+E12-F12 -> -129606
C13: 45509 | D13: Paid to Maaz (petrol Exp) | F13: 1000 | G13: =G12+E13-F13 -> -130606
C14: 45510 | D14: Uphone Super Card (AR Expense) | F14: 1600 | G14: =G13+E14-F14 -> -132206
C15: 45510 | D15: Transfer Muhammad ilyas (AR Expense) | F15: 16000 | G15: =G14+E15-F15 -> -148206
C16: 45510 | D16: Transfer Nasir Mahmood (AR Expense) | F16: 10000 | G16: =G15+E16-F16 -> -158206
C17: 45517 | D17: FBR Tax (A/R Exp meezan) | F17: 75.78 | G17: =G16+E17-F17 -> -158281.78
C18: 45517 | D18: Apple.Com Bill (A/R Exp meezan) | F18: 601.46 | G18: =G17+E18-F18 -> -158883.24
... C28: 45530 | D28: AR Personal | F28: 1661 | G28: =G27+E28-F28 -> -414960.24
G29: =G28+E29-F29 -> -414960.24
G30: =G29+E30-F30 -> -414960.24
G31: =G30+E31-F31 -> -414960.24
G32: =G31+E32-F32 -> -414960.24
G33: =G32+E33-F33 -> -414960.24
D34: Total Expense | G34: =G33+E34-F34 -> -414960.24
D38: A/R Dubai Expense Ledger
C39: DATE | D39: DETAILS | E39: IN | F39: OUT | G39: BALANCE
D41: Month of Aug-2024 | G41: 0
C42: 45502 | D42: Room Rent Advance | F42: 0 | G42: =G41+E42-F42 -> 0
C43: 45502 | D43: AR Personal Shop Cash | F43: 210 | G43: =G42+E43-F43 -> -210
C44: 45502 | D44: AR Credit Card Exp | F44: 20 | G44: =G43+E44-F44 -> -230
C45: 45502 | D45: AR Credit Card Exp | F45: 16 | G45: =G44+E45-F45 -> -246
C46: 45502 | D46: AR Credit Card Exp | F46: 87 | G46: =G45+E46-F46 -> -333
C47: 45510 | D47: Flat 307 Rent paid by Faisal Bhai | F47: 0 | G47: =G46+E47-F47 -> -333
C48: 45498 | D48: POS Purchase (AR DIB Online) | F48: 41 | G48: =G47+E48-F48 -> -374
C49: 45500 | D49: POS Purchase (AR DIB Online) | F49: 33.5 | G49: =G48+E49-F49 -> -407.5
C50: 45501 | D50: POS Purchase (AR DIB Online) | F50: 15.5 | G50: =G49+E50-F50 -> -423
C51: 45501 | D51: POS Purchase (AR DIB Online) | F51: 1.5 | G51: =G50+E51-F51 -> -424.5
C52: 45504 | D52: POS Purchase (AR DIB Online) | F52: 13.6 | G52: =G51+E52-F52 -> -438.1
C53: 45504 | D53: POS Purchase (AR DIB Online) | F53: 19.5 | G53: =G52+E53-F53 -> -457.6
... C82: 45520 | D82: Wal-Mart SuperCenter (12.35 CAD) | F82: 34.3 | G82: =G81+E82-F82 -> -3103.65
C83: 45531 | D83: Canadian Dollar 400 | F83: =400*2.7 -> 1080 | G83: =G82+E83-F83 -> -4183.65
G84: =G83+E84-F84 -> -4183.65
...

Sheet Book 1

Sheet Book 2
D4: MODEL | E4: IMEI
D5: IP 16ProMax 256GB Desert Titanium | E5: 359974601808093 | G5: 359974601822136
D6: Samsung SM-S921W 128GB | E6: 356380561350311
D7: IP 16 Pro 128GB Black Titanium | E7: 355171954666715 | G7: 355171954837670
D8: IP 16ProMax 256GB Desert Titanium | E8: 350523895462817 | G8: 350523895270590
D9: IP 16ProMax 256GB Desert Titanium | E9: 351655955619750 | G9: 351655955665670
D10: IP 16 128GB Ultramarine | E10: 352502303969835 | G10: 352502304215782
D11: Samsung SM-A546W 128GB | E11: 351617737060950
D12: Samsung SM-F741W 256GB | E12: 351250615743586 | G12: 359688605743581
D13: IP 16 128GB Black | E13: 358413699819150
D14: IP 16 128GB Black | E14: 359298855052764 | G14: 359298855126972
D15: IP 16 128GB Black | E15: 358413695701980
D16: IP 16Pro 256GB Desert Titanium | E16: 353446782484354 | G16: 353446784675439
D17: IP 16Pro 256GB Desert Titanium | E17: 353446786560563 | G17: 353446781513476
D18: Samsung SM-F741W 256GB | E18: 351250615737612 | G18: 359688605737617
D19: IP 16Pro 256GB Desert Titanium | E19: 353446781287865 | G19: 353446786176923
D20: IP 16Pro 256GB Black Titanium | E20: 354985550609675 | G20: 354985550506525
D21: Samsung SM-A546W 128GB | E21: 351617736910312
D22: Samsung SM-F741W 256GB | E22: 351250615600778 | G22: 359688605600773
